Workbook

Sheet CONTENÇÃO RÁPIDA
K1: EMPUXO EM CONTENÇÃO – CARGAS NO PILAR E NA LAJE ALVEOLAR
K2: PILAR – CARGA TRAPEZOIDAL | M2: ="p,topo = "&FIXED($L$59,2)&" kN/m" | O2: ="p,base = "&FIXED($L$60,2)&" kN/m" | R2: ="E = "&FIXED($L$63,2)&" kN a "&FIXED($L$65,2)&" m da base"
K3: PILAR – MOMENTOS | M3: ="M,base = "&FIXED($L$80,2)&" kN·m ("&$L$39&")" | O3: ="M,vão = "&IF($L$39="Balanço","-",FIXED($L$81,2)&" kN·m a "&FIXED($L$82,2)&" m") | R3: ="R,topo = "&FIXED($L$78,2)&" kN → laje"
K4: LAJE – PAINEL MAIS CARREGADO (P1) | M4: ="g = "&FIXED($L$93,2)&" | q = "&FIXED($L$94,2)&" kN/m" | O4: ="p,total = "&FIXED($L$92,2)&" kN/m²" | R4: ="Mk = "&FIXED($L$95,2)&" kN·m | Vk = "&FIXED($L$96,2)&" kN"
K6: Como usar: células CINZA são entradas (preencha/edite). As demais são calculadas. Empuxo de Rankine, solo sem coesão (a favor da segurança); valores característicos (sem γf); 1 tf = 10 kN. A coluna Status fica verde quando está Ok. O RESUMO abaixo traz o que lançar no modelo (Eberick/TQS) e na tabela do fabricante da laje alveolar.
K8: RESUMO – VALORES PARA LANÇAR
K10: Item | L10: Resultado | N10: Status | O10: O que é
K11: Empuxo | L11: =$L$38&" – K = "&FIXED($L$48,3) | N11: ="Ok" | O11: Coeficiente adotado – item 2.1
K12: Aviso | L12: =IF(AND($L$39<>"Balanço",$L$38="Ativo"),"⚠ Topo do pilar travado pela laje com empuxo ATIVO: se a estrutura for rígida (sem deslocamento), use REPOUSO – K0 = "&FIXED($L$47,2)&" contra Ka = "&FIXED($L$46,2)&" (+"&FIXED(($L$47/$L$46-1)*100,0)&"% de carga).",IF(AND($L$39="Balanço",$L$38="Repouso"),"⚠ Balanço com empuxo em REPOUSO: pilar livre no topo se desloca – ATIVO costuma bastar.","Sem avisos."))
K13: Pilar p,topo | L13: =FIXED($L$59,2)&" kN/m" | O13: Carga trapezoidal no pilar: valor no topo – item 3.1
K14: Pilar p,base | L14: =FIXED($L$60,2)&" kN/m" | O14: Carga trapezoidal no pilar: valor na base – item 3.1
K15: Resultante | L15: =FIXED($L$63,2)&" kN ("&FIXED($L$64,2)&" tf)" | O15: Solo + Sc, aplicada a y,E da base – item 3.2
K16: Modelo pilar | L16: =$L$39 | N16: =IF(ISNA(MATCH($L$39,$K$74:$K$76,0)),"Rever: modelo inválido","Ok") | O16: Modelo estrutural do pilar – item 4.1
K17: R,topo | L17: =FIXED($L$78,2)&" kN" | O17: Força que o pilar entrega à laje/viga do topo – item 4.2
K18: M,base | L18: =FIXED($L$80,2)&" kN·m" | O18: Momento na base do pilar – item 4.2
K19: M,vão | L19: =IF($L$39="Balanço","-",FIXED($L$81,2)&" kN·m a "&FIXED($L$82,2)&" m") | O19: Maior momento positivo e altura a partir da base – item 4.2
K20: M(x) | L20: =FIXED($L$83,2)&" kN·m" | N20: =IF($L$40>$L$33,"Rever: x maior que H",IF($L$40<0,"Rever: x negativo","Ok")) | O20: Momento na cota x – item 4.2
K21: Laje p,total | L21: =FIXED($L$92,2)&" kN/m²" | N21: =IF($L$89>10,"Rever: mais de 10 painéis","Ok") | O21: Painel inferior: comparar com a tabela do fabricante – item 5.1
K22: Laje g / q | L22: =FIXED($L$93,2)&" / "&FIXED($L$94,2)&" kN/m" | O22: Cargas lineares no painel inferior – item 5.1
K23: Laje Mk / Vk | L23: =FIXED($L$95,2)&" kN·m / "&FIXED($L$96,2)&" kN" | O23: Esforços no painel inferior, vão L – item 5.1
K26: 1 . DADOS DE ENTRADA
K28: 1.1 Solo
K29: γ | L29: 18 | M29: kN/m³ | O29: Peso específico do solo.
K30: φ | L30: 18 | M30: ° | O30: Ângulo de atrito do solo (ver aba DADOS DO SOLO, col. G).
K31: Sc | L31: 5 | M31: kN/m² | O31: Sobrecarga no terreno (veículos leves ≈ 5 a 10; só pedestres ≈ 2,5 a 5).
K32: 1.2 Geometria
K33: H | L33: 2.5 | M33: m | O33: Altura da contenção: da base até o topo do terreno contido.
K34: D | L34: =13.07/2 | M34: m | O34: Largura de influência no pilar: intermediário = (vão esq. + vão dir.)/2; extremidade = vão/2.
K35: bw | L35: 1.25 | M35: m | O35: Largura da placa de laje alveolar = altura de cada painel deitado na contenção.
K36: L | L36: =L34 | M36: m | O36: Vão que a placa vence entre pilares (padrão = D; altere se for diferente).
K37: 1.3 Modelo
K38: Empuxo | L38: Ativo | M38: - | O38: Ativo (Ka): parede pode se deslocar. Repouso (K0): topo travado, estrutura rígida.
K39: Pilar | L39: Engaste-apoio | M39: - | O39: Modelo do pilar: escolha na tabela do item 4.1 (define o resumo).
K40: x | L40: 0 | M40: m | O40: Cota de verificação do momento, medida a partir da base (x = 0 → base).
K42: 2 . COEFICIENTE DE EMPUXO E PRESSÕES
K44: Rankine, parede vertical e terreno horizontal. A sobrecarga Sc vira uma pressão constante K·Sc em toda a altura; o solo dá uma pressão triangular K·γ·z (zero no topo, máxima na base).
K45: 2.1 Coeficiente
K46: Ka | L46: =TAN(RADIANS(45-$L$30/2))^2 | M46: - | O46: Empuxo ativo: tan²(45° − φ/2).
K47: K0 | L47: =1-SIN(RADIANS($L$30)) | M47: - | O47: Empuxo em repouso: 1 − sen φ.
K48: K | L48: =IF($L$38="Repouso",$L$47,$L$46) | M48: - | O48: Coeficiente adotado (item 1.3).
...

Sheet MURO DE ARRIMO
A1: Estimativa de Parâmetros dos Solos - Argilas/ Areias - CURSO DOMINE ENGENHARIA ESTRUTURAL V2.0 | BD1: ....
A2: DADOS SOLO E PILARES: | L2: Sc | M2: 5 | N2: kN/m²
A3: TIPO DE SOLO | B3: Argila/ Silte Média(SPT 6-9) | L3: Peso específico (γ): | M3: 18 | N3: KN/m³
A4: NSPT (laudo de sondagem) | B4: 0 | L4: Altura pilar (H): | M4: 2.5 | N4: m | Q4: Ka = tan²(45 - 30/2) = tan²(30) = 0.33
A5: Altura pilar (H): | B5: 3.85 | C5: m | L5: Distância entre pilares (D): | M5: =13.07/2 -> 6.535 | N5: m | Q5: Ka = tan²(45 - φ/2)
A6: Distância entre pilares (D): | B6: 4.25 | C6: m
A7: Peso específico (γ): | B7: 18 | C7: KN/m³ | L7: ângulo de atrito | M7: 18 | N7: º
A8: Coesão [c]: | B8: {=(IF(B4>30,200,(SUMPRODUCT(('DADOS DO SOLO'!C2:C84=B4)*('DADOS DO SOLO'!A2:A84=B3)*('DADOS DO SOLO'!F2:F84)))))*(VLOOKUP(B10,'CÁLCULO FECHAMENTO'!A17:B19,2,0))} -> 0 | C8: Kpa | L8: Ka | M8: =TAN(RADIANS(45 - M7/2))^2 -> 0.52786405
A9: Ângulo de atrito (φ): | B9: =IF(B4>50,45,(SUMPRODUCT(('DADOS DO SOLO'!C2:C84=B4)*('DADOS DO SOLO'!A2:A84=B3)*('DADOS DO SOLO'!G2:G84)))) -> 0 | L9: Tensão (σa): KN/m² | M9: =M3*M4 -> 45 | N9: KN/m²
A10: Considerar solo coesivo? | B10: Não | L10: Pa=σa.Ka - 2.c.√Ka | M10: =(M9*M8) -> 23.753882 | N10: KN/m² | P10: Sobrecargas em lajes
A11: DADOS FECHAMENTO EM ALVENARIA: | L11: Ea=(Pa.H)/2 | M11: =M10*#REF!/2 -> #REF! | N11: KN/m
A12: Fechamento da alvenaria (até 2 metros) | B12: 1.75 | C12: m | L12: Ea(total)=Ea.D | M12: =(M11*#REF!) -> #REF! | N12: KN
A13: Espessura dos blocos: | B13: 14 | C13: cm
A14: Porcentagem de graute: | B14: 0.5 | C14: %
A15: Momento solicitante (Mk) - Líbano | B15: =MAX('TABELAS LÍBANO'!E4:E6) -> 23.555733 | C15: Kn.m
A16: Espessura parede do bloco: | B16: 2 | C16: cm
A17: Largura do bloco: | B17: 39 | C17: cm
A18: Resistência a compressão bloco | B18: 8 | C18: Mpa
A19: Ø Barra: | B19: 8
A20: Espaçamento a cada: | B20: ='FECHAMENTO EM ALVENARIA'!E48 -> #NUM! | C20: cm
A22: AVISOS | L22: Ea=(Pa.H)/2 | M22: =M10*M4/2 -> 29.692353 | N22: KN/m | P22: bw,laje | Q22: 1.25 | R22: m | T22: Largura da laje.
A23: Solo se autosustenta? | B23: =IF(B38>0,"Não","Sim") -> Não | L23: Ea(total)=Ea.D | M23: =(M22*M5) -> 194.03952 | N23: KN | P23: h | Q23: =M4 -> 2.5 | R23: m | T23: Altura da contenção.
A24: Esbeltez do pilar abaixo do limite? | B24: =IF('CÁLCULO FECHAMENTO'!B11="Não","Aumentar largura pilar",'CÁLCULO FECHAMENTO'!B11) -> Sim | L24: Carga no pilar (lançar no pilar) | M24: =M23*0.1 -> 19.403952 | N24: Tf | P24: h,eq | Q24: =M2/M3 -> 0.27777778 | R24: m | T24: Altura equivalente ocasionada pela sobrecarga.
A25: Esbeltez da alvenaria abaixo do limite? | B25: =IF('CÁLCULO FECHAMENTO'!B12="Não","Aumentar largura da alvenaria",'CÁLCULO FECHAMENTO'!B12) -> Sim | L25: Ponto de aplicação=B/3 | M25: =M4/3 -> 0.83333333 | N25: m | P25: Pa | Q25: =Q23*M8*M3 -> 23.753882 | R25: KN/m² | T25: Tensão atuante.
A26: Momento alvenaria abaixo do limite? | B26: =IF('CÁLCULO FECHAMENTO'!B13="Não","Aumentar resistência do bloco",'CÁLCULO FECHAMENTO'!B13) -> Sim | L26: Momento no Pilar | M26: =M24*M25 -> 16.16996 | P26: Pa = G | Q26: =Q25*Q22 -> 29.692353 | R26: KN/m | T26: Resultante na laje devido às cargas permanentes.
A27: Alvenaria resiste ao cisalhamento? | B27: =IF('CÁLCULO FECHAMENTO'!B14="Não","Aumentar resistência do bloco",'CÁLCULO FECHAMENTO'!B14) -> Sim | L27: Aplicar carga em: | M27: =M25 -> 0.83333333 | N27: m | P27: Pa = Q | Q27: =Q24*M3*M8*Q22 -> 3.2991503 | R27: KN/m | T27: Resultante na laje devido às cargas variáveis.
A28: Alvenaria resiste a carga gravitacional? | B28: =IF('CÁLCULO FECHAMENTO'!B15="Não","Aumentar resistência do bloco",'CÁLCULO FECHAMENTO'!B15) -> #DIV/0! | L28: Aplicar carga: | M28: =M25*M24/M27 -> 19.403952 | N28: tf
L29: h,eq | M29: =M2/M3 -> 0.27777778 | N29: m
A30: Altura efetiva da contenção: | B30: ='CÁLCULO FECHAMENTO'!B36 -> 0.95824574 | C30: m | L30: Pa,sup | M30: =M29*M8*M3*M5 -> 17.247958 | N30: KN/m
A31: Peso alvenaria (aplicar no baldrame) | B31: ='CÁLCULO FECHAMENTO'!B46*1000 -> 1590.842 | C31: kgf/m | L31: Pa,inf | M31: =(M29+M4)*M8*M3*M5 -> 172.47958 | N31: KN/m
A32: CÁLCULO DAS CARGAS
A33: Ka | B33: 0.36 | L33: Momento Pilar engastado/livre
A34: Tensão (σa): KN/m² | B34: =B7*B5 -> 69.3 | C34: KN/m² | L34: Momento máximo | M34: =(((M31-M30)*(M4-M35)^3)/(6*M4))+(M30*M4^2)/2 -> 215.59947 | N34: kN*m
A35: Pa=σa.Ka - 2.c.√Ka | B35: =(B34*B33)-(2*B8*SQRT(B33)) -> 24.948 | C35: KN/m² | L35: Cota de verificação | M35: 0 | N35: m
A36: Ea=(Pa.H)/2 | B36: =B35*B5/2 -> 48.0249 | C36: KN/m | L36: Momento máximo variado | M36: =((M31-M30)*(M4-M35)^3)/(6*M4)+(M30*(M4-M35)^2)/2 -> 215.59947 | N36: kN*m
A37: Ea(total)=Ea.D | B37: =(B36*B6) -> 204.10582 | C37: KN
A38: Carga no pilar (lançar no pilar) | B38: =B37*0.1 -> 20.410583 | C38: Tf | L38: Momento Pilar biapoiado
A39: Ponto de aplicação=B/3 | B39: =B5/3 -> 1.2833333 | C39: m | L39: Cota de verificação | M39: 0 | N39: m | O39: em ajuste
A40: Momento no Pilar | B40: =B38*B39 -> 26.193581 | L40: Momento máximo variado | M40: =-(M4^2*M30)/8-(M4^2*(M31-M30)/15+(5*M4*M39*M30)/8+(2*M4*M39*(M31-M30))/5-(M39^2*M30)/2-(M39^2*(M31-M30))/2-(M39^2*(M31-M30))/2+(M39^3*(M31-M30))/(6*M4)) -> -78.154808 | N40: kN*m
A41: Aplicar carga em: | B41: =B39 -> 1.2833333 | C41: m
...

Sheet DADOS DO SOLO
A1: SOLO | B1: K (coeficiente de empuxo ativo) | C1: SPT | D1: γ (KN/m³) | E1: fator c | F1: coesão KN/M² | G1: ângulo de atrito | K1: Solo | L1: K | M1: y | N1: C
A2: Argila/ Silte Fofo(SPT 5-) | B2: 0.85 | C2: 0 | D2: 13 | E2: 0.8 | F2: =E2*(D2/10)^0.5*10 -> 9.1214034 | G2: 0 | K2: Argila/ Silte Fofo(SPT 5-) | L2: 0.85 | M2: 1.3 | N2: 0.8
A3: Argila/ Silte Fofo(SPT 5-) | B3: 0.85 | C3: 1 | D3: 13 | E3: 0.8 | F3: =E3*(D3/10)^0.5*10 -> 9.1214034 | G3: 0 | K3: Argila/ Silte Média(SPT 6-9) | L3: 0.75 | M3: 1.5 | N3: 1.6
A4: Argila/ Silte Fofo(SPT 5-) | B4: 0.85 | C4: 2 | D4: 13 | E4: 0.8 | F4: =E4*(D4/10)^0.5*10 -> 9.1214034 | G4: 0 | K4: Argila/ Silte Rijo(SPT 10-19) | L4: 0.65 | M4: 1.7 | N4: 4.8
A5: Argila/ Silte Fofo(SPT 5-) | B5: 0.85 | C5: 3 | D5: 13 | E5: 0.8 | F5: =E5*(D5/10)^0.5*10 -> 9.1214034 | G5: 0 | K5: Argila/ Silte Duro(SPT 20+) | L5: 0.55 | M5: 1.9 | N5: 9.6
A6: Argila/ Silte Fofo(SPT 5-) | B6: 0.85 | C6: 4 | D6: 13 | E6: 0.8 | F6: =E6*(D6/10)^0.5*10 -> 9.1214034 | G6: 0 | K6: Areia Fofa(SPT 8-) | L6: 0.6 | M6: 1.7 | N6: 0
A7: Argila/ Silte Fofo(SPT 5-) | B7: 0.85 | C7: 5 | D7: 13 | E7: 0.8 | F7: =E7*(D7/10)^0.5*10 -> 9.1214034 | G7: 0 | K7: Areia Média(SPT 9-18) | L7: 0.55 | M7: 1.9 | N7: 0
A8: Argila/ Silte Média(SPT 6-9) | B8: 0.75 | C8: 6 | D8: 15 | E8: 1.6 | F8: =E8*(D8/10)^0.5*10 -> 19.595918 | G8: 0 | K8: Areia Compacta(SPT 19-39) | L8: 0.5 | M8: 2 | N8: 0
A9: Argila/ Silte Média(SPT 6-9) | B9: 0.75 | C9: 7 | D9: 15 | E9: 1.6 | F9: =E9*(D9/10)^0.5*10 -> 19.595918 | G9: 0 | K9: Areia Muito Compacta(SPT 40+) | L9: 0.45 | M9: 2.1 | N9: 0
A10: Argila/ Silte Média(SPT 6-9) | B10: 0.75 | C10: 8 | D10: 15 | E10: 1.6 | F10: =E10*(D10/10)^0.5*10 -> 19.595918 | G10: 0
A11: Argila/ Silte Média(SPT 6-9) | B11: 0.75 | C11: 9 | D11: 15 | E11: 1.6 | F11: =E11*(D11/10)^0.5*10 -> 19.595918 | G11: 0 | K11: Solo
A12: Argila/ Silte Rijo(SPT 10-19) | B12: 0.65 | C12: 10 | D12: 17 | E12: 4.8 | F12: =E12*(D12/10)^0.5*10 -> 62.584343 | G12: 0 | K12: Argila/ Silte Fofo(SPT 5-)
A13: Argila/ Silte Rijo(SPT 10-19) | B13: 0.65 | C13: 11 | D13: 17 | E13: 4.8 | F13: =E13*(D13/10)^0.5*10 -> 62.584343 | G13: 0 | K13: Argila/ Silte Média(SPT 6-9)
A14: Argila/ Silte Rijo(SPT 10-19) | B14: 0.65 | C14: 12 | D14: 17 | E14: 4.8 | F14: =E14*(D14/10)^0.5*10 -> 62.584343 | G14: 0 | K14: Argila/ Silte Rijo(SPT 10-19)
A15: Argila/ Silte Rijo(SPT 10-19) | B15: 0.65 | C15: 13 | D15: 17 | E15: 4.8 | F15: =E15*(D15/10)^0.5*10 -> 62.584343 | G15: 0 | K15: Argila/ Silte Duro(SPT 20+)
A16: Argila/ Silte Rijo(SPT 10-19) | B16: 0.65 | C16: 14 | D16: 17 | E16: 4.8 | F16: =E16*(D16/10)^0.5*10 -> 62.584343 | G16: 0 | K16: Areia Fofa(SPT 8-)
A17: Argila/ Silte Rijo(SPT 10-19) | B17: 0.65 | C17: 15 | D17: 17 | E17: 4.8 | F17: =E17*(D17/10)^0.5*10 -> 62.584343 | G17: 0 | K17: Areia Média(SPT 9-18)
A18: Argila/ Silte Rijo(SPT 10-19) | B18: 0.55 | C18: 16 | D18: 17 | E18: 4.8 | F18: =E18*(D18/10)^0.5*10 -> 62.584343 | G18: 0 | K18: Areia Compacta(SPT 19-39)
A19: Argila/ Silte Rijo(SPT 10-19) | B19: 0.55 | C19: 17 | D19: 17 | E19: 4.8 | F19: =E19*(D19/10)^0.5*10 -> 62.584343 | G19: 0 | K19: Areia Muito Compacta(SPT 40+)
A20: Argila/ Silte Rijo(SPT 10-19) | B20: 0.55 | C20: 18 | D20: 17 | E20: 4.8 | F20: =E20*(D20/10)^0.5*10 -> 62.584343 | G20: 0
A21: Argila/ Silte Rijo(SPT 10-19) | B21: 0.55 | C21: 19 | D21: 17 | E21: 4.8 | F21: =E21*(D21/10)^0.5*10 -> 62.584343 | G21: 0
A22: Argila/ Silte Duro(SPT 20+) | B22: 0.55 | C22: 20 | D22: 19 | E22: 9.6 | F22: =E22*(D22/10)^0.5*10 -> 132.32687 | G22: 0
A23: Argila/ Silte Duro(SPT 20+) | B23: 0.55 | C23: 21 | D23: 19 | E23: 9.6 | F23: =E23*(D23/10)^0.5*10 -> 132.32687 | G23: 0
A24: Argila/ Silte Duro(SPT 20+) | B24: 0.55 | C24: 22 | D24: 19 | E24: 9.6 | F24: =E24*(D24/10)^0.5*10 -> 132.32687 | G24: 0
A25: Argila/ Silte Duro(SPT 20+) | B25: 0.55 | C25: 23 | D25: 19 | E25: 9.6 | F25: =E25*(D25/10)^0.5*10 -> 132.32687 | G25: 0
A26: Argila/ Silte Duro(SPT 20+) | B26: 0.55 | C26: 24 | D26: 19 | E26: 9.6 | F26: =E26*(D26/10)^0.5*10 -> 132.32687 | G26: 0
A27: Argila/ Silte Duro(SPT 20+) | B27: 0.55 | C27: 25 | D27: 19 | E27: 9.6 | F27: =E27*(D27/10)^0.5*10 -> 132.32687 | G27: 0
A28: Argila/ Silte Duro(SPT 20+) | B28: 0.55 | C28: 26 | D28: 19 | E28: 9.6 | F28: =E28*(D28/10)^0.5*10 -> 132.32687 | G28: 0
A29: Argila/ Silte Duro(SPT 20+) | B29: 0.55 | C29: 27 | D29: 19 | E29: 9.6 | F29: =E29*(D29/10)^0.5*10 -> 132.32687 | G29: 0
A30: Argila/ Silte Duro(SPT 20+) | B30: 0.55 | C30: 28 | D30: 19 | E30: 9.6 | F30: =E30*(D30/10)^0.5*10 -> 132.32687 | G30: 0
A31: Argila/ Silte Duro(SPT 20+) | B31: 0.55 | C31: 29 | D31: 19 | E31: 9.6 | F31: =E31*(D31/10)^0.5*10 -> 132.32687 | G31: 0
A32: Argila/ Silte Duro(SPT 20+) | B32: 0.55 | C32: 30 | D32: 19 | E32: 9.6 | F32: =E32*(D32/10)^0.5*10 -> 132.32687 | G32: 0
A33: Areia Fofa(SPT 8-) | B33: 0.6 | C33: 0 | D33: 17 | E33: 0 | F33: =((D33/10)*E33)^0.5*10 -> 0 | G33: 0
A34: Areia Fofa(SPT 8-) | B34: 0.6 | C34: 1 | D34: 17 | E34: 0 | F34: =((D34/10)*E34)^0.5*10 -> 0 | G34: 7.5
A35: Areia Fofa(SPT 8-) | B35: 0.6 | C35: 2 | D35: 17 | E35: 0 | F35: =((D35/10)*E35)^0.5*10 -> 0 | G35: 15
A36: Areia Fofa(SPT 8-) | B36: 0.6 | C36: 3 | D36: 17 | E36: 0 | F36: =((D36/10)*E36)^0.5*10 -> 0 | G36: 22.5
A37: Areia Fofa(SPT 8-) | B37: 0.6 | C37: 4 | D37: 17 | E37: 0 | F37: =((D37/10)*E37)^0.5*10 -> 0 | G37: 30
A38: Areia Fofa(SPT 8-) | B38: 0.6 | C38: 5 | D38: 17 | E38: 0 | F38: =((D38/10)*E38)^0.5*10 -> 0 | G38: =G37-((C37-C38)*(G37-G43)/(C37-C43)) -> 30.833333
A39: Areia Fofa(SPT 8-) | B39: 0.6 | C39: 6 | D39: 17 | E39: 0 | F39: =((D39/10)*E39)^0.5*10 -> 0 | G39: =G38-((C38-C39)*(G38-G$43)/(C38-C$43)) -> 31.666667
A40: Areia Fofa(SPT 8-) | B40: 0.6 | C40: 7 | D40: 17 | E40: 0 | F40: =((D40/10)*E40)^0.5*10 -> 0 | G40: =G39-((C39-C40)*(G39-$G$43)/(C39-$C$43)) -> 32.5
...

Sheet ASSENTAMENTO
B3: Materiais Para Assentamento de tijolo furado
B5: - Incluída perda de 7% para tijolos | O5: ASSENTAMENTO | S5: 1 BETONEIRA
B6: - Descontar a área das portas e janelas da área da parede | O6: TRAÇO EM LATAS DE 18L | Q6: 10L | S6: 18L | T6: 10L
B7: - A junta entre os tijolos normalmente é de 1,5 cm | O7: CIMENTO | P7: =((D18*50)/1400)/0.018 -> 3.2467763 | Q7: =((D18*50)/1400)/0.01 -> 5.8441973 | S7: =P7/$O$16 -> 4.1883079 | T7: =Q7/$O$16 -> 7.5389542
B8: Proporção de Cimento | D8: 1 | O8: CAL | P8: =((D20*20)/670)/0.018 -> 0.43613413 | Q8: =((D19*20)/670)/0.01 -> 2.9220987 | S8: =P8/$O$16 -> 0.56260853 | T8: =Q8/$O$16 -> 3.7694771
B9: Proporção de Cal | D9: 0.5 | O9: AREIA | P9: =D20/0.018 -> 14.610493 | Q9: =D20/0.01 -> 26.298888 | S9: =P9/$O$16 -> 18.847386 | T9: =Q9/$O$16 -> 33.925294
B10: Proporção de Areia | D10: 4.5
B11: Largura da Junta | D11: 1 | E11: cm | O11: ÁGUA | P11: =$O$12*P7 -> 1.4610493 | Q11: =$O$12*Q7 -> 2.6298888 | S11: VOLUME DE ARGAMASSA
B12: Largura Tijolo | D12: 19 | E12: cm | N12: ÁGUA/CIMENTO | O12: 0.45 | S12: M³/M² | T12: TOTAL M³
B13: Altura Tijolo | D13: 19 | E13: cm | S13: =(1-(D21/D16)*((D14/100)*(D13/100)))*(D12/100) -> 0.020424571 | T13: =S13*D16 -> 0.27132
B14: Comprimento Tijolo | D14: 39 | E14: cm | N14: QTD | O14: BETONEIRA 400L (350L)
B15: Peso do bloco | D15: 16 | E15: kg
B16: Área de Parede | D16: ='MURO DE ARRIMO'!B85 -> 13.284 | E16: m2 | O16: =(T13/0.35) -> 0.7752
B17: Resultado:
B18: Quantidade de cimento | D18: =(D20/D10 )*1400/50 -> 1.6363753 | E18: saco de 50 kg
B19: Quantidade de cal | D19: =( (D20/D10 )* (D9*670 ) )/20 -> 0.97890305 | E19: saco de 20 Kg
B20: Quantidade de areia | D20: =D11*D12* ( (2*D13 )+D14 )*(1.07/((D13+1.5 )* (D14+1.5 )/10000 ))*D16/1000000*1.05 -> 0.26298888 | E20: m3
B21: Quantidade de tijolos | D21: =1/( (D13+1.5 )* (D14+1.5 )/10000 )*D16 -> 160 | E21: unidades
B23: GRAUTE
B24: QTD DE GRAUTES | D24: =ROUNDUP(('MURO DE ARRIMO'!B6-'MURO DE ARRIMO'!B55/100)/(D14/100),0) -> 11 | E24: GRAUTES
B25: ÁREA DO SEPTO | D25: 0.0002365 | E25: M²
B26: VOLUME DE GRAUTE | D26: =D24*D25*'MURO DE ARRIMO'!B5 -> 0.010015775 | E26: M³
B27: PESO ESPECÍFICO GRAUTE | D27: 24 | E27: KN

Sheet KC E KS

Sheet CÁLCULO FECHAMENTO
A1: FECHAMENTO DA ALVENARIA/ MURO APENAS DE BLOCO
A3: Altura do pilar do muro de arrimo | B3: ='MURO DE ARRIMO'!B5 -> 3.85 | C3: m
A4: Fechamento de alvenaria: | B4: ='MURO DE ARRIMO'!B12 -> 1.75 | C4: m | D4: Fc: | E4: ='MURO DE ARRIMO'!B18 -> 8 | F4: Mpa
A5: Espessura blocos | B5: ='MURO DE ARRIMO'!B13 -> 14 | C5: cm | D5: Fyk: | E5: 500 | F5: Mpa
A6: Espessura parede do bloco: | B6: ='MURO DE ARRIMO'!B16 -> 2 | C6: cm
A7: Largura do bloco: | B7: ='MURO DE ARRIMO'!B17 -> 39 | C7: cm
A8: Ø Barra: | B8: ='MURO DE ARRIMO'!B19 -> 8 | C8: mm
A9: Espaçamento a cada: | B9: =ROUNDDOWN(((B43/B42)*100)/((B7+1)/2),0) -> 0 | C9: furos
A11: Esbeltez do pilar abaixo do limite? | B11: =IF(B27<30,"Sim","Não") -> Sim
A12: Esbeltez da alvenaria abaixo do limite? | B12: =IF(B26<30,"Sim","Não") -> Sim
A13: Momento abaixo do limite? | B13: =IF(B40<0.4,"Sim","Não") -> Sim
A14: Resiste ao cisalhamento? | B14: =IF(B47>B46,"Sim","Não") -> Sim
A15: Resiste a carga gravitacional? | B15: =IF(B53>B52,"Sim","Não") -> #DIV/0!
A17: Sim | B17: 1
A18: Apenas 50% de coesão | B18: 0.5
A19: Não | B19: 0
A21: Distância entre pilares: | B21: ='MURO DE ARRIMO'!B6 -> 4.25
A22: Momento - base do pilar: | B22: =B21*B39*10 -> 2159.5915 | C22: kgf.m
A23: Força horizontal - base pilar: | B23: =B21*B46 -> 6.7610783 | C23: tf
A26: Esbeltez da alvenaria: | B26: =B4*100/B5*2 -> 25 | C26: cm/cm
A27: Esbeltez do pilar: | B27: =B4*100/'MURO DE ARRIMO'!B54*2 -> 11.666667 | C27: cm/cm
A28: Área efeitva: | B28: =B7*B6*2+(B5-2*B6)*B6*3 -> 216 | C28: cm²
A29: Área por metro: | B29: =B28*100/(B7+1) -> 540 | C29: cm²
A30: Fcd: | B30: =E4/100/2 -> 0.04 | C30: tf/cm²
A31: Fyd: | B31: =E5/100/2 -> 2.5 | C31: tf/cm²
A33: EMPUXO NA ALVENARIA
A34: Empuxo ativo: | B34: =VLOOKUP('MURO DE ARRIMO'!B3,A56:D63,2,FALSE)*VLOOKUP('MURO DE ARRIMO'!B3,A56:D63,3,FALSE)*B3 -> 4.33125 | C34: tf/m²
A35: Coesão | B35: =VLOOKUP('MURO DE ARRIMO'!B3,A56:D63,4,FALSE)*VLOOKUP('MURO DE ARRIMO'!B3,A56:D63,3,FALSE)^0.5 -> 1.9595918 | C35: tf/m²
A36: Altura efetiva: | B36: =(B34-B35)/B34*B4 -> 0.95824574 | C36: m
A38: MOMENTO FLETOR
A39: Md (aplicar na fundação): | B39: =(B34-B35)*B36^2/6*1.4*100 -> 50.813918 | C39: tf.cm/m
A40: μ (mi) | B40: =B39/(B5/2)^2/100/B30 -> 0.25925468
A41: ξ (xi) | B41: =1-(1-2*B40)^0.5 -> 0.30610474
A42: Área de aço (As) | B42: =B41*(B5/2)*100*B30/B31 -> 3.4283731 | C42: cm²/m
A43: As barra: | B43: =(B8/10)^2*3.141592/4 -> 0.50265472 | C43: cm²
A45: CISALHAMENTO
A46: Vd (aplicar na fundação): | B46: =(B34-B35)*B36/2*1.4 -> 1.590842 | C46: Tf/m
A47: Vr: | B47: =MIN(0.35+17.5*B42/100/(B5/2),0.7)/100*B29 -> 2.3528304 | C47: Tf/m
A49: PESO PRÓPRIO
A50: Peso do bloco: | B50: =B29/100^2*2.2*B4 -> 0.2079 | C50: tf/m
...

Sheet FECHAMENTO EM ALVENARIA
B1: ALVENARIA ESTRUTURAL - FLEXÃO SIMPLES SEÇÃO RETANGULAR ARMADURA SIMPLES
B2: d (espessura - 5 cm) | C2: ='MURO DE ARRIMO'!B13-5 -> 9 | D2: cm | J2: DADOS FECHAMENTO EM ALVENARIA:
B3: bw (largura da alvenaria | C3: 100 | D3: cm | J3: Fechamento da alvenaria (até 2 metros) | K3: 2.4
B4: Aço CA50 | C4: 50 | J4: Espessura dos blocos: | K4: 19
B5: Resistência característica do blocofbk (Mpa) | C5: ='MURO DE ARRIMO'!B18 -> 8 | J5: Porcentagem de graute: | K5: 0.5
B6: Fator de Eficiência (%) | C6: 0.8 | D6: fpk,oco | E6: =C5*C6 -> 6.4 | F6: Mpa | J6: Momento solicitante (Mk) - Líbano | K6: =MAX('TABELAS LÍBANO'!#REF!) -> #REF!
B7: fpk,cheio / fpk,oco (%) | C7: 0.8 | J7: Espessura parede do bloco: | K7: 2
B8: Porcentagem de graute | C8: ='MURO DE ARRIMO'!B14 -> 0.5 | D8: fpk,cheio | E8: =E6*(1+C7*C8) -> 8.96 | F8: Mpa | J8: Largura do bloco: | K8: 39
B9: Mk | C9: ='MURO DE ARRIMO'!B15 -> 23.555733 | D9: KN.m | J9: Resistência a compressão bloco | K9: 8
J10: Ø Barra: | K10: 10
B11: Valores de cálculo | J11: Espaçamento a cada: | K11: ='FECHAMENTO EM ALVENARIA'!N39 -> 0
B12: fd | C12: =E8/10*0.7/2 -> 0.3136 | D12: kN/cm²
B13: fyd | C13: =C4/1.15 -> 43.478261 | D13: kN/cm²
B14: Md | C14: =1.4*C9*100 -> 3297.8026 | D14: KN.cm
B15: Cálculo de εyd
B16: εyd | C16: =C13/21000 -> 0.0020703934
B17: Limíte dos domínios
B18: x2lim | C18: =0.23*C2 -> 2.07 | D18: cm
B19: x3lim | C19: =(0.003/(0.003+C16))*C2 -> 5.3250306 | D19: cm
B20: Cálculo de x
B21: 1 | C21: x² - | D21: =2.5*C2 -> 22.5 | E21: x + | F21: =C14/(0.32*C3*C12) -> 328.62351 | G21: = 0
B22: Δ | C22: =D21^2-4*B21*F21 -> -808.24404 | E22: =IF(C22<0,"**IMPOSSÍVEL DIMENSIONAR!**","") -> **IMPOSSÍVEL DIMENSIONAR!**
B23: x | C23: =(D21-SQRT(C22))/2 -> #NUM! | D23: cm
B24: βx | C24: =C23/C2 -> #NUM! | D24: =IF(C24>0.45,"**REDIMENSIONAR!","") -> #NUM!
B25: Verificação do Domínio
B26: =IF(C23<C18,"DOMÍNIO2","") -> #NUM!
B27: =IF(AND((C23>C18),(C23<C19)),"DOMÍNIO3","") -> #NUM!
B28: =IF(C23>C19,"DOMÍNIO4","") -> #NUM!
B30: CÁLCULO DA TENSÃO NO AÇO
B31: σ s = | C31: =IF(OR(B26="DOMÍNIO2",B27="DOMÍNIO3"),"fyd","Es*EpsS") -> #NUM! | D31: =IF(C31="fyd","=","") -> #NUM! | E31: =IF(C31="fyd",C13,"") -> #NUM!
B32: =IF(C31="Es*EpsS","Cálculo da deformação no aço pois é Domínio 4!","") -> #NUM!
B34: =IF(C31="Es*EpsS","EpsS =","") -> #NUM! | C34: =IF(C31="Es*EpsS",0.003*(C2-C23)/C23,"") -> #NUM!
B36: σ s | C36: =IF(C31="Es*EpsS",C34*21000,E31) -> #NUM! | D36: kN/cm²
B38: =IF(C31="Es*EpsS","Obs: εs =EpsS","") -> #NUM!
B40: Cálculo de Rc
B41: Rc | C41: =0.8*C3*C12*C23 -> #NUM! | D41: kN
B43: Cálculo de As
B44: As | C44: =C41/C36 -> #NUM! | D44: cm² | E44: =MAX(C44:C45) -> #NUM! | F44: cm²
B45: As,min | C45: =0.1/100*C3*(C2+4) -> 1.3 | D45: cm²
B48: φ | C48: ='MURO DE ARRIMO'!B19 -> 8 | D48: C/ | E48: =(0.1*C48)^2*PI()/4*100/E44 -> #NUM! | F48: espaçamento p/painéis
...

Sheet TABELAS LÍBANO
A1: La | B1: ='MURO DE ARRIMO'!B5 -> 3.85
A2: Lb | B2: ='MURO DE ARRIMO'!B6 -> 4.25
A3: y | B3: =B1/B2 -> 0.90588235
A4: μx | B4: 2.06 | D4: mμx | E4: =($B$7*$B$8^2/100)*B4 -> 7.6177096 | F4: Kn.m/m
A5: μ'x | B5: 6.37 | D5: mμ'x | E5: =($B$7*$B$8^2/100)*B5 -> 23.555733 | F5: Kn.m/m
A6: μy | B6: 2.4 | D6: mμy | E6: =($B$7*$B$8^2/100)*B6 -> 8.8750015 | F6: Kn.m/m
A7: p | B7: ='MURO DE ARRIMO'!B35 -> 24.948
A8: l (menor entre La e Lb | B8: =MIN(B1:B2) -> 3.85
