Workbook
Name FirstX: #REF!
Name FirstX: 'Propriedades geométricas chavet'!$B$6
Name FirstX: 'Propriedades geométricas LA '!$B$6
Name FirstX: 'Propriedades geométricas VI'!$B$6
Name FirstX: #REF!
Name FirstX: #REF!
Name FirstX: 'Valores "A" e "Y"'!$B$6
Name FirstX: 'Valores "A" e "Y" Alv. Preenc.'!$B$6
Name FirstX: #REF!
Name testex: #REF!
Name testey: #REF!
Name X: OFFSET(FirstX,0,0,COUNT(#REF!))
Name X: OFFSET(FirstX,0,0,COUNT(#REF!))
Name X: OFFSET(Homogeneização!FirstX,0,0,COUNT(#REF!))
Name X: OFFSET('Propriedades geométricas chavet'!FirstX,0,0,COUNT('Propriedades geométricas chavet'!$B$1:$B$65531))
Name X: OFFSET('Propriedades geométricas LA '!FirstX,0,0,COUNT('Propriedades geométricas LA '!$B$1:$B$65531))
Name X: OFFSET('Propriedades geométricas VI'!FirstX,0,0,COUNT('Propriedades geométricas VI'!$B$1:$B$65531))
Name X: OFFSET('Seções '!FirstX,0,0,COUNT(#REF!))
Name X: OFFSET('Seções Compostas'!FirstX,0,0,COUNT(#REF!))
Name X: OFFSET('Valores "A" e "Y"'!FirstX,0,0,COUNT('Valores "A" e "Y"'!$B$1:$B$65531))
Name X: OFFSET('Valores "A" e "Y" Alv. Preenc.'!FirstX,0,0,COUNT('Valores "A" e "Y" Alv. Preenc.'!$B$1:$B$65531))
Name X: OFFSET(FirstX,0,0,COUNT(#REF!))
Name XX: #REF!
Name XXX: #REF!
Name XXXX: #REF!
Name Y: OFFSET('ELU-Cisalhamento'!X,0,1)
Name Y: OFFSET(Frequência!X,0,1)
Name Y: OFFSET(Homogeneização!X,0,1)
Name Y: OFFSET('Propriedades geométricas chavet'!X,0,1)
Name Y: OFFSET('Propriedades geométricas LA '!X,0,1)
Name Y: OFFSET('Propriedades geométricas VI'!X,0,1)
Name Y: OFFSET('Seções '!X,0,1)
Name Y: OFFSET('Seções Compostas'!X,0,1)
Name Y: OFFSET('Valores "A" e "Y"'!X,0,1)
Name Y: OFFSET('Valores "A" e "Y" Alv. Preenc.'!X,0,1)
Name Y: OFFSET(X,0,1)
Name YY: #REF!
Name YYY: #REF!
Name YYYY: #REF!

Sheet ELU-Cisalhamento
C2: CARREGAMENTOS LINEARES | F2: COEFICIENTES DE PONDERAÇÃO
C3: g1 - peso próprio | D3: =Geometria!I73 -> 3.8972079 | F3: γf,g1 | G3: =Geometria!K51 -> 1.3
C4: g2 - peso capa e chaveta | D4: =Geometria!I75+Geometria!I74 -> 2.3825525 | F4: γf,g2 | G4: =Geometria!K52 -> 1.4
C5: g3 - revestimento | D5: =Geometria!I76 -> 3.75 | F5: γf,g3-g4-g5 | G5: =G4 -> 1.4
C6: g4 - alvenaria | D6: =Geometria!I77 -> 0 | F6: γf,q | G6: =G5 -> 1.4
C7: g5 - outras permanentes | F7: γc,pré | G7: =G3 -> 1.3
C8: q1 - acidental 1 | D8: =Geometria!I78 -> 4.75 | F8: γc,capa | G8: =G5 -> 1.4
C9: q2 - acidental 2 | D9: 0 | F9: γs | G9: 1.1
C10: total | D10: =SUM(D3:D9) -> 14.77976 | F10: γp, benéfico | G10: 0.9
C12: 1. Verificação da tensão de cisalhamento na interface entre capa e laje
C14: c | D14: 0.45 | F14: β | G14: =[1]Entrada!K993 -> 0.56966491
C15: fck,capa | D15: =Geometria!H59 -> 30 | F15: h | G15: =Geometria!H23 -> 25
C16: fct,m (fck até 50 Mpa) | D16: =0.3*D15^(2/3) -> 2.8964682 | F16: x (0,5.h) | G16: =0.5*G15 -> 12.5
C17: fct,m (fck > 50 MPa) | D17: =2.12*LN(1+0.1*(D15+8)) -> 3.3254657 | F17: Vsd(x) | G17: =(D3*G3+D4*G4+(D5+D6+D7)*G5+G6*(D8+D9))*(D30-2*G16)/200 -> 97.144801
C18: fct,m adotado | D18: =IF(D15<=50,D16,D17) -> 2.8964682 | F18: d,comp | G18: =Geometria!H23+Geometria!H33-Geometria!N52 -> 26.5
C19: fctk,inf | D19: =0.7*D18 -> 2.0275277 | F19: z | G19: =G18-('[1]ELU-Flexão'!E43*'[1]ELU-Flexão'!F51*0.5) -> 22.989164
C20: fctd,capa | D20: =D19/G4 -> 1.4482341 | F20: b | G20: ='[1]Dados de Entrada'!C8 -> 121.2
C21: fctd,capa | D21: =D20/10 -> 0.14482341 | F21: υEd | G21: =G14*G17/(G19*G20) -> 0.019861554
C22: υRd | D22: =D21*D14 -> 0.065170533 | F22: Situação | G22: =IF(G21<=D22,"Pode-se considerar seção composta!","Considerar laje sem capa!") -> Pode-se considerar seção composta!
C24: Considerar seção composta? | D24: Sim
C26: 2. Verificação de cálculo da resistência à flexo-cortante em regiões fissuradas por flexão e lajes com h ≤ 20 cm
C28: 2.1 Força Cortante de cálculo na seção crítica
C30: Vão total | D30: =Geometria!H21 -> 982
C31: la | D31: 0
C32: h | D32: =Geometria!H23 -> 25
C33: x (0,5.h) | D33: =0.5*D32 -> 12.5
C34: Vão cálculo | D34: =D30-D31-2*D33 -> 957
C35: VSd | D35: =(D34)*0.01*(G3*D3+G4*D4+G5*(D5+D6+D7)+G6*(D8+D9))*0.5 -> 97.144801
C37: 2.2 Verificação das diagonais comprimidas
C39: 2.2.1 Sem capa e Sem alvéolos preenchidos
C41: d (pré) | D41: =Geometria!H23-Geometria!N52 -> 21.5
C42: fck | D42: =Geometria!H58 -> 50
C43: ν | D43: =IF(0.7-D42/200<0.5,0.5,0.7-D42/200) -> 0.5
C44: fcd | D44: =D42/G7 -> 38.461538
C45: ∑bw1 | D45: =Geometria!H27 -> 31
C46: VRd,dc | D46: =0.5*D43*(D44/10)*0.9*D41*D45 -> 576.77885
C47: Situação | D47: =IF(D46>=D35,"Ok, Resiste!","Não Ok!""") -> Ok, Resiste!
C49: d | D49: =G18 -> 26.5
C50: fck | D50: =D42 -> 50
C51: ν | D51: =IF(0.7-D50/200<0.5,0.5,0.7-D50/200) -> 0.5
...

Sheet Geometria
G1: Homogeneizar seção? | H1: TRUE | I1: Deformações t=1 | K1: =L1000 -> -1.4113561 | L1: =IF(H23=20,"CALCULAR PELO MÉTODO ANTIGO","Método de cálculo") -> Método de cálculo | M1: NBR 14861/2022
I2: Deformações diferidas - t=inf | K2: =H1000 -> 0.14922692 | L2: Cortante | M2: =M13 -> 96.579745
I3: As | K3: =CONCATENATE(L24, " + ",L20) -> 8Ø12,7mm + 0 | L3: Vrd | M3: =M15 -> 136.86824
G5: Cargas atuantes
G6: Sobrecarga da laje = q0 | H6: 300 | I6: kgf/m² | L6: =H857 -> Domínio 3
G7: Laje = g1 | I7: kgf/m²
G8: Revestimento = g2 | H8: 300 | I8: kgf/m²
G9: Alvenaria = g3 | H9: =H11/100*H12*H13/100 -> 0 | I9: kgf/m | L9: Método de cálculo | M9: =IF(L1="CALCULAR PELO MÉTODO ANTIGO","NBR 14861/2002",M1) -> NBR 14861/2022
G11: e,alv | H11: 0 | I11: cm | L11: Preencher alvéolos? (Qtd) | M11: 0
G12: y,alv | H12: 1800 | I12: kgf/m²
G13: h,alv | H13: 220 | I13: cm | L13: Vd | M13: =IF(M9="NBR 14861/2022",'Cisalhamento 14861'!$C$132,((I73*K51)+(I74+I75+I76+I77+I78)*K52)*(H21/100)/2) -> 96.579745
G15: Considerar solidarização | I15: 1 - Sim | L15: Vrd,mín | M15: =IF(M9="NBR 14861/2022",'Cisalhamento 14861'!$C$133,H1214) -> 136.86824
G16: Seção | I16: 1 - Retângular
G17: Tipo de alveolo | I17: 2 - Não Circular | L17: =IF(M9="NBR 14861/2022",IF('Cisalhamento 14861'!$C$135="Ok!","Cisalhamento Ok","Reprova no cisalhamento"),IF(M13>M15,"Reprova no cisalhamento","Cisalhamento Ok")) -> Cisalhamento Ok | AD17: Tabela 11.2 – Valores do coeficiente γf2
G19: Geometria da viga retângular | L19: As'
H20: Simples | I20: Composta | L20: =IF(SUM(J131,J133,J135,J137)>0,(CONCATENATE(SUM(J131,J133,J135,J137),"Ø",H138,"mm")),) -> 0 | AK20: Ações | AL20: γf2
G21: L,vão | H21: 982 | J21: Tamanho da laje. | AL21: Ψ0 | AM21: Ψ1 | AN21: Ψ2
G22: bw | H22: 125 | J22: Largura da laje. | AK22: Cargas de utilização de edificações
G23: h | H23: 25 | J23: Altura da laje. | L23: As | AK23: Locais em que não há predominância de pesos de equipamentos que permanecem fixos por longos períodos de tempo, nem de elevadas concentrações de pessoas b | AL23: 0.5 | AM23: 0.4 | AN23: 0.3
G24: y'.1 | H24: =IF(H1=TRUE,Homogeneização!L13,'Propriedades geométricas VI'!M7) -> 12.451124 | I24: =IF(H1=TRUE,Homogeneização!L34,IF(I15="1 - Sim",'Propriedades geométricas LA '!M7,H24)) -> 16.001789 | J24: Centro de gravidade até a borda inferiror. | L24: =CONCATENATE(SUM(J118,J120,J122,J124),"Ø",H121,"mm") -> 8Ø12,7mm
G25: y'.2 | H25: =IF(H1=TRUE,Homogeneização!L12,'Propriedades geométricas VI'!M8) -> 12.548876 | I25: =IF(H1=TRUE,Homogeneização!L33,IF(I15="1 - Sim",'Propriedades geométricas LA '!M8,H25)) -> 13.998211 | J25: Centro de gravidade até a borda superior.
G26: La | H26: 14 | J26: Comprimento de apoio em viga.
G27: bw,ef | H27: 31 | J27: Largura da base considerando somente concreto. | L27: Deformações t=1 | AK27: Locais em que há predominância de pesos de equipamentos que permanecem fixos por longos períodos de tempo, ou de elevada concentração de pessoas c | AL27: 0.7 | AM27: 0.6 | AN27: 0.4
L28: =L1000 -> -1.4113561
G29: Geometria da mesa colaborante | AK29: Biblioteca, arquivos, oficinas e garagens | AL29: 0.8 | AM29: 0.7 | AN29: 0.6
G30: H,laje | H30: =H23 -> 25 | J30: Altura da laje.
G31: L,mc | H31: ='Seções '!B10-'Seções '!B9 -> 121.19 | I31: =IF(I15="1 - Sim",H31*H67,0) -> 93.87337 | J31: Largura da mesa colaborante. | L31: Deformações diferidas - t=inf | AK31: Vento
G32: L,apoio | H32: =H22 -> 125 | I32: =IF(I15="1 - Sim",H32*H67,0) -> 96.824584 | J32: Largura de apoio da mesa colaborante. | L32: =H1000 -> 0.14922692 | AK32: Pressão dinâmica do vento nas estruturas em geral | AL32: 0.6 | AM32: 0.3 | AN32: 0
G33: H,capa | H33: 5 | J33: Altura da capa de concreto.
G34: Hy,capa | H34: 7 | I34: =H33+3 -> 8 | J34: Altura da capa de concreto considerando contraflechas. | AK34: Temperatura
G35: Dados | AK35: Variações uniformes de temperatura em relação à média anual local | AL35: 0.6 | AM35: 0.5 | AN35: 0.3
G36: Ac | H36: =IF(H1=TRUE,Homogeneização!L9,'Propriedades geométricas VI'!M6) -> 1558.8832 | I36: =IF(H1=TRUE,Homogeneização!L30,IF(I15="1 - Sim",'Propriedades geométricas LA '!M6,H36)) -> 2017.6942 | J36: Área de concreto da seção transversal.
G37: Ic | H37: =IF(H1=TRUE,Homogeneização!L15,'Propriedades geométricas VI'!M9) -> 124422.7 | I37: =IF(H1=TRUE,Homogeneização!L36,IF(I15="1 - Sim",'Propriedades geométricas LA '!M9,H37)) -> 205322.42 | J37: Inércia da seção transversal.
G38: hcg,sup | H38: =H167/100 -> 0.094511237 | J38: Altura do centro de gravidade até o centro da armadura superior.
G39: hcg,inf | H39: =H169/100 -> 0.12548876 | J39: Altura do centro de gravidade até o centro da armadura inferior.
G40: W,sup | H40: =IF(H1=TRUE,Homogeneização!L20,'Propriedades geométricas VI'!M11) -> 9915.0468 | I40: =IF(H1=TRUE,Homogeneização!L41,IF(I15="1 - Sim",'Propriedades geométricas LA '!M11,H40)) -> 14667.761 | J40: Módulo resistente da fibra superior.
G41: W,inf | H41: =IF(H1=TRUE,Homogeneização!L21,'Propriedades geométricas VI'!M10) -> 9992.8889 | I41: =IF(H1=TRUE,Homogeneização!L42,IF(I15="1 - Sim",'Propriedades geométricas LA '!M10,H41)) -> 12831.216 | J41: Módulo resistente da fibra inferior.
G42: K1 | H42: =H41/H36 -> 6.4102873 | J42: Distância nuclear inferior.
G43: K2 | H43: =H40/H36 -> 6.3603528 | J43: Distância nuclear superior.
G44: Rendimento | H44: =(H43+H42)/H23 -> 0.5108256 | J44: Rendimento da protensão.
...

Sheet Cisalhamento 14861
B1: VERIFICAÇÃO DA FORÇA CORTANTE – NBR 14861:2022 (complemento da aba Geometria)
B2: Células sombreadas = entrada. Demais valores vêm da aba Geometria. Unidades: kN, cm (salvo indicação). O resumo final alimenta a tabela Vd / VRd do topo da aba Geometria.
B4: 0. Parâmetros complementares (entrada)
B5: γc,pré | C5: 1.3 | D5: – | E5: Coeficiente de ponderação do concreto da laje pré-fabricada (NBR 9062 – produção com controle rigoroso). Mesmo valor da planilha de apoio.
B6: γc,capa | C6: 1.4 | D6: – | E6: Coeficiente de ponderação do concreto moldado no local (capa).
B7: Preenchimento dos alvéolos | C7: Antes da liberação | E7: Antes da liberação: σcp = Np/Ac,2 atua em Σbw,2 (preenchido fresco na pista). Após a liberação: o preenchimento não recebe protensão → Vp = 0,15·σcp,1·Σbw,1·d.
B8: fck,alv | C8: =Geometria!H58 -> 50 | D8: MPa | E8: fck do concreto de preenchimento (padrão = concreto da laje). Se o preenchimento for feito na obra, informar o fck do graute/concreto usado.
B9: αE,alv | C9: =Geometria!H864 -> 1 | D9: – | E9: Agregado do preenchimento: 1,2 basalto/diabásio · 1,0 granito/gnaisse · 0,9 calcário · 0,7 arenito.
B10: c (interface) | C10: 0.45 | D10: – | E10: Coeficiente da interface capa × laje: 0,45 superfície não lisa · 0,35 superfície lisa (fck ≥ 30 MPa).
B11: γp (favorável) | C11: 0.9 | D11: – | E11: Coeficiente de ponderação da protensão favorável no ELU (NBR 6118, 11.7.1), aplicado em σcp (tração diagonal e flexo-cortante). Usar 1,0 para reproduzir a planilha de apoio.
B12: 1. Seção transversal (propriedades brutas, sem homogeneização)
B13: h | C13: =Geometria!H23 -> 25 | D13: cm | E13: Altura da laje pré-fabricada.
B14: Capa estrutural | C14: =IF(Geometria!I15="1 - Sim","Sim","Não") -> Sim | E14: Conforme 'Considerar solidarização' (Geometria I15).
B15: hcapa | C15: =IF(C14="Sim",Geometria!H33,0) -> 5 | D15: cm | E15: Espessura de capa considerada.
B16: d'p | C16: =Geometria!H144 -> 3 | D16: cm | E16: Posição do CG da armadura ativa inferior em relação à face inferior.
B17: d (pré) | C17: =C13-C16 -> 22 | D17: cm | E17: Altura útil da seção pré-fabricada.
B18: d (serviço) | C18: =C13+C15-C16 -> 27 | D18: cm | E18: Altura útil da seção em serviço (com capa, se houver).
B19: Σbw | C19: =Geometria!H27 -> 31 | D19: cm | E19: Soma das larguras das nervuras.
B20: Ac | C20: ='Propriedades geométricas VI'!M6 -> 1513.0702 | D20: cm² | E20: Área bruta da seção pré-fabricada.
B21: ycg | C21: ='Propriedades geométricas VI'!M7 -> 12.737286 | D21: cm | E21: CG da seção pré-fabricada até a face inferior.
B22: I | C22: ='Propriedades geométricas VI'!M9 -> 120206.61 | D22: cm⁴ | E22: Inércia bruta da seção pré-fabricada.
B23: nº de nós | C23: =COUNT('Propriedades geométricas VI'!$B$6:$B$400) -> 253 | D23: – | E23: Nós do polígono da seção (aba 'Propriedades geométricas VI').
B24: A,sup | C24: =ABS(SUMPRODUCT((((OFFSET('Propriedades geométricas VI'!$C$6,0,0,$C$23-1,1))+$C$21+ABS((OFFSET('Propriedades geométricas VI'!$C$6,0,0,$C$23-1,1))-$C$21))/2-((OFFSET('Propriedades geométricas VI'!$C$7,0,0,$C$23-1,1))+$C$21+ABS((OFFSET('Propriedades geométricas VI'!$C$7,0,0,$C$23-1,1))-$C$21))/2)*((OFFSET('Propriedades geométricas VI'!$B$6,0,0,$C$23-1,1))+(OFFSET('Propriedades geométricas VI'!$B$7,0,0,$C$23-1,1)))))/2 -> 774.56433 | D24: cm² | E24: Área acima do CG (polígono recortado em y = ycg).
B25: Q,sup | C25: =ABS(SUMPRODUCT(((OFFSET('Propriedades geométricas VI'!$B$7,0,0,$C$23-1,1))-(OFFSET('Propriedades geométricas VI'!$B$6,0,0,$C$23-1,1)))*((((OFFSET('Propriedades geométricas VI'!$C$6,0,0,$C$23-1,1))+$C$21+ABS((OFFSET('Propriedades geométricas VI'!$C$6,0,0,$C$23-1,1))-$C$21))/2+((OFFSET('Propriedades geométricas VI'!$C$7,0,0,$C$23-1,1))+$C$21+ABS((OFFSET('Propriedades geométricas VI'!$C$7,0,0,$C$23-1,1))-$C$21))/2)^2+(((OFFSET('Propriedades geométricas VI'!$C$7,0,0,$C$23-1,1))+$C$21+ABS((OFFSET('Propriedades geométricas VI'!$C$7,0,0,$C$23-1,1))-$C$21))/2-((OFFSET('Propriedades geométricas VI'!$C$6,0,0,$C$23-1,1))+$C$21+ABS((OFFSET('Propriedades geométricas VI'!$C$6,0,0,$C$23-1,1))-$C$21))/2)^2/3)))/8 -> 16082.448 | D25: cm³ | E25: Momento estático da área acima do CG em relação à base.
B26: y,sup | C26: =C25/C24-C21 -> 8.0259323 | D26: cm | E26: Distância do CG da área acima ao CG da seção.
B27: S | C27: =C24*C26 -> 6216.6009 | D27: cm³ | E27: Momento estático no CG – seção pré-fabricada.
B28: I' | C28: =IF(C14="Sim",'Propriedades geométricas LA '!M9,C22) -> 199263.1 | D28: cm⁴ | E28: Inércia da seção composta (capa com largura reduzida por Ecapa/Elaje).
B29: S' | C29: =IF(C14="Sim",'Valores "A" e "Y"'!M6*'Valores "A" e "Y"'!M16,C27) -> 8442.5163 | D29: cm³ | E29: Momento estático no CG da seção composta.
B30: n,alv | C30: =Geometria!M11 -> 0 | D30: – | E30: Número de alvéolos preenchidos (topo da aba Geometria).
B31: b,alv | C31: =Geometria!H1204*100 -> 12.5 | D31: cm | E31: Largura do alvéolo.
B32: A,alv | C32: =VLOOKUP(Geometria!H23,Geometria!L1204:M1206,2,FALSE)*10000 -> 212 | D32: cm² | E32: Área de um alvéolo (tabela Geometria L1204:M1206).
B33: hpc | C33: =Geometria!H1050 -> 5.8 | D33: cm | E33: Altura do ponto crítico na nervura (menor largura).
B35: 2. Materiais
B36: fck | C36: =Geometria!H58 -> 50 | D36: MPa | E36: Concreto da laje.
B37: fctk,inf | C37: =IF(C36<=50,0.21*C36^(2/3),0.7*2.12*LN(1+0.11*C36)) -> 2.8501385 | D37: MPa | E37: NBR 6118, 8.2.5.
B38: fctd | C38: =C37/C5/10 -> 0.21924142 | D38: kN/cm² | E38: fctk,inf/γc,pré
B39: fcd | C39: =C36/C5/10 -> 3.8461538 | D39: kN/cm² | E39: fck/γc,pré
B40: fck,capa | C40: =Geometria!H59 -> 30 | D40: MPa | E40: Concreto da capa.
B41: fctd,capa | C41: =IF(C40<=50,0.21*C40^(2/3),0.7*2.12*LN(1+0.11*C40))/C6/10 -> 0.14482341 | D41: kN/cm² | E41: fctk,inf,capa/γc,capa
B42: fcd,capa | C42: =C40/C6/10 -> 2.1428571 | D42: kN/cm² | E42: fck,capa/γc,capa
...

Sheet Diagrama cortante
F3: Momento fletor
F4: S1 | G4: S2 | H4: S3 | I4: S4 | J4: S5 | K4: S6 | L4: S7 | M4: S8 | N4: S9
F5: =Geometria!G1254 -> 0 | G5: =Geometria!H1254 -> 1.2275 | H5: =Geometria!I1254 -> 2.455 | I5: =Geometria!J1254 -> 3.6825 | J5: =Geometria!K1254 -> 4.91 | K5: =Geometria!L1254 -> 6.1375 | L5: =Geometria!M1254 -> 7.365 | M5: =Geometria!N1254 -> 8.5925 | N5: =Geometria!G1257 -> 9.82
F6: =(((-($I$78+#REF!+#REF!)*($H$21/100)^2)/12)*(3*($H$1222*(1-F5/($H$21/100))+$H$1228*F5/($H$21/100)))/(2+($H$1222*(1-F5/($H$21/100))+$H$1228*F5/($H$21/100)))+(((($I$78+#REF!+#REF!)*$H$21/100)/2)*F5)-(($I$78+#REF!+#REF!)*F5^2)/2)*-1 -> #REF! | G6: =(((-($I$78+#REF!+#REF!)*($H$21/100)^2)/12)*(3*($H$1222*(1-G5/($H$21/100))+$H$1228*G5/($H$21/100)))/(2+($H$1222*(1-G5/($H$21/100))+$H$1228*G5/($H$21/100)))+(((($I$78+#REF!+#REF!)*$H$21/100)/2)*G5)-(($I$78+#REF!+#REF!)*G5^2)/2)*-1 -> #REF! | H6: =(((-($I$78+#REF!+#REF!)*($H$21/100)^2)/12)*(3*($H$1222*(1-H5/($H$21/100))+$H$1228*H5/($H$21/100)))/(2+($H$1222*(1-H5/($H$21/100))+$H$1228*H5/($H$21/100)))+(((($I$78+#REF!+#REF!)*$H$21/100)/2)*H5)-(($I$78+#REF!+#REF!)*H5^2)/2)*-1 -> #REF! | I6: =(((-($I$78+#REF!+#REF!)*($H$21/100)^2)/12)*(3*($H$1222*(1-I5/($H$21/100))+$H$1228*I5/($H$21/100)))/(2+($H$1222*(1-I5/($H$21/100))+$H$1228*I5/($H$21/100)))+(((($I$78+#REF!+#REF!)*$H$21/100)/2)*I5)-(($I$78+#REF!+#REF!)*I5^2)/2)*-1 -> #REF! | J6: =(((-($I$78+#REF!+#REF!)*($H$21/100)^2)/12)*(3*($H$1222*(1-J5/($H$21/100))+$H$1228*J5/($H$21/100)))/(2+($H$1222*(1-J5/($H$21/100))+$H$1228*J5/($H$21/100)))+(((($I$78+#REF!+#REF!)*$H$21/100)/2)*J5)-(($I$78+#REF!+#REF!)*J5^2)/2)*-1 -> #REF! | K6: =(((-($I$78+#REF!+#REF!)*($H$21/100)^2)/12)*(3*($H$1222*(1-K5/($H$21/100))+$H$1228*K5/($H$21/100)))/(2+($H$1222*(1-K5/($H$21/100))+$H$1228*K5/($H$21/100)))+(((($I$78+#REF!+#REF!)*$H$21/100)/2)*K5)-(($I$78+#REF!+#REF!)*K5^2)/2)*-1 -> #REF! | L6: =(((-($I$78+#REF!+#REF!)*($H$21/100)^2)/12)*(3*($H$1222*(1-L5/($H$21/100))+$H$1228*L5/($H$21/100)))/(2+($H$1222*(1-L5/($H$21/100))+$H$1228*L5/($H$21/100)))+(((($I$78+#REF!+#REF!)*$H$21/100)/2)*L5)-(($I$78+#REF!+#REF!)*L5^2)/2)*-1 -> #REF! | M6: =(((-($I$78+#REF!+#REF!)*($H$21/100)^2)/12)*(3*($H$1222*(1-M5/($H$21/100))+$H$1228*M5/($H$21/100)))/(2+($H$1222*(1-M5/($H$21/100))+$H$1228*M5/($H$21/100)))+(((($I$78+#REF!+#REF!)*$H$21/100)/2)*M5)-(($I$78+#REF!+#REF!)*M5^2)/2)*-1 -> #REF! | N6: =(((-($I$78+#REF!+#REF!)*($H$21/100)^2)/12)*(3*($H$1222*(1-N5/($H$21/100))+$H$1228*N5/($H$21/100)))/(2+($H$1222*(1-N5/($H$21/100))+$H$1228*N5/($H$21/100)))+(((($I$78+#REF!+#REF!)*$H$21/100)/2)*N5)-(($I$78+#REF!+#REF!)*N5^2)/2)*-1 -> #REF!
F9: V,esq | G9: =(0.5-0.0625*Geometria!$H$1228)*((Geometria!I73+Geometria!I74+Geometria!I75)*Geometria!K51+(Geometria!I76+Geometria!I77+Geometria!I78)*Geometria!K52)*(Geometria!$H$21/100) -> 95.434188
F10: V,dir | G10: =(0.5+0.0625*Geometria!$H$1228)*((Geometria!I73+Geometria!I74+Geometria!I75)*Geometria!K51+(Geometria!I76+Geometria!I77+Geometria!I78)*Geometria!K52)*(Geometria!$H$21/100) -> 101.59123

Sheet K mola
C6: esquerdo
C7: alfa r | D7: =Geometria!H1222 -> 0.25 | F7: Alfa r
C8: i | D8: =Geometria!I37/100^4 -> 0.0020532242 | E8: m^4 | F8: Inercia
C9: Ecs | D9: =Geometria!H867*10^6 -> 36628131 | E9: kN/m | F9: Modulo de elasticidade secante
C10: L | D10: =Geometria!H21/100 -> 9.82 | E10: m | F10: Comprimento da laje
C12: K0 | D12: =((D7/(1-D7))*4*D9*D8)/D10 -> 10211.237 | E12: kN/m | F12: Coeficiente mola

Sheet Homogeneização
K2: 2 . Homogeneização da seção - Cordoalhas
K4: Ac = | L4: ='Propriedades geométricas VI'!M6 -> 1513.0702 | M4: cm²
K5: I = | L5: ='Propriedades geométricas VI'!M9 -> 120206.61 | M5: cm²
K6: y'.1 = | L6: ='Propriedades geométricas VI'!M7 -> 12.737286 | M6: cm
K7: y'.2 = | L7: ='Propriedades geométricas VI'!M8 -> 12.262714 | M7: cm
K9: Ach = | L9: =L4-(Geometria!H122+Geometria!H139)+L11*(Geometria!H122+Geometria!H139) -> 1558.8832 | M9: cm²
K11: α = | L11: =L52 -> 6.8020463
K12: yhs = | L12: =Geometria!H23-L13 -> 12.548876 | M12: cm
K13: yhi = | L13: =(L4*L6+(L11-1)*Geometria!H122*Geometria!M121+(L11-1)*Geometria!H139*(Geometria!H23-Geometria!M134))/L9 -> 12.451124 | M13: cm
K14: Dy = | L14: =L17 -> 12.548876
K15: Ih = | L15: =L5+L4*(L6-L13)^2+(L11-1)*Geometria!H122*(Geometria!M121-L13)^2+(L11-1)*Geometria!H139*((Geometria!H23-Geometria!M134)-L13)^2 -> 124422.7 | M15: cm^4
K17: yhs = | L17: =Geometria!H23-L18 -> 12.548876
K18: yhi = | L18: =L13 -> 12.451124
K19: Wh
K20: Whs = | L20: =L15/L17 -> 9915.0468 | M20: cm³
K21: Whi = | L21: =L15/L18 -> 9992.8889 | M21: cm³
K23: 2 . Homogeneização da seção composta
K25: Ac = | L25: ='Propriedades geométricas LA '!M6 -> 1982.4758 | M25: cm²
K26: I = | L26: ='Propriedades geométricas LA '!M9 -> 199263.1 | M26: cm²
K27: y'.1 = | L27: ='Propriedades geométricas LA '!M7 -> 16.232764 | M27: cm
K28: y'.2 = | L28: ='Propriedades geométricas LA '!M8 -> 13.767236 | M28: cm
K30: Ach = | L30: =L25-(Geometria!H122+Geometria!H139)+L32*(Geometria!H122+Geometria!H139) -> 2017.6942 | M30: cm²
K32: α = | L32: =L57 -> 5.460284
K33: yhs = | L33: =Geometria!H23+Geometria!H33-L34 -> 13.998211 | M33: cm
K34: yhi = | L34: =(L25*L27+(L32-1)*Geometria!H122*Geometria!M121+(L32-1)*Geometria!H139*(Geometria!H23-Geometria!M134))/L30 -> 16.001789 | M34: cm
K35: Dy = | L35: =L38 -> 13.998211
K36: Ih = | L36: =L26+L25*(L27-L34)^2+(L32-1)*Geometria!H122*(Geometria!M121-L34)^2+(L32-1)*Geometria!H139*((Geometria!H23-Geometria!M134)-L34)^2 -> 205322.42 | M36: cm^4
K38: yhs = | L38: =Geometria!H23+Geometria!H33-L39 -> 13.998211
K39: yhi = | L39: =L34 -> 16.001789
K40: Wh
K41: Whs = | L41: =L36/L38 -> 14667.761 | M41: cm³
K42: Whi = | L42: =L36/L39 -> 12831.216 | M42: cm³
K45: Parâmetros da homogeneização (como na planilha de referência: α = Ep/Ecs(t) para cordoalhas e Es/Ecs(t) para vergalhões)
K47: Ep = | L47: 200000 | M47: MPa | N47: Módulo de elasticidade das cordoalhas (NBR 6118, 8.4.4).
K48: Es = | L48: 210000 | M48: MPa | N48: Módulo de elasticidade dos vergalhões (NBR 6118, 8.3.5).
K49: t,pré = | L49: =Geometria!$I$201 -> 1 | M49: dias | N49: Idade da seção pré-fabricada na homogeneização (ato da protensão).
K50: β1(t,pré) = | L50: =EXP(Fluência!$B$17*(1-(28/L49)^(1/2))) -> 0.42388185 | M50: - | N50: Crescimento da resistência do concreto com a idade.
K51: Ecs(t,pré) = | L51: =MIN(1,0.8+0.2*MAX(Geometria!$H$60,MIN(Geometria!$H$58,L50*Geometria!$H$58))/80)*IF(Geometria!$H$58<=50,(MAX(Geometria!$H$60,MIN(Geometria!$H$58,L50*Geometria!$H$58))/Geometria!$H$58)^0.5,(MAX(Geometria!$H$60,MIN(Geometria!$H$58,L50*Geometria!$H$58))/Geometria!$H$58)^0.3)*Geometria!$H$866*1000 -> 29402.917 | M51: MPa | N51: Módulo secante do concreto da viga nessa idade.
K52: αp,pré = | L52: =L47/L51 -> 6.8020463 | M52: - | N52: Relação Ep/Ecs – cordoalhas na seção pré-fabricada.
K53: αe,pré = | L53: =L48/L51 -> 7.1421486 | M53: - | N53: Relação Es/Ecs – vergalhões na seção pré-fabricada.
...

Sheet Tensões
E1: Np | F1: =Geometria!H749 -> 867.4324 | G1: kN
E2: Mp | F2: =Geometria!H750 -> 81.98211 | G2: kN
A4: ATO | N4: ELS-F, MÁXIMO
C6: Tensão ajustada | D6: Tensão reduzida pelo comprimento de transferência | F6: Tensão calculada | I6: Np | J6: Mp | P6: Tensão ajustada | Q6: Tensão reduzida pelo comprimento de transferência | S6: Tensão calculada | V6: Np | W6: Mp
A8: σi,1 | B8: =IF(Geometria!$G$280<Geometria!$J$1030/100,"Reduzir","OK") -> Reduzir | C8: =IF(B8="Reduzir",D8,F8) -> 0 | D8: 0 | E8: 0 | F8: 0 | I8: 0 | J8: 0 | L8: =C8/1000 -> 0 | N8: σi,1 | O8: =IF(Geometria!$G$280<Geometria!$J$1030/100,"Reduzir","OK") -> Reduzir | P8: =IF(O8="Reduzir",Q8,S8) -> 0 | Q8: 0 | R8: 0 | S8: 0 | V8: 0 | W8: 0 | Y8: =P8/1000 -> 0
A9: σi,2 | B9: =IF(Geometria!$H$280<Geometria!$J$1030/100,"Reduzir","OK") -> OK | C9: =IF(B9="Reduzir",D9,F9) -> 1760.8451 | D9: =-I9/(Geometria!$H$36/100^2)+J9/(Geometria!$H$40/100^3)-Geometria!$H$741/(Geometria!$H$40/100^3) -> 1124.9497 | E9: =('Perdas por Seção'!D60*(Geometria!$H$280*100))/Geometria!$J$1030 -> 117.16985 | F9: =IF(H9="Sim",-('Isolamento de cabos'!$C$26)/(Geometria!$H$36/100^2)+('Isolamento de cabos'!$C$27)/(Geometria!$H$40/100^3)-Geometria!$H$741/(Geometria!$H$40/100^3),IF(M9="Sim",-'Perdas por Seção'!D99/(Geometria!$H$36/100^2)+'Perdas por Seção'!D100/(Geometria!$H$40/100^3)-Geometria!$H$741/(Geometria!$H$40/100^3),-'Perdas por Seção'!D99/(Geometria!$H$36/100^2)+'Perdas por Seção'!D100/(Geometria!$H$40/100^3)-Geometria!$H$741/(Geometria!$H$40/100^3))) -> 1760.8451 | H9: =IF(Geometria!$H$280<'Isolamento de cabos'!$C$8,"Sim","Não") -> Não | I9: =Geometria!$H$166*E32+Geometria!$H$168*E9 -> 649.66269 | J9: =Geometria!$H$166*E32*Geometria!$H$167/100-Geometria!$H$168*E9*Geometria!$H$169/100 -> 61.400425 | L9: =C9/1000 -> 1.7608451 | M9: =IF(Geometria!$H$280<'Isolamento de cabos'!$C$10,"Sim","Não") -> Não | N9: σi,2 | O9: =IF(Geometria!$H$280<Geometria!$J$1030/100,"Reduzir","OK") -> OK | P9: =IF(O9="Reduzir",Q9,S9) -> 92.584347 | Q9: =-(V9/(Geometria!$H$36/100^2))+(W9/(Geometria!$H$40/100^3))-((Geometria!$H$281)/(Geometria!$H$40/100^3))-((Geometria!$H$292)/(Geometria!$H$266))-((Geometria!$H$52*Geometria!$H$303)/(Geometria!$H$266)) -> -434.47014 | R9: =('Perdas por Seção'!D92*(Geometria!$H$280*100))/Geometria!$J$1030 -> 103.3558 | S9: =IF(H9="Sim",-('Isolamento de cabos'!$C$58/(Geometria!$H$36/100^2))+('Isolamento de cabos'!$C$59/(Geometria!$H$40/100^3))-((Geometria!$H$281)/(Geometria!$H$40/100^3))-((Geometria!$H$292)/(Geometria!$H$266))-((Geometria!$H$52*Geometria!$H$303)/(Geometria!$H$266)),IF(M9="Sim",-('Perdas por Seção'!D97/(Geometria!$H$36/100^2))+('Perdas por Seção'!D98/(Geometria!$H$40/100^3))-((Geometria!$H$281)/(Geometria!$H$40/100^3))-((Geometria!$H$292)/(Geometria!$H$266))-((Geometria!$H$52*Geometria!$H$303)/(Geometria!$H$266)),-('Perdas por Seção'!D97/(Geometria!$H$36/100^2))+('Perdas por Seção'!D98/(Geometria!$H$40/100^3))-((Geometria!$H$281)/(Geometria!$H$40/100^3))-((Geometria!$H$292)/(Geometria!$H$266))-((Geometria!$H$52*Geometria!$H$303)/(Geometria!$H$266)))) -> 92.584347 | V9: =Geometria!$H$166*R32+Geometria!$H$168*R9 -> 538.46542 | W9: =Geometria!$H$166*R32*Geometria!$H$167/100-Geometria!$H$168*R9*Geometria!$H$169/100 -> 50.891033 | Y9: =P9/1000 -> 0.092584347
A10: σi,3 | B10: =IF(Geometria!$I$280<Geometria!$J$1030/100,"Reduzir","OK") -> OK | C10: =IF(B10="Reduzir",D10,F10) -> 964.40488 | D10: =-I10/(Geometria!$H$36/100^2)+J10/(Geometria!$H$40/100^3)-Geometria!$I$741/(Geometria!$H$40/100^3) -> 2358.3784 | E10: =('Perdas por Seção'!E60*(Geometria!$I$280*100))/Geometria!$J$1030 -> 232.0719 | F10: =IF(H10="Sim",-('Isolamento de cabos'!$C$26)/(Geometria!$H$36/100^2)+('Isolamento de cabos'!$C$27)/(Geometria!$H$40/100^3)-Geometria!$I$741/(Geometria!$H$40/100^3),IF(M10="Sim",-'Perdas por Seção'!E99/(Geometria!$H$36/100^2)+'Perdas por Seção'!E100/(Geometria!$H$40/100^3)-Geometria!$I$741/(Geometria!$H$40/100^3),-'Perdas por Seção'!E99/(Geometria!$H$36/100^2)+'Perdas por Seção'!E100/(Geometria!$H$40/100^3)-Geometria!$I$741/(Geometria!$H$40/100^3))) -> 964.40488 | H10: =IF(Geometria!$I$280<'Isolamento de cabos'!$C$8,"Sim","Não") -> Não | I10: =Geometria!$H$166*E33+Geometria!$H$168*E10 -> 1303.7266 | J10: =Geometria!$H$166*E33*Geometria!$H$167/100-Geometria!$H$168*E10*Geometria!$H$169/100 -> 123.21681 | L10: =C10/1000 -> 0.96440488 | M10: =IF(Geometria!$I$280<'Isolamento de cabos'!$C$10,"Sim","Não") -> Não | N10: σi,3 | O10: =IF(Geometria!$I$280<Geometria!$J$1030/100,"Reduzir","OK") -> OK | P10: =IF(O10="Reduzir",Q10,S10) -> -1758.7273 | Q10: =-(V10/(Geometria!$H$36/100^2))+(W10/(Geometria!$H$40/100^3))-((Geometria!$I$281)/(Geometria!$H$40/100^3))-((Geometria!$I$292)/(Geometria!$H$266))-((Geometria!$H$52*Geometria!$I$303)/(Geometria!$H$266)) -> -586.74704 | R10: =('Perdas por Seção'!E92*(Geometria!$I$280*100))/Geometria!$J$1030 -> 197.68932 | S10: =IF(H10="Sim",-('Isolamento de cabos'!$C$58/(Geometria!$H$36/100^2))+('Isolamento de cabos'!$C$59/(Geometria!$H$40/100^3))-((Geometria!$I$281)/(Geometria!$H$40/100^3))-((Geometria!$I$292)/(Geometria!$H$266))-((Geometria!$H$52*Geometria!$I$303)/(Geometria!$H$266)),IF(M10="Sim",-('Perdas por Seção'!E97/(Geometria!$H$36/100^2))+('Perdas por Seção'!E98/(Geometria!$H$40/100^3))-((Geometria!$I$281)/(Geometria!$H$40/100^3))-((Geometria!$I$292)/(Geometria!$H$266))-((Geometria!$H$52*Geometria!$I$303)/(Geometria!$H$266)),-('Perdas por Seção'!E97/(Geometria!$H$36/100^2))+('Perdas por Seção'!E98/(Geometria!$H$40/100^3))-((Geometria!$I$281)/(Geometria!$H$40/100^3))-((Geometria!$I$292)/(Geometria!$H$266))-((Geometria!$H$52*Geometria!$I$303)/(Geometria!$H$266)))) -> -1758.7273 | V10: =Geometria!$H$166*R33+Geometria!$H$168*R10 -> 1096.1054 | W10: =Geometria!$H$166*R33*Geometria!$H$167/100-Geometria!$H$168*R10*Geometria!$H$169/100 -> 103.59427 | Y10: =P10/1000 -> -1.7587273
A11: σi,4 | B11: =IF(Geometria!$J$280<Geometria!$J$1030/100,"Reduzir","OK") -> OK | C11: =IF(B11="Reduzir",D11,F11) -> 261.66354 | D11: =-I11/(Geometria!$H$36/100^2)+J11/(Geometria!$H$40/100^3)-Geometria!$J$741/(Geometria!$H$40/100^3) -> 3697.8648 | E11: =('Perdas por Seção'!F60*(Geometria!$J$280*100))/Geometria!$J$1030 -> 345.10636 | F11: =IF(H11="Sim",-('Isolamento de cabos'!$C$26)/(Geometria!$H$36/100^2)+('Isolamento de cabos'!$C$27)/(Geometria!$H$40/100^3)-Geometria!$J$741/(Geometria!$H$40/100^3),IF(M11="Sim",-'Perdas por Seção'!F99/(Geometria!$H$36/100^2)+'Perdas por Seção'!F100/(Geometria!$H$40/100^3)-Geometria!$J$741/(Geometria!$H$40/100^3),-'Perdas por Seção'!F99/(Geometria!$H$36/100^2)+'Perdas por Seção'!F100/(Geometria!$H$40/100^3)-Geometria!$J$741/(Geometria!$H$40/100^3))) -> 261.66354 | H11: =IF(Geometria!$J$280<'Isolamento de cabos'!$C$8,"Sim","Não") -> Não | I11: =Geometria!$H$166*E34+Geometria!$H$168*E11 -> 1961.415 | J11: =Geometria!$H$166*E34*Geometria!$H$167/100-Geometria!$H$168*E11*Geometria!$H$169/100 -> 185.37575 | L11: =C11/1000 -> 0.26166354 | M11: =IF(Geometria!$J$280<'Isolamento de cabos'!$C$10,"Sim","Não") -> Não | N11: σi,4 | O11: =IF(Geometria!$J$280<Geometria!$J$1030/100,"Reduzir","OK") -> OK | P11: =IF(O11="Reduzir",Q11,S11) -> -3392.2751 | Q11: =-(V11/(Geometria!$H$36/100^2))+(W11/(Geometria!$H$40/100^3))-((Geometria!$J$281)/(Geometria!$H$40/100^3))-((Geometria!$J$292)/(Geometria!$H$266))-((Geometria!$H$52*Geometria!$J$303)/(Geometria!$H$266)) -> -467.4643 | R11: =('Perdas por Seção'!F92*(Geometria!$J$280*100))/Geometria!$J$1030 -> 284.59274 | S11: =IF(H11="Sim",-('Isolamento de cabos'!$C$58/(Geometria!$H$36/100^2))+('Isolamento de cabos'!$C$59/(Geometria!$H$40/100^3))-((Geometria!$J$281)/(Geometria!$H$40/100^3))-((Geometria!$J$292)/(Geometria!$H$266))-((Geometria!$H$52*Geometria!$J$303)/(Geometria!$H$266)),IF(M11="Sim",-('Perdas por Seção'!F97/(Geometria!$H$36/100^2))+('Perdas por Seção'!F98/(Geometria!$H$40/100^3))-((Geometria!$J$281)/(Geometria!$H$40/100^3))-((Geometria!$J$292)/(Geometria!$H$266))-((Geometria!$H$52*Geometria!$J$303)/(Geometria!$H$266)),-('Perdas por Seção'!F97/(Geometria!$H$36/100^2))+('Perdas por Seção'!F98/(Geometria!$H$40/100^3))-((Geometria!$J$281)/(Geometria!$H$40/100^3))-((Geometria!$J$292)/(Geometria!$H$266))-((Geometria!$H$52*Geometria!$J$303)/(Geometria!$H$266)))) -> -3392.2751 | V11: =Geometria!$H$166*R34+Geometria!$H$168*R11 -> 1669.5086 | W11: =Geometria!$H$166*R34*Geometria!$H$167/100-Geometria!$H$168*R11*Geometria!$H$169/100 -> 157.78733 | Y11: =P11/1000 -> -3.3922751
A12: σi,5 | B12: =IF(Geometria!$K$280<Geometria!$J$1030/100,"Reduzir","OK") -> OK | C12: =IF(B12="Reduzir",D12,F12) -> -347.37894 | D12: =-I12/(Geometria!$H$36/100^2)+J12/(Geometria!$H$40/100^3)-Geometria!$K$741/(Geometria!$H$40/100^3) -> 5140.9879 | E12: =('Perdas por Seção'!G60*(Geometria!$K$280*100))/Geometria!$J$1030 -> 456.67342 | F12: =IF(H12="Sim",-('Isolamento de cabos'!$C$26)/(Geometria!$H$36/100^2)+('Isolamento de cabos'!$C$27)/(Geometria!$H$40/100^3)-Geometria!$K$741/(Geometria!$H$40/100^3),IF(M12="Sim",-'Perdas por Seção'!G99/(Geometria!$H$36/100^2)+'Perdas por Seção'!G100/(Geometria!$H$40/100^3)-Geometria!$K$741/(Geometria!$H$40/100^3),-'Perdas por Seção'!G99/(Geometria!$H$36/100^2)+'Perdas por Seção'!G100/(Geometria!$H$40/100^3)-Geometria!$K$741/(Geometria!$H$40/100^3))) -> -347.37894 | H12: =IF(Geometria!$K$280<'Isolamento de cabos'!$C$8,"Sim","Não") -> Não | I12: =Geometria!$H$166*E35+Geometria!$H$168*E12 -> 2621.9512 | J12: =Geometria!$H$166*E35*Geometria!$H$167/100-Geometria!$H$168*E12*Geometria!$H$169/100 -> 247.80385 | L12: =C12/1000 -> -0.34737894 | M12: =IF(Geometria!$K$280<'Isolamento de cabos'!$C$10,"Sim","Não") -> Não | N12: σi,5 | O12: =IF(Geometria!$K$280<Geometria!$J$1030/100,"Reduzir","OK") -> OK | P12: =IF(O12="Reduzir",Q12,S12) -> -4808.045 | Q12: =-(V12/(Geometria!$H$36/100^2))+(W12/(Geometria!$H$40/100^3))-((Geometria!$K$281)/(Geometria!$H$40/100^3))-((Geometria!$K$292)/(Geometria!$H$266))-((Geometria!$H$52*Geometria!$K$303)/(Geometria!$H$266)) -> -87.212651 | R12: =('Perdas por Seção'!G92*(Geometria!$K$280*100))/Geometria!$J$1030 -> 365.65821 | S12: =IF(H12="Sim",-('Isolamento de cabos'!$C$58/(Geometria!$H$36/100^2))+('Isolamento de cabos'!$C$59/(Geometria!$H$40/100^3))-((Geometria!$K$281)/(Geometria!$H$40/100^3))-((Geometria!$K$292)/(Geometria!$H$266))-((Geometria!$H$52*Geometria!$K$303)/(Geometria!$H$266)),IF(M12="Sim",-('Perdas por Seção'!G97/(Geometria!$H$36/100^2))+('Perdas por Seção'!G98/(Geometria!$H$40/100^3))-((Geometria!$K$281)/(Geometria!$H$40/100^3))-((Geometria!$K$292)/(Geometria!$H$266))-((Geometria!$H$52*Geometria!$K$303)/(Geometria!$H$266)),-('Perdas por Seção'!G97/(Geometria!$H$36/100^2))+('Perdas por Seção'!G98/(Geometria!$H$40/100^3))-((Geometria!$K$281)/(Geometria!$H$40/100^3))-((Geometria!$K$292)/(Geometria!$H$266))-((Geometria!$H$52*Geometria!$K$303)/(Geometria!$H$266)))) -> -4808.045 | V12: =Geometria!$H$166*R35+Geometria!$H$168*R12 -> 2255.2778 | W12: =Geometria!$H$166*R35*Geometria!$H$167/100-Geometria!$H$168*R12*Geometria!$H$169/100 -> 213.14909 | Y12: =P12/1000 -> -4.808045
A13: σi,6 | B13: =IF(Geometria!$L$280<Geometria!$J$1030/100,"Reduzir","OK") -> OK | C13: =IF(B13="Reduzir",D13,F13) -> -862.72259 | D13: =-I13/(Geometria!$H$36/100^2)+J13/(Geometria!$H$40/100^3)-Geometria!$L$741/(Geometria!$H$40/100^3) -> 6685.3266 | E13: =('Perdas por Seção'!H60*(Geometria!$L$280*100))/Geometria!$J$1030 -> 567.17328 | F13: =IF(H13="Sim",-('Isolamento de cabos'!$C$26)/(Geometria!$H$36/100^2)+('Isolamento de cabos'!$C$27)/(Geometria!$H$40/100^3)-Geometria!$L$741/(Geometria!$H$40/100^3),IF(M13="Sim",-'Perdas por Seção'!H99/(Geometria!$H$36/100^2)+'Perdas por Seção'!H100/(Geometria!$H$40/100^3)-Geometria!$L$741/(Geometria!$H$40/100^3),-'Perdas por Seção'!H99/(Geometria!$H$36/100^2)+'Perdas por Seção'!H100/(Geometria!$H$40/100^3)-Geometria!$L$741/(Geometria!$H$40/100^3))) -> -862.72259 | H13: =IF(Geometria!$L$280<'Isolamento de cabos'!$C$8,"Sim","Não") -> Não | I13: =Geometria!$H$166*E36+Geometria!$H$168*E13 -> 3284.5585 | J13: =Geometria!$H$166*E36*Geometria!$H$167/100-Geometria!$H$168*E13*Geometria!$H$169/100 -> 310.42769 | L13: =C13/1000 -> -0.86272259 | M13: =IF(Geometria!$L$280<'Isolamento de cabos'!$C$10,"Sim","Não") -> Não | N13: σi,6 | O13: =IF(Geometria!$L$280<Geometria!$J$1030/100,"Reduzir","OK") -> OK | P13: =IF(O13="Reduzir",Q13,S13) -> -6006.0247 | Q13: =-(V13/(Geometria!$H$36/100^2))+(W13/(Geometria!$H$40/100^3))-((Geometria!$L$281)/(Geometria!$H$40/100^3))-((Geometria!$L$292)/(Geometria!$H$266))-((Geometria!$H$52*Geometria!$L$303)/(Geometria!$H$266)) -> 543.45285 | R13: =('Perdas por Seção'!H92*(Geometria!$L$280*100))/Geometria!$J$1030 -> 442.47791 | S13: =IF(H13="Sim",-('Isolamento de cabos'!$C$58/(Geometria!$H$36/100^2))+('Isolamento de cabos'!$C$59/(Geometria!$H$40/100^3))-((Geometria!$L$281)/(Geometria!$H$40/100^3))-((Geometria!$L$292)/(Geometria!$H$266))-((Geometria!$H$52*Geometria!$L$303)/(Geometria!$H$266)),IF(M13="Sim",-('Perdas por Seção'!H97/(Geometria!$H$36/100^2))+('Perdas por Seção'!H98/(Geometria!$H$40/100^3))-((Geometria!$L$281)/(Geometria!$H$40/100^3))-((Geometria!$L$292)/(Geometria!$H$266))-((Geometria!$H$52*Geometria!$L$303)/(Geometria!$H$266)),-('Perdas por Seção'!H97/(Geometria!$H$36/100^2))+('Perdas por Seção'!H98/(Geometria!$H$40/100^3))-((Geometria!$L$281)/(Geometria!$H$40/100^3))-((Geometria!$L$292)/(Geometria!$H$266))-((Geometria!$H$52*Geometria!$L$303)/(Geometria!$H$266)))) -> -6006.0247 | V13: =Geometria!$H$166*R36+Geometria!$H$168*R13 -> 2850.0268 | W13: =Geometria!$H$166*R36*Geometria!$H$167/100-Geometria!$H$168*R13*Geometria!$H$169/100 -> 269.35956 | Y13: =P13/1000 -> -6.0060247
A14: σi,7 | B14: =IF(Geometria!$M$280<Geometria!$J$1030/100,"Reduzir","OK") -> OK | C14: =IF(B14="Reduzir",D14,F14) -> -1284.3674 | D14: =-I14/(Geometria!$H$36/100^2)+J14/(Geometria!$H$40/100^3)-Geometria!$M$741/(Geometria!$H$40/100^3) -> 8328.4598 | E14: =('Perdas por Seção'!I60*(Geometria!$M$280*100))/Geometria!$J$1030 -> 677.00614 | F14: =IF(H14="Sim",-('Isolamento de cabos'!$C$26)/(Geometria!$H$36/100^2)+('Isolamento de cabos'!$C$27)/(Geometria!$H$40/100^3)-Geometria!$M$741/(Geometria!$H$40/100^3),IF(M14="Sim",-'Perdas por Seção'!I99/(Geometria!$H$36/100^2)+'Perdas por Seção'!I100/(Geometria!$H$40/100^3)-Geometria!$M$741/(Geometria!$H$40/100^3),-'Perdas por Seção'!I99/(Geometria!$H$36/100^2)+'Perdas por Seção'!I100/(Geometria!$H$40/100^3)-Geometria!$M$741/(Geometria!$H$40/100^3))) -> -1284.3674 | H14: =IF(Geometria!$M$280<'Isolamento de cabos'!$C$8,"Sim","Não") -> Não | I14: =Geometria!$H$166*E37+Geometria!$H$168*E14 -> 3948.4604 | J14: =Geometria!$H$166*E37*Geometria!$H$167/100-Geometria!$H$168*E14*Geometria!$H$169/100 -> 373.17388 | L14: =C14/1000 -> -1.2843674 | M14: =IF(Geometria!$M$280<'Isolamento de cabos'!$C$10,"Sim","Não") -> Não | N14: σi,7 | O14: =IF(Geometria!$M$280<Geometria!$J$1030/100,"Reduzir","OK") -> OK | P14: =IF(O14="Reduzir",Q14,S14) -> -6986.2039 | Q14: =-(V14/(Geometria!$H$36/100^2))+(W14/(Geometria!$H$40/100^3))-((Geometria!$M$281)/(Geometria!$H$40/100^3))-((Geometria!$M$292)/(Geometria!$H$266))-((Geometria!$H$52*Geometria!$M$303)/(Geometria!$H$266)) -> 1414.0056 | R14: =('Perdas por Seção'!I92*(Geometria!$M$280*100))/Geometria!$J$1030 -> 516.644 | S14: =IF(H14="Sim",-('Isolamento de cabos'!$C$58/(Geometria!$H$36/100^2))+('Isolamento de cabos'!$C$59/(Geometria!$H$40/100^3))-((Geometria!$M$281)/(Geometria!$H$40/100^3))-((Geometria!$M$292)/(Geometria!$H$266))-((Geometria!$H$52*Geometria!$M$303)/(Geometria!$H$266)),IF(M14="Sim",-('Perdas por Seção'!I97/(Geometria!$H$36/100^2))+('Perdas por Seção'!I98/(Geometria!$H$40/100^3))-((Geometria!$M$281)/(Geometria!$H$40/100^3))-((Geometria!$M$292)/(Geometria!$H$266))-((Geometria!$H$52*Geometria!$M$303)/(Geometria!$H$266)),-('Perdas por Seção'!I97/(Geometria!$H$36/100^2))+('Perdas por Seção'!I98/(Geometria!$H$40/100^3))-((Geometria!$M$281)/(Geometria!$H$40/100^3))-((Geometria!$M$292)/(Geometria!$H$266))-((Geometria!$H$52*Geometria!$M$303)/(Geometria!$H$266)))) -> -6986.2039 | V14: =Geometria!$H$166*R37+Geometria!$H$168*R14 -> 3450.3787 | W14: =Geometria!$H$166*R37*Geometria!$H$167/100-Geometria!$H$168*R14*Geometria!$H$169/100 -> 326.09956 | Y14: =P14/1000 -> -6.9862039
A15: σi,8 | B15: =IF(Geometria!$N$280<Geometria!$J$1030/100,"Reduzir","OK") -> OK | C15: =IF(B15="Reduzir",D15,F15) -> -1612.3133 | D15: =-I15/(Geometria!$H$36/100^2)+J15/(Geometria!$H$40/100^3)-Geometria!$N$741/(Geometria!$H$40/100^3) -> 10067.966 | E15: =('Perdas por Seção'!J60*(Geometria!$N$280*100))/Geometria!$J$1030 -> 786.5722 | F15: =IF(H15="Sim",-('Isolamento de cabos'!$C$26)/(Geometria!$H$36/100^2)+('Isolamento de cabos'!$C$27)/(Geometria!$H$40/100^3)-Geometria!$N$741/(Geometria!$H$40/100^3),IF(M15="Sim",-'Perdas por Seção'!J99/(Geometria!$H$36/100^2)+'Perdas por Seção'!J100/(Geometria!$H$40/100^3)-Geometria!$N$741/(Geometria!$H$40/100^3),-'Perdas por Seção'!J99/(Geometria!$H$36/100^2)+'Perdas por Seção'!J100/(Geometria!$H$40/100^3)-Geometria!$N$741/(Geometria!$H$40/100^3))) -> -1612.3133 | H15: =IF(Geometria!$N$280<'Isolamento de cabos'!$C$8,"Sim","Não") -> Não | I15: =Geometria!$H$166*E38+Geometria!$H$168*E15 -> 4612.88 | J15: =Geometria!$H$166*E38*Geometria!$H$167/100-Geometria!$H$168*E15*Geometria!$H$169/100 -> 435.969 | L15: =C15/1000 -> -1.6123133 | M15: =IF(Geometria!$N$280<'Isolamento de cabos'!$C$10,"Sim","Não") -> Não | N15: σi,8 | O15: =IF(Geometria!$N$280<Geometria!$J$1030/100,"Reduzir","OK") -> OK | P15: =IF(O15="Reduzir",Q15,S15) -> -7748.5743 | Q15: =-(V15/(Geometria!$H$36/100^2))+(W15/(Geometria!$H$40/100^3))-((Geometria!$N$281)/(Geometria!$H$40/100^3))-((Geometria!$N$292)/(Geometria!$H$266))-((Geometria!$H$52*Geometria!$N$303)/(Geometria!$H$266)) -> 2513.9406 | R15: =('Perdas por Seção'!J92*(Geometria!$N$280*100))/Geometria!$J$1030 -> 589.74864 | S15: =IF(H15="Sim",-('Isolamento de cabos'!$C$58/(Geometria!$H$36/100^2))+('Isolamento de cabos'!$C$59/(Geometria!$H$40/100^3))-((Geometria!$N$281)/(Geometria!$H$40/100^3))-((Geometria!$N$292)/(Geometria!$H$266))-((Geometria!$H$52*Geometria!$N$303)/(Geometria!$H$266)),IF(M15="Sim",-('Perdas por Seção'!J97/(Geometria!$H$36/100^2))+('Perdas por Seção'!J98/(Geometria!$H$40/100^3))-((Geometria!$N$281)/(Geometria!$H$40/100^3))-((Geometria!$N$292)/(Geometria!$H$266))-((Geometria!$H$52*Geometria!$N$303)/(Geometria!$H$266)),-('Perdas por Seção'!J97/(Geometria!$H$36/100^2))+('Perdas por Seção'!J98/(Geometria!$H$40/100^3))-((Geometria!$N$281)/(Geometria!$H$40/100^3))-((Geometria!$N$292)/(Geometria!$H$266))-((Geometria!$H$52*Geometria!$N$303)/(Geometria!$H$266)))) -> -7748.5743 | V15: =Geometria!$H$166*R38+Geometria!$H$168*R15 -> 4052.9637 | W15: =Geometria!$H$166*R38*Geometria!$H$167/100-Geometria!$H$168*R15*Geometria!$H$169/100 -> 383.05061 | Y15: =P15/1000 -> -7.7485743
A16: σi,9 | B16: =IF(Geometria!$G$283<Geometria!$J$1030/100,"Reduzir","OK") -> OK | C16: =IF(B16="Reduzir",D16,F16) -> -1846.5604 | D16: =-I16/(Geometria!$H$36/100^2)+J16/(Geometria!$H$40/100^3)-Geometria!$G$744/(Geometria!$H$40/100^3) -> 11901.425 | E16: =('Perdas por Seção'!K60*(Geometria!$G$283*100))/Geometria!$J$1030 -> 896.27166 | F16: =IF(H16="Sim",-('Isolamento de cabos'!$C$26)/(Geometria!$H$36/100^2)+('Isolamento de cabos'!$C$27)/(Geometria!$H$40/100^3)-Geometria!$G$744/(Geometria!$H$40/100^3),IF(M16="Sim",-'Perdas por Seção'!K99/(Geometria!$H$36/100^2)+'Perdas por Seção'!K100/(Geometria!$H$40/100^3)-Geometria!$G$744/(Geometria!$H$40/100^3),-'Perdas por Seção'!K99/(Geometria!$H$36/100^2)+'Perdas por Seção'!K100/(Geometria!$H$40/100^3)-Geometria!$G$744/(Geometria!$H$40/100^3))) -> -1846.5604 | H16: =IF(Geometria!$G$283<'Isolamento de cabos'!$C$8,"Sim","Não") -> Não | I16: =Geometria!$H$166*E39+Geometria!$H$168*E16 -> 5277.0407 | J16: =Geometria!$H$166*E39*Geometria!$H$167/100-Geometria!$H$168*E16*Geometria!$H$169/100 -> 498.73965 | L16: =C16/1000 -> -1.8465604 | M16: =IF(Geometria!$G$283<'Isolamento de cabos'!$C$10,"Sim","Não") -> Não | N16: σi,9 | O16: =IF(Geometria!$G$283<Geometria!$J$1030/100,"Reduzir","OK") -> OK | P16: =IF(O16="Reduzir",Q16,S16) -> -8293.1292 | Q16: =-(V16/(Geometria!$H$36/100^2))+(W16/(Geometria!$H$40/100^3))-((Geometria!$G$284)/(Geometria!$H$40/100^3))-((Geometria!$G$295)/(Geometria!$H$266))-((Geometria!$H$52*Geometria!$G$306)/(Geometria!$H$266)) -> 3832.7667 | R16: =('Perdas por Seção'!K92*(Geometria!$G$283*100))/Geometria!$J$1030 -> 663.38401 | S16: =IF(H16="Sim",-('Isolamento de cabos'!$C$58/(Geometria!$H$36/100^2))+('Isolamento de cabos'!$C$59/(Geometria!$H$40/100^3))-((Geometria!$G$284)/(Geometria!$H$40/100^3))-((Geometria!$G$295)/(Geometria!$H$266))-((Geometria!$H$52*Geometria!$G$306)/(Geometria!$H$266)),IF(M16="Sim",-('Perdas por Seção'!K97/(Geometria!$H$36/100^2))+('Perdas por Seção'!K98/(Geometria!$H$40/100^3))-((Geometria!$G$284)/(Geometria!$H$40/100^3))-((Geometria!$G$295)/(Geometria!$H$266))-((Geometria!$H$52*Geometria!$G$306)/(Geometria!$H$266)),-('Perdas por Seção'!K97/(Geometria!$H$36/100^2))+('Perdas por Seção'!K98/(Geometria!$H$40/100^3))-((Geometria!$G$284)/(Geometria!$H$40/100^3))-((Geometria!$G$295)/(Geometria!$H$266))-((Geometria!$H$52*Geometria!$G$306)/(Geometria!$H$266)))) -> -8293.1292 | V16: =Geometria!$H$166*R39+Geometria!$H$168*R16 -> 4654.4162 | W16: =Geometria!$H$166*R39*Geometria!$H$167/100-Geometria!$H$168*R16*Geometria!$H$169/100 -> 439.89463 | Y16: =P16/1000 -> -8.2931292
A17: σi,10 | B17: =IF(Geometria!$H$283<Geometria!$J$1030/100,"Reduzir","OK") -> OK | C17: =IF(B17="Reduzir",D17,F17) -> -1987.1087 | D17: =-$I$17/(Geometria!$H$36/100^2)+J17/(Geometria!$H$40/100^3)-Geometria!$H$744/(Geometria!$H$40/100^3) -> 13826.415 | E17: =('Perdas por Seção'!L60*(Geometria!$H$283*100))/Geometria!$J$1030 -> 1006.5047 | F17: =IF(H17="Sim",-('Isolamento de cabos'!$C$26)/(Geometria!$H$36/100^2)+('Isolamento de cabos'!$C$27)/(Geometria!$H$40/100^3)-Geometria!$H$744/(Geometria!$H$40/100^3),IF(M17="Sim",-'Perdas por Seção'!L99/(Geometria!$H$36/100^2)+'Perdas por Seção'!L100/(Geometria!$H$40/100^3)-Geometria!$H$744/(Geometria!$H$40/100^3),-'Perdas por Seção'!L99/(Geometria!$H$36/100^2)+'Perdas por Seção'!L100/(Geometria!$H$40/100^3)-Geometria!$H$744/(Geometria!$H$40/100^3))) -> -1987.1087 | H17: =IF(Geometria!$H$283<'Isolamento de cabos'!$C$8,"Sim","Não") -> Não | I17: =Geometria!$H$166*E40+Geometria!$H$168*E17 -> 5940.1659 | J17: =Geometria!$H$166*E40*Geometria!$H$167/100-Geometria!$H$168*E17*Geometria!$H$169/100 -> 561.41243 | L17: =C17/1000 -> -1.9871087 | M17: =IF(Geometria!$H$283<'Isolamento de cabos'!$C$10,"Sim","Não") -> Não | N17: σi,10 | O17: =IF(Geometria!$H$283<Geometria!$J$1030/100,"Reduzir","OK") -> OK | P17: =IF(O17="Reduzir",Q17,S17) -> -8619.8641 | Q17: =-(V17/(Geometria!$H$36/100^2))+(W17/(Geometria!$H$40/100^3))-((Geometria!$H$284)/(Geometria!$H$40/100^3))-((Geometria!$H$295)/(Geometria!$H$266))-((Geometria!$H$52*Geometria!$H$306)/(Geometria!$H$266)) -> 5360.0001 | R17: =('Perdas por Seção'!L92*(Geometria!$H$283*100))/Geometria!$J$1030 -> 739.14226 | S17: =IF(H17="Sim",-('Isolamento de cabos'!$C$58/(Geometria!$H$36/100^2))+('Isolamento de cabos'!$C$59/(Geometria!$H$40/100^3))-((Geometria!$H$284)/(Geometria!$H$40/100^3))-((Geometria!$H$295)/(Geometria!$H$266))-((Geometria!$H$52*Geometria!$H$306)/(Geometria!$H$266)),IF(M17="Sim",-('Perdas por Seção'!L97/(Geometria!$H$36/100^2))+('Perdas por Seção'!L98/(Geometria!$H$40/100^3))-((Geometria!$H$284)/(Geometria!$H$40/100^3))-((Geometria!$H$295)/(Geometria!$H$266))-((Geometria!$H$52*Geometria!$H$306)/(Geometria!$H$266)),-('Perdas por Seção'!L97/(Geometria!$H$36/100^2))+('Perdas por Seção'!L98/(Geometria!$H$40/100^3))-((Geometria!$H$284)/(Geometria!$H$40/100^3))-((Geometria!$H$295)/(Geometria!$H$266))-((Geometria!$H$52*Geometria!$H$306)/(Geometria!$H$266)))) -> -8619.8641 | V17: =Geometria!$H$166*R40+Geometria!$H$168*R17 -> 5251.373 | W17: =Geometria!$H$166*R40*Geometria!$H$167/100-Geometria!$H$168*R17*Geometria!$H$169/100 -> 496.31376 | Y17: =P17/1000 -> -8.6198641
A18: σi,11 | B18: =IF(Geometria!$I$283<Geometria!$J$1030/100,"Reduzir","OK") -> OK | C18: =IF(B18="Reduzir",D18,F18) -> -2033.9581 | D18: =-$I$18/(Geometria!$H$36/100^2)+J18/(Geometria!$H$40/100^3)-Geometria!$I$744/(Geometria!$H$40/100^3) -> 15840.515 | E18: =('Perdas por Seção'!M60*(Geometria!$I$283*100))/Geometria!$J$1030 -> 1117.6716 | F18: =IF(H18="Sim",-('Isolamento de cabos'!$C$26)/(Geometria!$H$36/100^2)+('Isolamento de cabos'!$C$27)/(Geometria!$H$40/100^3)-Geometria!$I$744/(Geometria!$H$40/100^3),IF(M18="Sim",-'Perdas por Seção'!M99/(Geometria!$H$36/100^2)+'Perdas por Seção'!M100/(Geometria!$H$40/100^3)-Geometria!$I$744/(Geometria!$H$40/100^3),-'Perdas por Seção'!M99/(Geometria!$H$36/100^2)+'Perdas por Seção'!M100/(Geometria!$H$40/100^3)-Geometria!$I$744/(Geometria!$H$40/100^3))) -> -2033.9581 | H18: =IF(Geometria!$I$283<'Isolamento de cabos'!$C$8,"Sim","Não") -> Não | I18: =Geometria!$H$166*E41+Geometria!$H$168*E18 -> 6601.4788 | J18: =Geometria!$H$166*E41*Geometria!$H$167/100-Geometria!$H$168*E18*Geometria!$H$169/100 -> 623.91393 | L18: =C18/1000 -> -2.0339581 | M18: =IF(Geometria!$I$283<'Isolamento de cabos'!$C$10,"Sim","Não") -> Não | N18: σi,11 | O18: =IF(Geometria!$I$283<Geometria!$J$1030/100,"Reduzir","OK") -> OK | P18: =IF(O18="Reduzir",Q18,S18) -> -8728.776 | Q18: =-(V18/(Geometria!$H$36/100^2))+(W18/(Geometria!$H$40/100^3))-((Geometria!$I$284)/(Geometria!$H$40/100^3))-((Geometria!$I$295)/(Geometria!$H$266))-((Geometria!$H$52*Geometria!$I$306)/(Geometria!$H$266)) -> 7085.1569 | R18: =('Perdas por Seção'!M92*(Geometria!$I$283*100))/Geometria!$J$1030 -> 818.61557 | S18: =IF(H18="Sim",-('Isolamento de cabos'!$C$58/(Geometria!$H$36/100^2))+('Isolamento de cabos'!$C$59/(Geometria!$H$40/100^3))-((Geometria!$I$284)/(Geometria!$H$40/100^3))-((Geometria!$I$295)/(Geometria!$H$266))-((Geometria!$H$52*Geometria!$I$306)/(Geometria!$H$266)),IF(M18="Sim",-('Perdas por Seção'!M97/(Geometria!$H$36/100^2))+('Perdas por Seção'!M98/(Geometria!$H$40/100^3))-((Geometria!$I$284)/(Geometria!$H$40/100^3))-((Geometria!$I$295)/(Geometria!$H$266))-((Geometria!$H$52*Geometria!$I$306)/(Geometria!$H$266)),-('Perdas por Seção'!M97/(Geometria!$H$36/100^2))+('Perdas por Seção'!M98/(Geometria!$H$40/100^3))-((Geometria!$I$284)/(Geometria!$H$40/100^3))-((Geometria!$I$295)/(Geometria!$H$266))-((Geometria!$H$52*Geometria!$I$306)/(Geometria!$H$266)))) -> -8728.776 | V18: =Geometria!$H$166*R41+Geometria!$H$168*R18 -> 5840.471 | W18: =Geometria!$H$166*R41*Geometria!$H$167/100-Geometria!$H$168*R18*Geometria!$H$169/100 -> 551.99014 | Y18: =P18/1000 -> -8.728776
A19: σi,12 | B19: =B17 -> OK | C19: =IF(B19="Reduzir",D19,F19) -> -1987.1087 | D19: =-$I$19/(Geometria!$H$36/100^2)+J19/(Geometria!$H$40/100^3)-Geometria!$J$744/(Geometria!$H$40/100^3) -> 13826.415 | E19: =('Perdas por Seção'!N60*(Geometria!$H$283*100))/Geometria!$J$1030 -> 1006.5047 | F19: =IF(H19="Sim",-('Isolamento de cabos'!$C$26)/(Geometria!$H$36/100^2)+('Isolamento de cabos'!$C$27)/(Geometria!$H$40/100^3)-Geometria!$J$744/(Geometria!$H$40/100^3),IF(M19="Sim",-'Perdas por Seção'!N99/(Geometria!$H$36/100^2)+'Perdas por Seção'!N100/(Geometria!$H$40/100^3)-Geometria!$J$744/(Geometria!$H$40/100^3),-'Perdas por Seção'!N99/(Geometria!$H$36/100^2)+'Perdas por Seção'!N100/(Geometria!$H$40/100^3)-Geometria!$J$744/(Geometria!$H$40/100^3))) -> -1987.1087 | H19: =IF(Geometria!$H$283<'Isolamento de cabos'!$C$8,"Sim","Não") -> Não | I19: =Geometria!$H$166*E42+Geometria!$H$168*E19 -> 5940.1659 | J19: =Geometria!$H$166*E42*Geometria!$H$167/100-Geometria!$H$168*E19*Geometria!$H$169/100 -> 561.41243 | L19: =C19/1000 -> -1.9871087 | M19: =IF(Geometria!$H$283<'Isolamento de cabos'!$C$10,"Sim","Não") -> Não | N19: σi,12 | O19: =O17 -> OK | P19: =IF(O19="Reduzir",Q19,S19) -> -8619.8641 | Q19: =-(V19/(Geometria!$H$36/100^2))+(W19/(Geometria!$H$40/100^3))-((Geometria!$J$284)/(Geometria!$H$40/100^3))-((Geometria!$J$295)/(Geometria!$H$266))-((Geometria!$H$52*Geometria!$J$306)/(Geometria!$H$266)) -> 5360.0001 | R19: =('Perdas por Seção'!N92*(Geometria!$H$283*100))/Geometria!$J$1030 -> 739.14226 | S19: =IF(H19="Sim",-('Isolamento de cabos'!$C$58/(Geometria!$H$36/100^2))+('Isolamento de cabos'!$C$59/(Geometria!$H$40/100^3))-((Geometria!$J$284)/(Geometria!$H$40/100^3))-((Geometria!$J$295)/(Geometria!$H$266))-((Geometria!$H$52*Geometria!$J$306)/(Geometria!$H$266)),IF(M19="Sim",-('Perdas por Seção'!N97/(Geometria!$H$36/100^2))+('Perdas por Seção'!N98/(Geometria!$H$40/100^3))-((Geometria!$J$284)/(Geometria!$H$40/100^3))-((Geometria!$J$295)/(Geometria!$H$266))-((Geometria!$H$52*Geometria!$J$306)/(Geometria!$H$266)),-('Perdas por Seção'!N97/(Geometria!$H$36/100^2))+('Perdas por Seção'!N98/(Geometria!$H$40/100^3))-((Geometria!$J$284)/(Geometria!$H$40/100^3))-((Geometria!$J$295)/(Geometria!$H$266))-((Geometria!$H$52*Geometria!$J$306)/(Geometria!$H$266)))) -> -8619.8641 | V19: =Geometria!$H$166*R42+Geometria!$H$168*R19 -> 5251.373 | W19: =Geometria!$H$166*R42*Geometria!$H$167/100-Geometria!$H$168*R19*Geometria!$H$169/100 -> 496.31376 | Y19: =P19/1000 -> -8.6198641
A20: σi,13 | B20: =B16 -> OK | C20: =IF(B20="Reduzir",D20,F20) -> -1846.5604 | D20: =-$I$20/(Geometria!$H$36/100^2)+J20/(Geometria!$H$40/100^3)-Geometria!$K$744/(Geometria!$H$40/100^3) -> 11901.425 | E20: =('Perdas por Seção'!O60*(Geometria!$G$283*100))/Geometria!$J$1030 -> 896.27166 | F20: =IF(H20="Sim",-('Isolamento de cabos'!$C$26)/(Geometria!$H$36/100^2)+('Isolamento de cabos'!$C$27)/(Geometria!$H$40/100^3)-Geometria!$K$744/(Geometria!$H$40/100^3),IF(M20="Sim",-'Perdas por Seção'!O99/(Geometria!$H$36/100^2)+'Perdas por Seção'!O100/(Geometria!$H$40/100^3)-Geometria!$K$744/(Geometria!$H$40/100^3),-'Perdas por Seção'!O99/(Geometria!$H$36/100^2)+'Perdas por Seção'!O100/(Geometria!$H$40/100^3)-Geometria!$K$744/(Geometria!$H$40/100^3))) -> -1846.5604 | H20: =IF(Geometria!$G$283<'Isolamento de cabos'!$C$8,"Sim","Não") -> Não | I20: =Geometria!$H$166*E43+Geometria!$H$168*E20 -> 5277.0407 | J20: =Geometria!$H$166*E43*Geometria!$H$167/100-Geometria!$H$168*E20*Geometria!$H$169/100 -> 498.73965 | L20: =C20/1000 -> -1.8465604 | M20: =IF(Geometria!$G$283<'Isolamento de cabos'!$C$10,"Sim","Não") -> Não | N20: σi,13 | O20: =O16 -> OK | P20: =IF(O20="Reduzir",Q20,S20) -> -8293.1292 | Q20: =-(V20/(Geometria!$H$36/100^2))+(W20/(Geometria!$H$40/100^3))-((Geometria!$K$284)/(Geometria!$H$40/100^3))-((Geometria!$K$295)/(Geometria!$H$266))-((Geometria!$H$52*Geometria!$K$306)/(Geometria!$H$266)) -> 3832.7667 | R20: =('Perdas por Seção'!O92*(Geometria!$G$283*100))/Geometria!$J$1030 -> 663.38401 | S20: =IF(H20="Sim",-('Isolamento de cabos'!$C$58/(Geometria!$H$36/100^2))+('Isolamento de cabos'!$C$59/(Geometria!$H$40/100^3))-((Geometria!$K$284)/(Geometria!$H$40/100^3))-((Geometria!$K$295)/(Geometria!$H$266))-((Geometria!$H$52*Geometria!$K$306)/(Geometria!$H$266)),IF(M20="Sim",-('Perdas por Seção'!O97/(Geometria!$H$36/100^2))+('Perdas por Seção'!O98/(Geometria!$H$40/100^3))-((Geometria!$K$284)/(Geometria!$H$40/100^3))-((Geometria!$K$295)/(Geometria!$H$266))-((Geometria!$H$52*Geometria!$K$306)/(Geometria!$H$266)),-('Perdas por Seção'!O97/(Geometria!$H$36/100^2))+('Perdas por Seção'!O98/(Geometria!$H$40/100^3))-((Geometria!$K$284)/(Geometria!$H$40/100^3))-((Geometria!$K$295)/(Geometria!$H$266))-((Geometria!$H$52*Geometria!$K$306)/(Geometria!$H$266)))) -> -8293.1292 | V20: =Geometria!$H$166*R43+Geometria!$H$168*R20 -> 4654.4162 | W20: =Geometria!$H$166*R43*Geometria!$H$167/100-Geometria!$H$168*R20*Geometria!$H$169/100 -> 439.89463 | Y20: =P20/1000 -> -8.2931292
A21: σi,14 | B21: =B15 -> OK | C21: =IF(B21="Reduzir",D21,F21) -> -1612.3133 | D21: =-$I$21/(Geometria!$H$36/100^2)+J21/(Geometria!$H$40/100^3)-Geometria!$L$744/(Geometria!$H$40/100^3) -> 10067.966 | E21: =('Perdas por Seção'!P60*(Geometria!$N$280*100))/Geometria!$J$1030 -> 786.5722 | F21: =IF(H21="Sim",-('Isolamento de cabos'!$C$26)/(Geometria!$H$36/100^2)+('Isolamento de cabos'!$C$27)/(Geometria!$H$40/100^3)-Geometria!$L$744/(Geometria!$H$40/100^3),IF(M21="Sim",-'Perdas por Seção'!P99/(Geometria!$H$36/100^2)+'Perdas por Seção'!P100/(Geometria!$H$40/100^3)-Geometria!$L$744/(Geometria!$H$40/100^3),-'Perdas por Seção'!P99/(Geometria!$H$36/100^2)+'Perdas por Seção'!P100/(Geometria!$H$40/100^3)-Geometria!$L$744/(Geometria!$H$40/100^3))) -> -1612.3133 | H21: =IF(Geometria!$N$280<'Isolamento de cabos'!$C$8,"Sim","Não") -> Não | I21: =Geometria!$H$166*E44+Geometria!$H$168*E21 -> 4612.88 | J21: =Geometria!$H$166*E44*Geometria!$H$167/100-Geometria!$H$168*E21*Geometria!$H$169/100 -> 435.969 | L21: =C21/1000 -> -1.6123133 | M21: =IF(Geometria!$N$280<'Isolamento de cabos'!$C$10,"Sim","Não") -> Não | N21: σi,14 | O21: =O15 -> OK | P21: =IF(O21="Reduzir",Q21,S21) -> -7748.5743 | Q21: =-(V21/(Geometria!$H$36/100^2))+(W21/(Geometria!$H$40/100^3))-((Geometria!$L$284)/(Geometria!$H$40/100^3))-((Geometria!$L$295)/(Geometria!$H$266))-((Geometria!$H$52*Geometria!$L$306)/(Geometria!$H$266)) -> 2513.9406 | R21: =('Perdas por Seção'!P92*(Geometria!$N$280*100))/Geometria!$J$1030 -> 589.74864 | S21: =IF(H21="Sim",-('Isolamento de cabos'!$C$58/(Geometria!$H$36/100^2))+('Isolamento de cabos'!$C$59/(Geometria!$H$40/100^3))-((Geometria!$L$284)/(Geometria!$H$40/100^3))-((Geometria!$L$295)/(Geometria!$H$266))-((Geometria!$H$52*Geometria!$L$306)/(Geometria!$H$266)),IF(M21="Sim",-('Perdas por Seção'!P97/(Geometria!$H$36/100^2))+('Perdas por Seção'!P98/(Geometria!$H$40/100^3))-((Geometria!$L$284)/(Geometria!$H$40/100^3))-((Geometria!$L$295)/(Geometria!$H$266))-((Geometria!$H$52*Geometria!$L$306)/(Geometria!$H$266)),-('Perdas por Seção'!P97/(Geometria!$H$36/100^2))+('Perdas por Seção'!P98/(Geometria!$H$40/100^3))-((Geometria!$L$284)/(Geometria!$H$40/100^3))-((Geometria!$L$295)/(Geometria!$H$266))-((Geometria!$H$52*Geometria!$L$306)/(Geometria!$H$266)))) -> -7748.5743 | V21: =Geometria!$H$166*R44+Geometria!$H$168*R21 -> 4052.9637 | W21: =Geometria!$H$166*R44*Geometria!$H$167/100-Geometria!$H$168*R21*Geometria!$H$169/100 -> 383.05061 | Y21: =P21/1000 -> -7.7485743
A22: σi,15 | B22: =B14 -> OK | C22: =IF(B22="Reduzir",D22,F22) -> -1284.3674 | D22: =-$I$22/(Geometria!$H$36/100^2)+J22/(Geometria!$H$40/100^3)-Geometria!$M$744/(Geometria!$H$40/100^3) -> 8328.4598 | E22: =('Perdas por Seção'!Q60*(Geometria!$M$280*100))/Geometria!$J$1030 -> 677.00614 | F22: =IF(H22="Sim",-('Isolamento de cabos'!$C$26)/(Geometria!$H$36/100^2)+('Isolamento de cabos'!$C$27)/(Geometria!$H$40/100^3)-Geometria!$M$744/(Geometria!$H$40/100^3),IF(M22="Sim",-'Perdas por Seção'!Q99/(Geometria!$H$36/100^2)+'Perdas por Seção'!Q100/(Geometria!$H$40/100^3)-Geometria!$M$744/(Geometria!$H$40/100^3),-'Perdas por Seção'!Q99/(Geometria!$H$36/100^2)+'Perdas por Seção'!Q100/(Geometria!$H$40/100^3)-Geometria!$M$744/(Geometria!$H$40/100^3))) -> -1284.3674 | H22: =IF(Geometria!$M$280<'Isolamento de cabos'!$C$8,"Sim","Não") -> Não | I22: =Geometria!$H$166*E45+Geometria!$H$168*E22 -> 3948.4604 | J22: =Geometria!$H$166*E45*Geometria!$H$167/100-Geometria!$H$168*E22*Geometria!$H$169/100 -> 373.17388 | L22: =C22/1000 -> -1.2843674 | M22: =IF(Geometria!$M$280<'Isolamento de cabos'!$C$10,"Sim","Não") -> Não | N22: σi,15 | O22: =O14 -> OK | P22: =IF(O22="Reduzir",Q22,S22) -> -6986.2039 | Q22: =-(V22/(Geometria!$H$36/100^2))+(W22/(Geometria!$H$40/100^3))-((Geometria!$M$284)/(Geometria!$H$40/100^3))-((Geometria!$M$295)/(Geometria!$H$266))-((Geometria!$H$52*Geometria!$M$306)/(Geometria!$H$266)) -> 1414.0056 | R22: =('Perdas por Seção'!Q92*(Geometria!$M$280*100))/Geometria!$J$1030 -> 516.644 | S22: =IF(H22="Sim",-('Isolamento de cabos'!$C$58/(Geometria!$H$36/100^2))+('Isolamento de cabos'!$C$59/(Geometria!$H$40/100^3))-((Geometria!$M$284)/(Geometria!$H$40/100^3))-((Geometria!$M$295)/(Geometria!$H$266))-((Geometria!$H$52*Geometria!$M$306)/(Geometria!$H$266)),IF(M22="Sim",-('Perdas por Seção'!Q97/(Geometria!$H$36/100^2))+('Perdas por Seção'!Q98/(Geometria!$H$40/100^3))-((Geometria!$M$284)/(Geometria!$H$40/100^3))-((Geometria!$M$295)/(Geometria!$H$266))-((Geometria!$H$52*Geometria!$M$306)/(Geometria!$H$266)),-('Perdas por Seção'!Q97/(Geometria!$H$36/100^2))+('Perdas por Seção'!Q98/(Geometria!$H$40/100^3))-((Geometria!$M$284)/(Geometria!$H$40/100^3))-((Geometria!$M$295)/(Geometria!$H$266))-((Geometria!$H$52*Geometria!$M$306)/(Geometria!$H$266)))) -> -6986.2039 | V22: =Geometria!$H$166*R45+Geometria!$H$168*R22 -> 3450.3787 | W22: =Geometria!$H$166*R45*Geometria!$H$167/100-Geometria!$H$168*R22*Geometria!$H$169/100 -> 326.09956 | Y22: =P22/1000 -> -6.9862039
