Workbook
Name FirstX: 'Propriedades geométricas VIGA'!$B$6
Name FirstX: 'Propriedades geométricas LAJE'!$B$6
Name testex: 'ELU i'!$T$85:$T$99
Name testey: 'ELU i'!$U$85:$U$99
Name X: OFFSET(FirstX,0,0,COUNT('Propriedades geométricas VIGA'!$B$1:$B$65531))
Name X: OFFSET('Propriedades geométricas LAJE'!FirstX,0,0,COUNT('Propriedades geométricas LAJE'!$B$1:$B$65531))
Name XX: 'ELU i'!$T$4:$T$18
Name XXX: 'ELU i'!$T$27:$T$41
Name XXXX: 'ELU i'!$T$52:$T$66
Name Y: OFFSET(X,0,1)
Name Y: OFFSET('Propriedades geométricas LAJE'!X,0,1)
Name YY: 'ELU i'!$U$4:$U$18
Name YYY: 'ELU i'!$U$27:$U$41
Name YYYY: 'ELU i'!$U$52:$U$66

Sheet Geometria
K1: Homogeneizar seção? | L1: FALSE | M1: Deformações t=1 | O1: =N1284 -> -1.1762592 | P1: =IF(M19="1 - Retângular","","Estádios Viga 'i'") | Q1: =IF(M19="1 - Retângular","",'ELU i'!G145)
M2: Deformações diferidas - t=inf | O2: =N1281 -> 0.73209376 | P2: Fissuração T=1 | Q2: =IF(L1209>L1214,"Ok","Estádio II") -> Ok
M3: Taxa | O3: =Taxas!L56 -> 290.7128 | P3: Fissuração T,inf | Q3: =IF(L1220>L1222,"Ok","Estádio II") -> Estádio II
K4: =IF(M19="1 - Retângular","Estádios viga retângular","") -> Estádios viga retângular | M4: As'p | N4: =Taxas!H50 -> 3 | O4: 16 | P4: As',adicional | Q4: 0 | R4: x
K5: =IF(M19="1 - Retângular",IF(M19="2 - i",M1083,IF(M19="3 - Transição",M1083,(_xlfn.CONCAT((IF(M18="1 - Sim",(IF(K1087="Seção 'T' Verdadeira",O1122,L1078)),L1078))," - ",M1075)))),"") -> Domínio 3 - Armadura simples | M5: As,p | N5: =Taxas!H57 -> 12 | O5: 16 | P5: As',adicional | Q5: 0 | R5: x
K6: ='Fissuração - wk por Seção'!N107
K7: 1 . Dados de entrada
K9: Cargas atuantes | T9: tamanhos estribos (U14 = aba Cisalhamento e Apoios, item 3b) | X9: Peso lajes
K10: Sobrecarga da laje = q0 | L10: 2500 | M10: kgf/m² | Q10: Linha neutra - Viga "i" | T10: T | U10: =(L26-2*R76)+18+(L37-2*R76)+(L38+L26-2*R76)+L38+(L37-2*R76)+18+(L27-L38)+(L26-2*R76)+(L27+L42-2*R76)+(L26-2*R76)+(L27+L42-2*R76) -> 388 | X10: 20 | Y10: 320
K11: Laje = g1 | L11: 355 | M11: kgf/m² | Q11: =IF(Q614="Ok","Ok","OBS: Valor da linha neutra é MAIOR que hf1 - armadura ativa necessita verificação") -> Ok | T11: R/A | U11: =(L27-2*R76)+(L26-2*R76)+(L27+L42-2*R76)+(L39-2*R76)+L42+(L26-(L39-2*R76)-2*R76) -> 206 | X11: 25 | Y11: 355
F12: Tabela 11.2 – Valores do coeficiente γf2 | K12: Revestimento = g2 | L12: 100 | M12: kgf/m² | T12: R | U12: =(L27-2*R76)*2+(L26-2*R76)*2 -> 156 | X12: 30 | Y12: 430
F13: Ações | G13: γf2 | K13: Alvenaria = g3 | L13: =L15/100*L16*L17/100 -> 0 | M13: kgf/m | T13: "i" | U13: =7+(L61-2*R76)+((L60-L61)/2)+L63+(L61-2*R76)+L63+(L63-2*R76)+((L60-L61)/2)+(L70-2*R76)+((L62-L61)/2-R76)+((L62-L61)/2)+(L67-2*R76)+15+((L62-L61)/2)-R76+15+(((L62-L61)/2)-R76+((L62-L61)/2))+(L70-2*R76)+(((L62-L61)/2)-R76+((L62-L61)/2))+7 -> 361
G14: Ψ0 | H14: Ψ1 | I14: Ψ2 | K14: Alvenaria | Q14: As' | U14: ='Cisalhamento e Apoios'!$J$76/100 -> 3.64 | V14: m
F15: Cargas de utilização de edificações | K15: e,alv | L15: 0 | M15: cm | Q15: =Taxas!L60 -> 0
F16: Locais em que não há predominância de pesos de equipamentos que permanecem fixos por longos períodos de tempo, nem de elevadas concentrações de pessoas b | G16: 0.5 | H16: 0.4 | I16: 0.3 | K16: y,alv | L16: 1350 | M16: kgf/m² | V16: ='Propriedades geométricas VIGA'!B7 -> 0 | W16: ='Propriedades geométricas VIGA'!C7 -> 0
K17: h,alv | L17: =350-50 -> 300 | M17: cm | V17: ='Propriedades geométricas VIGA'!B8 -> -15 | W17: ='Propriedades geométricas VIGA'!C8 -> 0
K18: Considerar solidarização | M18: 1 - Sim | Q18: As | V18: ='Propriedades geométricas VIGA'!B9 -> -15 | W18: ='Propriedades geométricas VIGA'!C9 -> 40
K19: Seção | M19: 1 - Retângular | Q19: =Taxas!L64 -> 8Ø15.2mm | V19: ='Propriedades geométricas VIGA'!B10 -> -15 | W19: ='Propriedades geométricas VIGA'!C10 -> 45
F20: Locais em que há predominância de pesos de equipamentos que permanecem fixos por longos períodos de tempo, ou de elevada concentração de pessoas c | G20: 0.7 | H20: 0.6 | I20: 0.4 | M20: 3 - R/A | V20: ='Propriedades geométricas VIGA'!B11 -> -15 | W20: ='Propriedades geométricas VIGA'!C11 -> 60
K21: L,balanço,esq | L21: 0 | N21: Comprimento do balanço esquerdo. | V21: ='Propriedades geométricas VIGA'!B12 -> 15 | W21: ='Propriedades geométricas VIGA'!C12 -> 60
K22: L,balanço,dir | L22: 0 | N22: Comprimento do balanço dirito. | V22: ='Propriedades geométricas VIGA'!B13 -> 15 | W22: ='Propriedades geométricas VIGA'!C13 -> 45
F23: Biblioteca, arquivos, oficinas e garagens | G23: 0.8 | H23: 0.7 | I23: 0.6 | K23: Geometria da viga retângular | Q23: Armadura Passiva - ELU | V23: ='Propriedades geométricas VIGA'!B14 -> 15 | W23: ='Propriedades geométricas VIGA'!C14 -> 40
L24: Simples | M24: Composta | Q24: =K1150 -> Necessita armadura passiva ELU | V24: ='Propriedades geométricas VIGA'!B15 -> 15 | W24: ='Propriedades geométricas VIGA'!C15 -> 0
F25: Vento | K25: L,útil | L25: 815 | N25: Comprimento total da viga. | V25: ='Propriedades geométricas VIGA'!B16 -> 0 | W25: ='Propriedades geométricas VIGA'!C16 -> 0
F26: Pressão dinâmica do vento nas estruturas em geral | G26: 0.6 | H26: 0.3 | I26: 0 | K26: bw | L26: 30 | N26: Largura da viga. | V26: ='Propriedades geométricas VIGA'!B17 -> 0 | W26: ='Propriedades geométricas VIGA'!C17 -> 0
K27: h | L27: 60 | N27: Altura da viga. | V27: ='Propriedades geométricas VIGA'!B18 -> 0 | W27: ='Propriedades geométricas VIGA'!C18 -> 0
F28: Temperatura | K28: l,console | L28: 30 | N28: Comprimento do console. | V28: ='Propriedades geométricas VIGA'!B19 -> 0 | W28: ='Propriedades geométricas VIGA'!C19 -> 0
F29: Variações uniformes de temperatura em relação à média anual local | G29: 0.6 | H29: 0.5 | I29: 0.3 | K29: L,útil | L29: =L25-L28 -> 785 | N29: Comprimento útil da viga. | V29: ='Propriedades geométricas VIGA'!B20 -> 0 | W29: ='Propriedades geométricas VIGA'!C20 -> 0
K30: y'.1 | L30: =IF(L1=TRUE(),Homogeneização!L55,'Propriedades geométricas VIGA'!M7) -> 30 | M30: =IF(L1=TRUE(),IF(M18="1 - Sim",Homogeneização!R55,Homogeneização!L55),IF(M18="1 - Sim",'Propriedades geométricas LAJE'!M7,L30)) -> 51.362431 | N30: Centro de gravidade até a borda inferiror. | V30: ='Propriedades geométricas VIGA'!B21 -> 0 | W30: ='Propriedades geométricas VIGA'!C21 -> 0
K31: y'.2 | L31: =IF(L1=TRUE(),Homogeneização!L54,'Propriedades geométricas VIGA'!M8) -> 30 | M31: =IF(L1=TRUE(),IF(M18="1 - Sim",Homogeneização!R54,Homogeneização!L54),IF(M18="1 - Sim",'Propriedades geométricas LAJE'!M8,L31)) -> 38.637569 | N31: Centro de gravidade até a borda superior. | V31: ='Propriedades geométricas VIGA'!B22 -> 0 | W31: ='Propriedades geométricas VIGA'!C22 -> 0
K32: d | L32: =L27-5 -> 55 | N32: Altura útil ESTIMADA. | V32: ='Propriedades geométricas VIGA'!B23 -> 0 | W32: ='Propriedades geométricas VIGA'!C23 -> 0
E33: Tabela 17.2 – Valores máximos de diâmetro e espaçamento, com barras de alta aderência | K33: d' | L33: =L27-L32 -> 5 | N33: Distância do C.G. de Ast até a fibra mais tracionada. | V33: ='Propriedades geométricas VIGA'!B24 -> 0 | W33: ='Propriedades geométricas VIGA'!C24 -> 0
E34: Tensão na barra σsi ou Δσpi MPa | F34: S/ armaduras ativas | H34: C/ armaduras ativas | K34: Consolo | L34: Chanfro | N34: Tipo do consolo. | V34: ='Propriedades geométricas VIGA'!B25 -> 0 | W34: ='Propriedades geométricas VIGA'!C25 -> 0
F35: ϕmáx (mm) | G35: s máx (cm) | H35: ϕmáx (mm) | I35: s máx (cm) | K35: Geometria da aba
E36: 160 | F36: 32 | G36: 30 | H36: 25 | I36: 20 | K36: Laba "T" | L36: 15 | M36: =IF(AND($M$19="1 - Retângular",$M$20="2 - T"),L36,0) -> 0 | N36: Comprimento da aba da seção "T". M36 = aba efetiva usada nos cálculos/desenho (só vale se M20 = "2 - T"; em "1 - R" e "3 - R/A" vale 0).
E37: 200 | F37: 25 | G37: 25 | H37: 16 | I37: 15 | K37: h-aba | L37: 15 | N37: altura menor da aba da viga seção "T".
E38: 240 | F38: 20 | G38: 20 | H38: 12.5 | I38: 10 | K38: h+aba | L38: 20 | N38: altura maior da aba da viga seção "T".
E39: 280 | F39: 16 | G39: 15 | H39: 8 | I39: 5 | K39: Laba R/A | L39: 10 | M39: =((L39*(L42+M46))/100^2)*L25/100 -> 0.26895 | N39: Largura da aba para casos de vigas retangulares com aba. | V39: ='Propriedades geométricas LAJE'!B7 -> 0 | W39: ='Propriedades geométricas LAJE'!C7 -> 0
E40: 320 | F40: 12.5 | G40: 10 | H40: 6 | I40: - | K40: Geometria da mesa colaborante | V40: ='Propriedades geométricas LAJE'!B8 -> -15 | W40: ='Propriedades geométricas LAJE'!C8 -> 0
E41: 360 | F41: 10 | G41: 5 | H41: - | I41: - | K41: Llaje | L41: =455.5+652 -> 1107.5 | N41: Comprimento da laje. | V41: ='Propriedades geométricas LAJE'!B9 -> -15 | W41: ='Propriedades geométricas LAJE'!C9 -> 40
...

Sheet ELU i
T2: Seção 1
T3: x | U3: y | AD3: Section Properties About Centroidal Axis Parallel to Original Axis | AK3: PROPRIEDADES EM TORNO DO EIXO X | AP3: About Original Axis | AU3: DX = | AV3: =MAX(XX)-MIN(XX) -> 30
AD4: f = | AE4: =IF(AE10=0,0,IF(AE8-AE9=0,45,DEGREES(1/2*ATAN(-2*AE10/(AE8-AE9))))) -> 0 | AF4: deg | AG4: X-dim = | AH4: =MAX(XX)-MIN(XX) -> 30 | AI4: =$B$2 -> 0 | AJ4: Ix = | AK4: h | AL4: =AH5 -> 20 | AM4: =AA1 -> 0 | AP4: {=SUM((OFFSET(XX,1,0)-XX)*(YY+OFFSET(YY,1,0))/24*((OFFSET(YY,1,0)+YY)^2+(OFFSET(YY,1,0)-YY)^2))} -> 2555000 | AQ4: =$B$2&"^4" -> ^4 | AR4: Imax = | AS4: =+(AE8+AE9)/2-SQRT((AE8-AE9)^2/4+AE10^2) -> 20000 | AT4: =$B$2&"^4" -> ^4 | AU4: DY= | AV4: =MAX(YY)-MIN(YY) -> 20
AD5: A = | AE5: {=SUM((YY-OFFSET(YY,1,0))*(XX+OFFSET(XX,1,0)))/2} -> 600 | AF5: =$B$2 & "^2" -> ^2 | AG5: Y-dim = | AH5: =MAX(YY)-MIN(YY) -> 20 | AI5: =$B$2 -> 0 | AJ5: Iy = | AK5: A | AL5: =ABS(AE5) -> 600 | AM5: =CONCATENATE(AA1,"²") -> ² | AP5: {=-SUM((OFFSET(YY,1,0)-YY)*(XX+OFFSET(XX,1,0))/24*((OFFSET(XX,1,0)+XX)^2+(OFFSET(XX,1,0)-XX)^2))} -> 45000 | AQ5: =AA1&"^4" -> ^4 | AR5: Imin = | AS5: =+(AE8+AE9)/2+SQRT((AE8-AE9)^2/4+AE10^2) -> 45000 | AT5: =$B$2&"^4" -> ^4 | AU5: Plot of diagonal
AD6: Xcg = | AE6: {=SUM((YY-OFFSET(YY,1,0))/8*((XX+OFFSET(XX,1,0))^2+(OFFSET(XX,1,0)-XX)^2/3))/$AE$5} -> 0 | AF6: =AA1 -> 0 | AG6: Sx(top) = | AH6: =AE8/ABS(MAX(YY)-AE7) -> 2000 | AI6: =$B$2&"^3" -> ^3 | AJ6: Ixy = | AK6: Yi | AL6: =AE7 -> 65 | AM6: =AA1 -> 0 | AP6: {=SUM(((OFFSET(YY,1,0)-YY)^2*(OFFSET(XX,1,0)+XX)*(OFFSET(XX,1,0)^2+XX^2)/8+(OFFSET(YY,1,0)-YY)*(OFFSET(XX,1,0)*YY-XX*OFFSET(YY,1,0))*(OFFSET(XX,1,0)^2+OFFSET(XX,1,0)*XX+XX^2)/3+(OFFSET(XX,1,0)*YY-XX*OFFSET(YY,1,0))^2*(OFFSET(XX,1,0)+XX)/4)*IF(OFFSET(XX,1,0)=XX,0,1/(OFFSET(XX,1,0)-XX)))} -> 0 | AQ6: =AA1&"^4" -> ^4 | AR6: Principal Axis Plot | AU6: to control XY scale
AD7: Ycg = | AE7: {=SUM((OFFSET(XX,1,0)-XX)/8*((YY+OFFSET(YY,1,0))^2+(OFFSET(YY,1,0)-YY)^2/3))/$AE$5} -> 65 | AF7: =AA1 -> 0 | AG7: Sx(bot) = | AH7: =AE8/ABS(MIN(YY)-AE7) -> 2000 | AI7: =$B$2&"^3" -> ^3 | AK7: Ys | AL7: =AH5-AL6 -> -45 | AM7: =AA1 -> 0 | AR7: x | AS7: y | AU7: x | AV7: y
T8: 0 | U8: =U9 -> 55 | AD8: Ixo = | AE8: =AP4-AE5*AE7^2 -> 20000 | AF8: =$B$2&"^4" -> ^4 | AG8: Sy(left) = | AH8: =AE9/ABS(MIN(XX)-AE6) -> 3000 | AI8: =$B$2&"^3" -> ^3 | AK8: Ix | AL8: =ABS(AE8) -> 20000 | AM8: =CONCATENATE(AA1,"4") -> 4 | AR8: =MIN(XX) -> -15 | AS8: =(AR8-$F$7)*TAN(RADIANS($F$5))+$F$8 -> 0 | AU8: =IF(AV3>=AV4,MIN(XX),(MAX(XX)+MIN(XX)-AV4)/2) -> -15 | AV8: =IF(AV3>=AV4,(MAX(YY)+MIN(YY)-AV3)/2,MIN(YY)) -> 50
T9: =Seções!K30 -> -15 | U9: =Seções!L30 -> 55 | AD9: Iyo = | AE9: =AP5-AE5*AE6^2 -> 45000 | AF9: =$B$2&"^4" -> ^4 | AG9: Sy(right)= | AH9: =AE9/ABS(MAX(XX)-AE6) -> 3000 | AI9: =$B$2&"^3" -> ^3 | AK9: Wi | AL9: =ABS(AH7) -> 2000 | AM9: =CONCATENATE(AA1,"³") -> ³ | AR9: =MAX(XX) -> 15 | AS9: =(AR9-$F$7)*TAN(RADIANS($F$5))+$F$8 -> 0 | AU9: =IF(AV3>=AV4,MAX(XX),(MAX(XX)+MIN(XX)+AV4)/2) -> 15 | AV9: =IF(AV3>=AV4,(MAX(YY)+MIN(YY)+AV3)/2,MAX(YY)) -> 80
T10: =Seções!K31 -> -15 | U10: =Seções!L31 -> 75 | AD10: Ixyo = | AE10: =+AP6-AE5*AE6*AE7 -> 0 | AF10: =$B$2&"^4" -> ^4 | AK10: Ws | AL10: =ABS(AH6) -> 2000 | AM10: =CONCATENATE(AA1,"³") -> ³
T11: =Seções!K32 -> 0 | U11: =Seções!L32 -> 75 | AR11: =(AS11-$F$8)*TAN(RADIANS(-$F$5))+$F$7 -> 0 | AS11: =MIN(Y) -> 0
T12: =Seções!K33 -> 15 | U12: =Seções!L33 -> 75 | AD12: Section Properties About Principal Axis | AR12: =(AS12-$F$8)*TAN(RADIANS(-$F$5))+$F$7 -> 0 | AS12: =MAX(Y) -> 60
T13: =Seções!K34 -> 15 | U13: =Seções!L34 -> 55 | AD13: f = | AE13: =AE4 -> 0 | AF13: deg | AG13: Sxp(top) = | AH13: {=ABS(AE14/MAX(SQRT((XX-AE6)^2+(YY-AE7)^2)*SIN(ATAN2(XX-AE6,YY-AE7)-RADIANS(AE4))))} -> 2000 | AI13: =$B$2&"^3" -> ^3
T14: 0 | U14: =U13 -> 55 | AD14: Ixp = | AE14: =AE8*COS(RADIANS(AE13))^2+AE9*SIN(RADIANS(AE13))^2-AE10*SIN(2*RADIANS(AE13)) -> 20000 | AF14: =$B$2&"^4" -> ^4 | AG14: Sxp(bot) = | AH14: {=ABS(AE14/MIN(SQRT((XX-AE6)^2+(YY-AE7)^2)*SIN(ATAN2(XX-AE6,YY-AE7)-RADIANS(AE4))))} -> 307.69231 | AI14: =$B$2&"^3" -> ^3
AD15: Iyp = | AE15: =AE9*COS(RADIANS(AE13))^2+AE8*SIN(RADIANS(AE13))^2+AE10*SIN(2*RADIANS(AE13)) -> 45000 | AF15: =$B$2&"^4" -> ^4 | AG15: Syp(left) = | AH15: {=ABS($F$16/MIN(SQRT((XX-AE6)^2+(YY-AE7)^2)*COS(ATAN2(XX-AE6,YY-AE7)-RADIANS(AE4))))} -> 0 | AI15: =$B$2&"^3" -> ^3
AD16: Ixyp = | AE16: =+(AE8-AE9)/2*SIN(RADIANS(AE13)*2)+AE10*COS(2*RADIANS(AE13)) -> 0 | AF16: =$B$2&"^4" -> ^4 | AG16: Syp(right)= | AH16: {=ABS(AE15/MAX(SQRT((XX-AE6)^2+(YY-AE7)^2)*COS(ATAN2(XX-AE6,YY-AE7)-RADIANS(AE4))))} -> 3000 | AI16: =$B$2&"^3" -> ^3
AD17: J = | AE17: =+AE14+AE15 -> 65000 | AF17: =$B$2&"^4" -> ^4 | AK17: =IF($C$3="Retângular",Seções!AA7,Seções!AJ24) -> 0
F24: Geometria da viga i ou T
F25: bf | G25: =Geometria!L60 -> 30 | H25: cm | I25: Largura do topo da viga. | T25: Seção 2
F26: tw | G26: =Geometria!L61 -> 12 | H26: cm | I26: Espessura da alma. | T26: x | U26: y | AD26: Section Properties About Centroidal Axis Parallel to Original Axis | AK26: PROPRIEDADES EM TORNO DO EIXO X | AP26: About Original Axis | AU26: DX = | AV26: =MAX(XXX)-MIN(XXX) -> 30
F27: bw | G27: =Geometria!L62 -> 40 | H27: cm | I27: Largura da base da viga. | AD27: f = | AE27: =IF(AE33=0,0,IF(AE31-AE32=0,45,DEGREES(1/2*ATAN(-2*AE33/(AE31-AE32))))) -> 0 | AF27: deg | AG27: X-dim = | AH27: =MAX(XXX)-MIN(XXX) -> 30 | AI27: =$B$2 -> 0 | AJ27: Ix = | AK27: h | AL27: =AH28 -> 5 | AM27: =AA24 -> 0 | AP27: {=SUM((OFFSET(XXX,1,0)-XXX)*(YYY+OFFSET(YYY,1,0))/24*((OFFSET(YYY,1,0)+YYY)^2+(OFFSET(YYY,1,0)-YYY)^2))} -> 293562.5 | AQ27: =$B$2&"^4" -> ^4 | AR27: Imax = | AS27: =+(AE31+AE32)/2-SQRT((AE31-AE32)^2/4+AE33^2) -> 205.35714 | AT27: =$B$2&"^4" -> ^4 | AU27: DY= | AV27: =MAX(YYY)-MIN(YYY) -> 5
F28: hf1 | G28: =Geometria!L63 -> 20 | H28: cm | I28: Altura da mesa superior 1. | AD28: A = | AE28: {=SUM((YYY-OFFSET(YYY,1,0))*(XXX+OFFSET(XXX,1,0)))/2} -> 105 | AF28: =$B$2 & "^2" -> ^2 | AG28: Y-dim = | AH28: =MAX(YYY)-MIN(YYY) -> 5 | AI28: =$B$2 -> 0 | AJ28: Iy = | AK28: A | AL28: =ABS(AE28) -> 105 | AM28: =CONCATENATE(AA24,"²") -> ² | AP28: {=-SUM((OFFSET(YYY,1,0)-YYY)*(XXX+OFFSET(XXX,1,0))/24*((OFFSET(XXX,1,0)+XXX)^2+(OFFSET(XXX,1,0)-XXX)^2))} -> 4567.5 | AQ28: =AA24&"^4" -> ^4 | AR28: Imin = | AS28: =+(AE31+AE32)/2+SQRT((AE31-AE32)^2/4+AE33^2) -> 4567.5 | AT28: =$B$2&"^4" -> ^4 | AU28: Plot of diagonal
F29: hf2 | G29: =Geometria!L64 -> 5 | H29: cm | I29: Altura da mesa superior 2. | AD29: Xcg = | AE29: {=SUM((YYY-OFFSET(YYY,1,0))/8*((XXX+OFFSET(XXX,1,0))^2+(OFFSET(XXX,1,0)-XXX)^2/3))/AE28} -> 0 | AF29: =AA24 -> 0 | AG29: Sx(top) = | AH29: =AE31/ABS(MAX(YYY)-AE30) -> 95.833333 | AI29: =$B$2&"^3" -> ^3 | AJ29: Ixy = | AK29: Yi | AL29: =AE30 -> 52.857143 | AM29: =AA24 -> 0 | AP29: {=SUM(((OFFSET(YYY,1,0)-YYY)^2*(OFFSET(XXX,1,0)+XXX)*(OFFSET(XXX,1,0)^2+XXX^2)/8+(OFFSET(YYY,1,0)-YYY)*(OFFSET(XXX,1,0)*YYY-XXX*OFFSET(YYY,1,0))*(OFFSET(XXX,1,0)^2+OFFSET(XXX,1,0)*XXX+XXX^2)/3+(OFFSET(XXX,1,0)*YYY-XXX*OFFSET(YYY,1,0))^2*(OFFSET(XXX,1,0)+XXX)/4)*IF(OFFSET(XXX,1,0)=XXX,0,1/(OFFSET(XXX,1,0)-XXX)))} -> 0 | AQ29: =AA24&"^4" -> ^4 | AR29: Principal Axis Plot | AU29: to control XY scale
F30: hf3 | G30: =Geometria!L65 -> 30 | H30: cm | I30: Altura da mesa central 3. | T30: 0 | U30: =U31 -> 50 | AD30: Ycg = | AE30: {=SUM((OFFSET(XXX,1,0)-XXX)/8*((YYY+OFFSET(YYY,1,0))^2+(OFFSET(YYY,1,0)-YYY)^2/3))/AE28} -> 52.857143 | AF30: =AA24 -> 0 | AG30: Sx(bot) = | AH30: =AE31/ABS(MIN(YYY)-AE30) -> 71.875 | AI30: =$B$2&"^3" -> ^3 | AK30: Ys | AL30: =AH28-AL29 -> -47.857143 | AM30: =AA24 -> 0 | AR30: x | AS30: y | AU30: x | AV30: y
F31: hf4 | G31: =Geometria!L66 -> 5 | H31: cm | I31: Altura da mesa inferior 4. | T31: =Seções!K29 -> -6 | U31: =Seções!L29 -> 50 | AD31: Ixo = | AE31: =AP27-AE28*AE30^2 -> 205.35714 | AF31: =$B$2&"^4" -> ^4 | AG31: Sy(left) = | AH31: =AE32/ABS(MIN(XXX)-AE29) -> 304.5 | AI31: =$B$2&"^3" -> ^3 | AK31: Ix | AL31: =ABS(AE31) -> 205.35714 | AM31: =CONCATENATE(AA24,"4") -> 4 | AR31: =MIN(XXX) -> -15 | AS31: =(AR31-$F$7)*TAN(RADIANS($F$5))+$F$8 -> 0 | AU31: =IF(AV26>=AV27,MIN(XXX),(MAX(XXX)+MIN(XXX)-AV27)/2) -> -15 | AV31: =IF(AV26>=AV27,(MAX(YYY)+MIN(YYY)-AV26)/2,MIN(YYY)) -> 37.5
F32: hf5 | G32: =Geometria!L67 -> 15 | H32: cm | I32: Altura da mesa inferior 5. | T32: =Seções!K30 -> -15 | U32: =Seções!L30 -> 55 | AD32: Iyo = | AE32: =AP28-AE28*AE29^2 -> 4567.5 | AF32: =$B$2&"^4" -> ^4 | AG32: Sy(right)= | AH32: =AE32/ABS(MAX(XXX)-AE29) -> 304.5 | AI32: =$B$2&"^3" -> ^3 | AK32: Wi | AL32: =ABS(AH30) -> 71.875 | AM32: =CONCATENATE(AA24,"³") -> ³ | AR32: =MAX(XXX) -> 15 | AS32: =(AR32-$F$7)*TAN(RADIANS($F$5))+$F$8 -> 0 | AU32: =IF(AV26>=AV27,MAX(XXX),(MAX(XXX)+MIN(XXX)+AV27)/2) -> 15 | AV32: =IF(AV26>=AV27,(MAX(YYY)+MIN(YYY)+AV26)/2,MAX(YYY)) -> 67.5
F33: Lvão | G33: =Geometria!L68 -> 785 | H33: cm | I33: Tamanho da viga. | T33: =Seções!K31 -> -15 | U33: =U32 -> 55 | AD33: Ixyo = | AE33: =+AP29-AE28*AE29*AE30 -> 0 | AF33: =$B$2&"^4" -> ^4 | AK33: Ws | AL33: =ABS(AH29) -> 95.833333 | AM33: =CONCATENATE(AA24,"³") -> ³
F34: bw | G34: =Geometria!L69 -> 40 | H34: cm | I34: Largura da base da viga. | T34: =Seções!K32 -> 0 | U34: =U33 -> 55 | AR34: =(AS34-$F$8)*TAN(RADIANS(-$F$5))+$F$7 -> 0 | AS34: =MIN(Y) -> 0
F35: h | G35: =Geometria!L70 -> 75 | H35: cm | I35: Altura da viga. | T35: =Seções!K33 -> 15 | U35: =U36 -> 55 | AD35: Section Properties About Principal Axis | AR35: =(AS35-$F$8)*TAN(RADIANS(-$F$5))+$F$7 -> 0 | AS35: =MAX(Y) -> 60
T36: =Seções!K34 -> 15 | U36: =Seções!L34 -> 55 | AD36: f = | AE36: =AE27 -> 0 | AF36: deg | AG36: Sxp(top) = | AH36: {=ABS(AE37/MAX(SQRT((XXX-AE29)^2+(YYY-AE30)^2)*SIN(ATAN2(XXX-$F$7,YYY-AE30)-RADIANS(AE27))))} -> 95.833333 | AI36: =$B$2&"^3" -> ^3
F37: Em casos de seção "i" | T37: =Seções!K35 -> 6 | U37: =Seções!L35 -> 50 | AD37: Ixp = | AE37: =AE31*COS(RADIANS(AE36))^2+AE32*SIN(RADIANS(AE36))^2-AE33*SIN(2*RADIANS(AE36)) -> 205.35714 | AF37: =$B$2&"^4" -> ^4 | AG37: Sxp(bot) = | AH37: {=ABS(AE37/MIN(SQRT((XXX-AE29)^2+(YYY-AE30)^2)*SIN(ATAN2(XXX-AE29,YYY-AE30)-RADIANS(AE27))))} -> 3.8851351 | AI37: =$B$2&"^3" -> ^3
F38: Md | G38: =Geometria!L1038*100 -> 202227.8 | H38: kN*cm | T38: 0 | U38: =U37 -> 50 | AD38: Iyp = | AE38: =AE32*COS(RADIANS(AE36))^2+AE31*SIN(RADIANS(AE36))^2+AE33*SIN(2*RADIANS(AE36)) -> 4567.5 | AF38: =$B$2&"^4" -> ^4 | AG38: Syp(left) = | AH38: {=ABS(AE38/MIN(SQRT((XXX-AE29)^2+(YYY-AE30)^2)*COS(ATAN2(XXX-AE29,YYY-AE30)-RADIANS(AE27))))} -> 304.5 | AI38: =$B$2&"^3" -> ^3
F39: Kmd,"i" | G39: =Geometria!R1038 -> 0.46442678 | H39: =G38/100 -> 2022.278 | AD39: Ixyp = | AE39: =+(AE31-AE32)/2*SIN(RADIANS(AE36)*2)+AE33*COS(2*RADIANS(AE36)) -> 0 | AF39: =$B$2&"^4" -> ^4 | AG39: Syp(right)= | AH39: {=ABS(AE38/MAX(SQRT((XXX-AE29)^2+(YYY-AE30)^2)*COS(ATAN2(XXX-AE29,YYY-AE30)-RADIANS(AE27))))} -> 304.5 | AI39: =$B$2&"^3" -> ^3
F40: kx | G40: =Geometria!R1039 -> 0.628 | AD40: J = | AE40: =+AE37+AE38 -> 4772.8571 | AF40: =$B$2&"^4" -> ^4 | AK40: =IF($C$3="Retângular",Seções!AA30,Seções!AJ47) -> 0
F41: kz | G41: =Geometria!R1040 -> 0.748
F42: ε,s | G42: =Geometria!R1041 -> 2.06
F43: x | G43: =Geometria!R1042 -> 0.27859271
F44: fpd | G44: =Geometria!R1043 -> 132
F46: fyk = | G46: =Geometria!L81 -> 500 | H46: MPa | I46: Resistência caracterítica ao escoamento das barras de aço.
F47: fck = | G47: =Geometria!L82 -> 50 | H47: MPa | I47: Resistência característica à compressão do concreto.
F48: fck = | G48: =Geometria!L83 -> 30 | H48: MPa | I48: Resistência característica à compressão do concreto da laje.
...

Sheet Homogeneização
K2: 2 . Homogeneização da seção - Cordoalhas
K4: Ac = | L4: ='Propriedades geométricas VIGA'!M6 -> 1800 | M4: cm²
K5: I = | L5: ='Propriedades geométricas VIGA'!M9 -> 540000 | M5: cm²
K6: y'.1 = | L6: ='Propriedades geométricas VIGA'!M7 -> 30 | M6: cm
K7: y'.2 = | L7: ='Propriedades geométricas VIGA'!M8 -> 30 | M7: cm
K9: Ach = | L9: =L4-(Geometria!L252+Geometria!L266)+L11*(Geometria!L252+Geometria!L266) -> 1864.9829 | M9: cm²
K11: α = | L11: =L73 -> 6.8020463
K12: yhs = | L12: =IF(Geometria!$M$19="2 - i",Geometria!$L$70,Geometria!$L$27)-L13 -> 30.65332 | M12: cm | N12: yhs = H - yhi (mesma referencia, complementar)
K13: yhi = | L13: =(L4*L6+(L11-1)*Geometria!L252*Geometria!R253+(L11-1)*Geometria!L266*(IF(Geometria!$M$19="2 - i",Geometria!$L$70,Geometria!$L$27)-Geometria!R267))/L9 -> 29.34668 | M13: cm | N13: yhi = (Ac.Yi + (a-1).Ap.hp + (a-1).A'p.h'p) / Ach -> media ponderada DIRETA das areas em relacao a base, com as duas armaduras (Ap e A'p) ao mesmo tempo. Antes: calculava cada armadura isolada e tirava media simetrica (aproximacao errada)
K14: Dy = | L14: =L17 -> 30.65332
K15: Ih = | L15: =L5+L4*(L6-L13)^2+(L11-1)*Geometria!L252*(L13-Geometria!R253)^2+(L11-1)*Geometria!L266*(L13-(IF(Geometria!$M$19="2 - i",Geometria!$L$70,Geometria!$L$27)-Geometria!R267))^2 -> 562049.53 | M15: cm^4 | N15: Ih = I + Ac.(Yi-yhi)^2 + (a-1).Ap.(yhi-hp)^2 + (a-1).A'p.(yhi-h'p)^2 -> Steiner com AREA BRUTA (Ac) e distancias ATE O NOVO centroide (yhi), nao ate o antigo
K17: yhs = | L17: =IF(Geometria!$M$19="2 - i",Geometria!$L$70,Geometria!$L$27)-L18 -> 30.65332
K18: yhi = | L18: =L13 -> 29.34668
K19: Wh
K20: Whs = | L20: =L15/L17 -> 18335.682 | M20: cm³
K21: Whi = | L21: =L15/L18 -> 19152.065 | M21: cm³
K23: 2 . Homogeneização da seção composta
K25: Ac = | L25: ='Propriedades geométricas LAJE'!M6 -> 3105.1954 | M25: cm²
K26: I = | L26: =IF(Geometria!$M$18="1 - Sim",'Propriedades geométricas LAJE'!M9,0) -> 2598580.9 | M26: cm²
K27: y'.1 = | L27: =IF(Geometria!$M$18="1 - Sim",'Propriedades geométricas LAJE'!M7,0) -> 51.362431 | M27: cm
K28: y'.2 = | L28: =IF(Geometria!$M$18="1 - Sim",'Propriedades geométricas LAJE'!M8,0) -> 38.637569 | M28: cm
K30: Ach,comp = | L30: =L25-(Geometria!L252+Geometria!L266)+L32*(Geometria!L252+Geometria!L266) -> 3155.1506 | M30: cm²
K32: α = | L32: =L78 -> 5.460284
K33: yhs = | L33: =IF(Geometria!$M$18="1 - Sim",IF(Geometria!$M$19="2 - i",Geometria!$L$70,Geometria!$L$27)+Geometria!L42+Geometria!L45-L34,0) -> 39.272665 | M33: cm | N33: yhs = H,total - yhi (H,total = viga + capa + laje)
K34: yhi = | L34: =IF(Geometria!$M$18="1 - Sim",(L25*L27+(L32-1)*Geometria!L252*Geometria!R253+(L32-1)*Geometria!L266*(IF(Geometria!$M$19="2 - i",Geometria!$L$70,Geometria!$L$27)-Geometria!R267))/L30,0) -> 50.727335 | M34: cm | N34: yhi = (Ac,comp.Yi,comp + (a-1).Ap.hp + (a-1).A'p.h'p) / Ach,comp -> agora usa a area/Yi da SECAO COMPOSTA (L25/L28). Antes usava por engano a area/Yi da viga isolada (L4/L6) - maior erro de todos, ~3cm de LN e ~16% no Ih
K35: Dy = | L35: =IF(Geometria!$M$18="1 - Sim",L38,0) -> 39.272665
K36: Ih = | L36: =IF(Geometria!$M$18="1 - Sim",L26+L25*(L27-L34)^2+(L32-1)*Geometria!L252*(L34-Geometria!R253)^2+(L32-1)*Geometria!L266*(L34-(IF(Geometria!$M$19="2 - i",Geometria!$L$70,Geometria!$L$27)-Geometria!R267))^2,0) -> 2677686.5 | M36: cm^4 | N36: Ih = I,comp + Ac,comp.(Yi,comp-yhi)^2 + (a-1).Ap.(yhi-hp)^2 + (a-1).A'p.(yhi-h'p)^2
K38: yhs = | L38: =IF(Geometria!$M$18="1 - Sim",IF(Geometria!$M$19="2 - i",Geometria!$L$70,Geometria!$L$27)+Geometria!L42+Geometria!L45-L39,0) -> 39.272665
K39: yhi = | L39: =IF(Geometria!$M$18="1 - Sim",L34,0) -> 50.727335
K40: Wh
K41: Whs = | L41: =IF(Geometria!$M$18="1 - Sim",L36/L38,0) -> 68181.94 | M41: cm³
K42: Whi = | L42: =IF(Geometria!$M$18="1 - Sim",L36/L39,0) -> 52785.87 | M42: cm³
K44: 2 . Homogeneização da seção - Vergalhão
L45: seção pré | R45: seção composta
K46: Ac = | L46: =L9 -> 1864.9829 | M46: cm² | Q46: Ac = | R46: =L30 -> 3155.1506 | S46: cm²
K47: I = | L47: =L15 -> 562049.53 | M47: cm² | Q47: I = | R47: =IF(Geometria!$M$18="1 - Sim",L36,0) -> 2677686.5 | S47: cm²
K48: y'.1 = | L48: =L18 -> 29.34668 | M48: cm | Q48: y'.1 = | R48: =IF(Geometria!$M$18="1 - Sim",L39,0) -> 50.727335 | S48: cm
K49: y'.2 = | L49: =L17 -> 30.65332 | M49: cm | Q49: y'.2 = | R49: =IF(Geometria!$M$18="1 - Sim",L38,0) -> 39.272665 | S49: cm
K51: Ach = | L51: =L46-(IFERROR(Taxas!K51,0)+IFERROR(Taxas!K58,0))+L53*(IFERROR(Taxas!K51,0)+IFERROR(Taxas!K58,0)) -> 2050.1318 | M51: cm² | Q51: Ach = | R51: =R46-(IFERROR(Taxas!K51,0)+IFERROR(Taxas!K58,0))+R53*(IFERROR(Taxas!K51,0)+IFERROR(Taxas!K58,0)) -> 3297.8311 | S51: cm²
K53: α = | L53: =L74 -> 7.1421486 | Q53: α = | R53: =L79 -> 5.7332982
...

Sheet Isolamento de cabos
L2: 9 . Perdas de protensão
L3: Tamanho da pista | M3: =Geometria!L280 -> 100 | N3: m
L4: Acomodação da cunha | M4: 0.6 | N4: cm
L6: Δσancoragem | M6: =(2*10^4*M4/100)/M3 -> 1.2 | N6: kN/cm²
L10: Relaxação da armadura | Q10: Perdas diferidas
L12: σ,pi | M12: =Geometria!N236-M6 -> 145.1 | N12: kN/cm² | Q12: Seção 1 (viga)
Q13: Ac | R13: =Geometria!Q290 -> 1800
L14: R | M14: =M12/190 -> 0.76368421 | N14: =M14*100 -> 76.368421 | Q14: Perímetro | R14: =Geometria!Q291 -> 201.62278 | S14: cm
L15: Ѱ | M15: 1.772
L16: Δσ,pr | M16: =M15/100*M12 -> 2.571172 | N16: kN/cm² | Q16: Seção 2 (laje)
Q17: Ac | R17: =Geometria!Q294 -> 3105.1954
Q18: Perímetro | R18: =Geometria!Q295 -> 187 | S18: cm
L19: Perda por deformação imediata do concreto
L21: A,p | M21: =Geometria!P1414 -> 5.6 | N21: cm² | Q21: Np | R21: =M21*N47+M23*N48 -> 749.9028 | S21: kN
L22: e,p | M22: =Geometria!L30-Geometria!P1406 -> 28.5 | N22: cm | Q22: Mp | R22: =M21*N47*M22/100-M23*N48*M24/100 -> 213.7223 | S22: kN*m
L23: A',p | M23: =Geometria!P1429 -> 0 | N23: cm²
L24: e',p | M24: =Geometria!L31-Geometria!P1421 -> 30 | N24: cm
Q25: A | R25: =(R21/(Geometria!L48/100^2)+(R22-Geometria!M206)/(Geometria!L49/100^4)*(M22/100))*O54 -> 32881.447 | S25: kN/m²
Q26: B | R26: =((Geometria!M207*R56+Geometria!M208*R57)*(M22/100))/(Geometria!L49/100^4) -> 25379.208 | S26: kN/m²
L27: σ,pi | M27: =Geometria!N236-(M6+M16) -> 142.52883 | N27: kN/cm² | Q27: C | R27: =((Geometria!M210*R58+Geometria!M209*R59)*((Geometria!M30/100)-(Geometria!L277/100)))/(Geometria!M49/100^4) -> 1228.6509 | S27: kN/m²
Q28: D | R28: =Geometria!L77*((Geometria!M211*((Geometria!M30/100)-(Geometria!L277/100)))/(Geometria!M49/100^4))*R60 -> 11479.365 | S28: kN/m²
L30: Np | M30: =M21*M27+M23*M27 -> 798.16144 | N30: kN
L31: Mp | M31: =M21*M27*M22/100-M23*M27*M24/100 -> 227.47601 | N31: kN*cm | Q31: σ,p | R31: =Geometria!Q308 -> 5.0507627
Q32: Δσ,p,c,inf | R32: =(R31*(R25-R26-R27-R28)) -> -26293.139 | S32: kN/m²
R33: =R32/100^2 -> -2.6293139 | S33: kN/cm²
L34: σc,po+g,inf | M34: =(M30/(Geometria!L48/100^2)+((M31-Geometria!M206)/(Geometria!L49/100^4))*M22/100) -> 14275.097 | N34: kN/m²
L35: σc,po+g,sup | M35: =(M30/(Geometria!L48/100^2)+((-M31+Geometria!M206)/(Geometria!L49/100^4))*M24/100) -> -5924.5772 | N35: kN/m²
Q37: A' | R37: =(R21/(Geometria!L48/100^2)+((-R22+Geometria!M206)/(Geometria!L49/100^4))*M24/100)*R54 -> -13440.13 | S37: kN/m²
Q38: B | R38: =((Geometria!M207*R56+Geometria!M208*R57)*M24/100)/(Geometria!L49/100^4) -> 26714.955 | S38: kN/m²
L39: Eci | M39: =Geometria!L316 -> 33130.047 | N39: Mpa | Q39: C | R39: =((Geometria!M210*R58+Geometria!M209*R59)*((Geometria!M31-Geometria!R76-Geometria!L42-Geometria!L45)/100))/(Geometria!M49/100^4) -> 172.67974 | S39: kN/m²
L40: σp | M40: =200000/M39 -> 6.0368161 | Q40: D | R40: =Geometria!L77*((Geometria!M211*((Geometria!M31-Geometria!R76-Geometria!L42-Geometria!L45)/100)))/(Geometria!M49/100^4)*R60 -> 1613.358 | S40: kN/m²
L43: Δσcg,inf | M43: =M40*M34/10000 -> 8.6176137 | N43: kN/cm² | Q43: Δσ,p,c,sup | R43: =R31*ABS(-R37-R38-R39-R40) -> 76068.847 | S43: kN/m²
L44: Δσcg,sup | M44: =M40*M35/10000 -> -3.5765583 | N44: kN/cm² | R44: =R43/100^2 -> 7.6068847 | S44: kN/cm²
M47: σpinf,t=1 | N47: =Geometria!N236-M6-M16-M43 -> 133.91121 | O47: kN/cm² | P47: =100-(N47*100)/Geometria!N236 -> 8.4680695
M48: σpsup,t=1 | N48: =Geometria!N236-M6-M16-M44 -> 146.10539 | O48: kN/cm² | P48: =100-(N48*100)/Geometria!N236 -> 0.13302372
L51: 10 . Coeficientes de fluência
M53: Ação | N53: t₀ seção 01 | O53: Coeficiente φ seção 01 | P53: t₀ seção 02 | Q53: Coeficiente φ seção 02 | R53: Coeficiente φ final
M54: Protensão | N54: 1 | O54: =Fluência!$B$44 -> 2.4758069 | P54: -- | Q54: -- | R54: =AVERAGE(O54,Q54) -> 2.4758069
M55: Pp VIGA | N55: 1 | O55: =Fluência!$B$44 -> 2.4758069 | P55: -- | Q55: -- | R55: =AVERAGE(O55,Q55) -> 2.4758069
M56: PP Laje | N56: 15 | O56: =Fluência!$V$44 -> 1.5488539 | P56: -- | Q56: -- | R56: =AVERAGE(O56,Q56) -> 1.5488539
...

Sheet Tensões
E1: Np | F1: =Geometria!L906 -> 1475.4133 | G1: kN | N1: Np,tot | O1: =Geometria!L373 -> 1243.5596 | P1: kN
E2: Mp | F2: =Geometria!L907 -> 276.63999 | G2: kN | N2: Mp,tot | O2: =Geometria!L374 -> 233.16743 | P2: kN*m
A4: ATO | M4: ELS-F, MÁXIMO | Y4: ELS-F, Mínimo | AK4: ELS-D, MÁXIMO | AW4: ELS-D, MÍNIMO
C6: Tensão ajustada | D6: Tensão reduzida pelo comprimento de transferência | F6: Tensão calculada | I6: Np | J6: Mp | O6: Tensão ajustada | P6: Tensão reduzida pelo comprimento de transferência | R6: Tensão calculada | U6: Np | V6: Mp | AA6: Tensão ajustada | AB6: Tensão reduzida pelo comprimento de transferência | AD6: Tensão calculada | AG6: Np | AH6: Mp | AM6: Tensão ajustada | AN6: Tensão reduzida pelo comprimento de transferência | AP6: Tensão calculada | AS6: Np | AT6: Mp | AY6: Tensão ajustada | AZ6: Tensão reduzida pelo comprimento de transferência | BB6: Tensão calculada | BE6: Np | BF6: Mp
A8: σi,1 | B8: =IF(Geometria!$K$437<Geometria!$N$1307/100,"Reduzir","OK") -> Reduzir | C8: =IF(B8="Reduzir",D8,F8) -> 0 | D8: 0 | E8: 0 | F8: =Geometria!$C$913 -> 0 | I8: 0 | J8: 0 | M8: σi,1 | N8: =IF(Geometria!$K$437<Geometria!$N$1307/100,"Reduzir","OK") -> Reduzir | O8: =IF(N8="Reduzir",P8,R8) -> 0 | P8: 0 | Q8: 0 | R8: =Geometria!$C$913 -> 0 | U8: 0 | V8: 0 | Y8: σi,1 | Z8: =IF(Geometria!$K$437<Geometria!$N$1307/100,"Reduzir","OK") -> Reduzir | AA8: =IF(Z8="Reduzir",AB8,AD8) -> 0 | AB8: 0 | AC8: 0 | AD8: =Geometria!$C$913 -> 0 | AG8: 0 | AH8: 0 | AK8: σi,1 | AL8: =IF(Geometria!$K$437<Geometria!$N$1307/100,"Reduzir","OK") -> Reduzir | AM8: =IF(AL8="Reduzir",AN8,AP8) -> 0 | AN8: 0 | AO8: 0 | AP8: =Geometria!$C$913 -> 0 | AS8: 0 | AT8: 0 | AW8: σi,1 | AX8: =IF(Geometria!$K$437<Geometria!$N$1307/100,"Reduzir","OK") -> Reduzir | AY8: =IF(AX8="Reduzir",AZ8,BB8) -> 0 | AZ8: 0 | BA8: 0 | BB8: =Geometria!$C$913 -> 0 | BE8: 0 | BF8: 0
A9: σi,2 | B9: =IF(Geometria!$L$437<Geometria!$N$1307/100,"Reduzir","OK") -> Reduzir | C9: =IF(B9="Reduzir",D9,F9) -> 1795.0896 | D9: =-I9/(Geometria!$L$48/100^2)+J9/(Geometria!$L$52/100^3)-Geometria!$L$898/(Geometria!$L$52/100^3) -> 1795.0896 | E9: =(((Geometria!$L$326*(Geometria!$L$897*100))/Geometria!$N$1307)) -> 48.979188 | F9: =-'Perdas por Seção'!$D$101/(Geometria!$L$48/100^2)+'Perdas por Seção'!$D$102/(Geometria!$L$52/100^3)-Geometria!$L$898/(Geometria!$L$52/100^3) -> 6701.2696 | I9: =Geometria!$L$298*E32+Geometria!$L$300*E9 -> 458.34209 | J9: =Geometria!$L$298*E32*Geometria!$L$299/100-Geometria!$L$300*E9*Geometria!$L$301/100 -> 85.939142 | M9: σi,2 | N9: =IF(Geometria!$L$437<Geometria!$N$1307/100,"Reduzir","OK") -> Reduzir | O9: =IF(N9="Reduzir",P9,R9) -> -1628.4279 | P9: =-(U9/(Geometria!$L$48/100^2))+(V9/(Geometria!$L$52/100^3))-(('Cargas adicionais'!$O$244)/(Geometria!$L$52/100^3))-(('Cargas adicionais'!$R$244)/(Geometria!$L$401))-((Geometria!$L$76*'Cargas adicionais'!$U$244)/(Geometria!$L$401)) -> -1628.4279 | Q9: =(((Geometria!$N$369*(Geometria!$L$897*100))/Geometria!$N$1307)) -> 41.387508 | R9: =-('Perdas por Seção'!$D$99/(Geometria!$L$48/100^2))+('Perdas por Seção'!$D$100/(Geometria!$L$52/100^3))-(('Cargas adicionais'!$O$244)/(Geometria!$L$52/100^3))-(('Cargas adicionais'!$R$244)/(Geometria!$L$401))-((Geometria!$L$76*'Cargas adicionais'!$U$244)/(Geometria!$L$401)) -> 1934.627 | U9: =Geometria!$L$298*Q32+Geometria!$L$300*Q9 -> 386.31597 | V9: =Geometria!$L$298*Q32*Geometria!$L$299/100-Geometria!$L$300*Q9*Geometria!$L$301/100 -> 72.434245 | Y9: σi,2 | Z9: =IF(Geometria!$L$437<Geometria!$N$1307/100,"Reduzir","OK") -> Reduzir | AA9: =IF(Z9="Reduzir",AB9,AD9) -> -1628.4279 | AB9: =-(AG9/(Geometria!$L$48/100^2))+(AH9/(Geometria!$L$52/100^3))-(('Cargas adicionais'!$O$244)/(Geometria!$L$52/100^3))-(('Cargas adicionais'!$R$244)/(Geometria!$L$401))-((Geometria!$L$76*'Cargas adicionais'!$U$244)/(Geometria!$L$401)) -> -1628.4279 | AC9: =(((Geometria!$N$369*(Geometria!$L$897*100))/Geometria!$N$1307)) -> 41.387508 | AD9: =-('Perdas por Seção'!$D$99/(Geometria!$L$48/100^2))+('Perdas por Seção'!$D$100/(Geometria!$L$52/100^3))-(('Cargas adicionais'!$O$244)/(Geometria!$L$52/100^3))-(('Cargas adicionais'!$R$244)/(Geometria!$L$401)) -> 2360.5944 | AG9: =Geometria!$L$298*AC32+Geometria!$L$300*AC9 -> 386.31597 | AH9: =Geometria!$L$298*AC32*Geometria!$L$299/100-Geometria!$L$300*AC9*Geometria!$L$301/100 -> 72.434245 | AK9: σi,2 | AL9: =IF(Geometria!$L$437<Geometria!$N$1307/100,"Reduzir","OK") -> Reduzir | AM9: =IF(AL9="Reduzir",AN9,AP9) -> -1628.4279 | AN9: =-(AS9/(Geometria!$L$48/100^2))+(AT9/(Geometria!$L$52/100^3))-(('Cargas adicionais'!$O$244)/(Geometria!$L$52/100^3))-(('Cargas adicionais'!$R$244)/(Geometria!$L$401))-((Geometria!$L$76*'Cargas adicionais'!$U$244)/(Geometria!$L$401)) -> -1628.4279 | AO9: =(((Geometria!$N$369*(Geometria!$L$897*100))/Geometria!$N$1307)) -> 41.387508 | AP9: =-('Perdas por Seção'!$D$99/(Geometria!$L$48/100^2))+('Perdas por Seção'!$D$100/(Geometria!$L$52/100^3))-((Geometria!$L$673)/(Geometria!$L$52/100^3))-((Geometria!$L$684)/(Geometria!$L$401))-((Geometria!$L$77*Geometria!$L$695)/(Geometria!$L$401)) -> 2076.6162 | AS9: =Geometria!$L$298*AO32+Geometria!$L$300*AO9 -> 386.31597 | AT9: =Geometria!$L$298*AO32*Geometria!$L$299/100-Geometria!$L$300*AO9*Geometria!$L$301/100 -> 72.434245 | AW9: σi,2 | AX9: =IF(Geometria!$L$437<Geometria!$N$1307/100,"Reduzir","OK") -> Reduzir | AY9: =IF(AX9="Reduzir",AZ9,BB9) -> -1628.4279 | AZ9: =-(BE9/(Geometria!$L$48/100^2))+(BF9/(Geometria!$L$52/100^3))-(('Cargas adicionais'!$O$244)/(Geometria!$L$52/100^3))-(('Cargas adicionais'!$R$244)/(Geometria!$L$401))-((Geometria!$L$76*'Cargas adicionais'!$U$244)/(Geometria!$L$401)) -> -1628.4279 | BA9: =(((Geometria!$N$369*(Geometria!$L$897*100))/Geometria!$N$1307)) -> 41.387508 | BB9: =-('Perdas por Seção'!$D$99/(Geometria!$L$48/100^2))+('Perdas por Seção'!$D$100/(Geometria!$L$52/100^3))-((Geometria!$L$673)/(Geometria!$L$52/100^3))-((Geometria!$L$684)/(Geometria!$L$401)) -> 2360.5944 | BE9: =Geometria!$L$298*BA32+Geometria!$L$300*BA9 -> 386.31597 | BF9: =Geometria!$L$298*BA32*Geometria!$L$299/100-Geometria!$L$300*BA9*Geometria!$L$301/100 -> 72.434245
A10: σi,3 | B10: =IF(Geometria!$M$437<Geometria!$N$1307/100,"Reduzir","OK") -> Reduzir | C10: =IF(B10="Reduzir",D10,F10) -> 4023.1414 | D10: =-I10/(Geometria!$L$48/100^2)+J10/(Geometria!$L$52/100^3)-Geometria!$L$898/(Geometria!$L$52/100^3) -> 4023.1414 | E10: =((Geometria!$L$326*(Geometria!$M$897*100))/Geometria!$N$1307) -> 97.958377 | F10: =-'Perdas por Seção'!$E$101/(Geometria!$L$48/100^2)+'Perdas por Seção'!$E$102/(Geometria!$L$52/100^3)-Geometria!$M$898/(Geometria!$L$52/100^3) -> 6321.84 | I10: =Geometria!$L$298*E33+Geometria!$L$300*E10 -> 916.68418 | J10: =Geometria!$L$298*E33*Geometria!$L$299/100-Geometria!$L$300*E10*Geometria!$L$301/100 -> 171.87828 | M10: σi,3 | N10: =IF(Geometria!$M$437<Geometria!$N$1307/100,"Reduzir","OK") -> Reduzir | O10: =IF(N10="Reduzir",P10,R10) -> -2887.766 | P10: =-(U10/(Geometria!$L$48/100^2))+(V10/(Geometria!$L$52/100^3))-(('Cargas adicionais'!$O$245)/(Geometria!$L$52/100^3))-(('Cargas adicionais'!$R$245)/(Geometria!$L$401))-((Geometria!$L$76*'Cargas adicionais'!$U$245)/(Geometria!$L$401)) -> -2887.766 | Q10: =((Geometria!$N$369*(Geometria!$M$897*100))/Geometria!$N$1307) -> 82.775016 | R10: =-('Perdas por Seção'!$E$99/(Geometria!$L$48/100^2))+('Perdas por Seção'!$E$100/(Geometria!$L$52/100^3))-(('Cargas adicionais'!$O$245)/(Geometria!$L$52/100^3))-(('Cargas adicionais'!$R$245)/(Geometria!$L$401))-((Geometria!$L$76*'Cargas adicionais'!$U$245)/(Geometria!$L$401)) -> -1075.7521 | U10: =Geometria!$L$298*Q33+Geometria!$L$300*Q10 -> 772.63194 | V10: =Geometria!$L$298*Q33*Geometria!$L$299/100-Geometria!$L$300*Q10*Geometria!$L$301/100 -> 144.86849 | Y10: σi,3 | Z10: =IF(Geometria!$M$437<Geometria!$N$1307/100,"Reduzir","OK") -> Reduzir | AA10: =IF(Z10="Reduzir",AB10,AD10) -> -2887.766 | AB10: =-(AG10/(Geometria!$L$48/100^2))+(AH10/(Geometria!$L$52/100^3))-(('Cargas adicionais'!$O$245)/(Geometria!$L$52/100^3))-(('Cargas adicionais'!$R$245)/(Geometria!$L$401))-((Geometria!$L$76*'Cargas adicionais'!$U$245)/(Geometria!$L$401)) -> -2887.766 | AC10: =((Geometria!$N$369*(Geometria!$M$897*100))/Geometria!$N$1307) -> 82.775016 | AD10: =-('Perdas por Seção'!$E$99/(Geometria!$L$48/100^2))+('Perdas por Seção'!$E$100/(Geometria!$L$52/100^3))-(('Cargas adicionais'!$O$245)/(Geometria!$L$52/100^3))-(('Cargas adicionais'!$R$245)/(Geometria!$L$401)) -> -268.656 | AG10: =Geometria!$L$298*AC33+Geometria!$L$300*AC10 -> 772.63194 | AH10: =Geometria!$L$298*AC33*Geometria!$L$299/100-Geometria!$L$300*AC10*Geometria!$L$301/100 -> 144.86849 | AK10: σi,3 | AL10: =IF(Geometria!$M$437<Geometria!$N$1307/100,"Reduzir","OK") -> Reduzir | AM10: =IF(AL10="Reduzir",AN10,AP10) -> -2887.766 | AN10: =-(AS10/(Geometria!$L$48/100^2))+(AT10/(Geometria!$L$52/100^3))-(('Cargas adicionais'!$O$245)/(Geometria!$L$52/100^3))-(('Cargas adicionais'!$R$245)/(Geometria!$L$401))-((Geometria!$L$76*'Cargas adicionais'!$U$245)/(Geometria!$L$401)) -> -2887.766 | AO10: =((Geometria!$N$369*(Geometria!$M$897*100))/Geometria!$N$1307) -> 82.775016 | AP10: =-('Perdas por Seção'!$E$99/(Geometria!$L$48/100^2))+('Perdas por Seção'!$E$100/(Geometria!$L$52/100^3))-((Geometria!$M$673)/(Geometria!$L$52/100^3))-((Geometria!$M$684)/(Geometria!$L$401))-((Geometria!$L$77*Geometria!$M$695)/(Geometria!$L$401)) -> -806.72009 | AS10: =Geometria!$L$298*AO33+Geometria!$L$300*AO10 -> 772.63194 | AT10: =Geometria!$L$298*AO33*Geometria!$L$299/100-Geometria!$L$300*AO10*Geometria!$L$301/100 -> 144.86849 | AW10: σi,3 | AX10: =IF(Geometria!$M$437<Geometria!$N$1307/100,"Reduzir","OK") -> Reduzir | AY10: =IF(AX10="Reduzir",AZ10,BB10) -> -2887.766 | AZ10: =-(BE10/(Geometria!$L$48/100^2))+(BF10/(Geometria!$L$52/100^3))-(('Cargas adicionais'!$O$245)/(Geometria!$L$52/100^3))-(('Cargas adicionais'!$R$245)/(Geometria!$L$401))-((Geometria!$L$76*'Cargas adicionais'!$U$245)/(Geometria!$L$401)) -> -2887.766 | BA10: =((Geometria!$N$369*(Geometria!$M$897*100))/Geometria!$N$1307) -> 82.775016 | BB10: =-('Perdas por Seção'!$E$99/(Geometria!$L$48/100^2))+('Perdas por Seção'!$E$100/(Geometria!$L$52/100^3))-((Geometria!$M$673)/(Geometria!$L$52/100^3))-((Geometria!$M$684)/(Geometria!$L$401)) -> -268.656 | BE10: =Geometria!$L$298*BA33+Geometria!$L$300*BA10 -> 772.63194 | BF10: =Geometria!$L$298*BA33*Geometria!$L$299/100-Geometria!$L$300*BA10*Geometria!$L$301/100 -> 144.86849
A11: σi,4 | B11: =IF(Geometria!$N$437<Geometria!$N$1307/100,"Reduzir","OK") -> OK | C11: =IF(B11="Reduzir",D11,F11) -> 5987.0492 | D11: =-I11/(Geometria!$L$48/100^2)+J11/(Geometria!$L$52/100^3)-Geometria!$L$898/(Geometria!$L$52/100^3) -> 6251.1932 | E11: =((Geometria!$L$326*(Geometria!$N$897*100))/Geometria!$N$1307) -> 146.93757 | F11: =-'Perdas por Seção'!$F$101/(Geometria!$L$48/100^2)+'Perdas por Seção'!$F$102/(Geometria!$L$52/100^3)-Geometria!$N$898/(Geometria!$L$52/100^3) -> 5987.0492 | I11: =Geometria!$L$298*E34+Geometria!$L$300*E11 -> 1375.0263 | J11: =Geometria!$L$298*E34*Geometria!$L$299/100-Geometria!$L$300*E11*Geometria!$L$301/100 -> 257.81743 | M11: σi,4 | N11: =IF(Geometria!$N$437<Geometria!$N$1307/100,"Reduzir","OK") -> OK | O11: =IF(N11="Reduzir",P11,R11) -> -3732.0119 | P11: =-(U11/(Geometria!$L$48/100^2))+(V11/(Geometria!$L$52/100^3))-(('Cargas adicionais'!$O$246)/(Geometria!$L$52/100^3))-(('Cargas adicionais'!$R$246)/(Geometria!$L$401))-((Geometria!$L$76*'Cargas adicionais'!$U$246)/(Geometria!$L$401)) -> -3778.0143 | Q11: =((Geometria!$N$369*(Geometria!$N$897*100))/Geometria!$N$1307) -> 124.16252 | R11: =-('Perdas por Seção'!$F$99/(Geometria!$L$48/100^2))+('Perdas por Seção'!$F$100/(Geometria!$L$52/100^3))-(('Cargas adicionais'!$O$246)/(Geometria!$L$52/100^3))-(('Cargas adicionais'!$R$246)/(Geometria!$L$401))-((Geometria!$L$76*'Cargas adicionais'!$U$246)/(Geometria!$L$401)) -> -3732.0119 | U11: =Geometria!$L$298*Q34+Geometria!$L$300*Q11 -> 1158.9479 | V11: =Geometria!$L$298*Q34*Geometria!$L$299/100-Geometria!$L$300*Q11*Geometria!$L$301/100 -> 217.30273 | Y11: σi,4 | Z11: =IF(Geometria!$N$437<Geometria!$N$1307/100,"Reduzir","OK") -> OK | AA11: =IF(Z11="Reduzir",AB11,AD11) -> -2588.6257 | AB11: =-(AG11/(Geometria!$L$48/100^2))+(AH11/(Geometria!$L$52/100^3))-(('Cargas adicionais'!$O$246)/(Geometria!$L$52/100^3))-(('Cargas adicionais'!$R$246)/(Geometria!$L$401))-((Geometria!$L$76*'Cargas adicionais'!$U$246)/(Geometria!$L$401)) -> -3778.0143 | AC11: =((Geometria!$N$369*(Geometria!$N$897*100))/Geometria!$N$1307) -> 124.16252 | AD11: =-('Perdas por Seção'!$F$99/(Geometria!$L$48/100^2))+('Perdas por Seção'!$F$100/(Geometria!$L$52/100^3))-(('Cargas adicionais'!$O$246)/(Geometria!$L$52/100^3))-(('Cargas adicionais'!$R$246)/(Geometria!$L$401)) -> -2588.6257 | AG11: =Geometria!$L$298*AC34+Geometria!$L$300*AC11 -> 1158.9479 | AH11: =Geometria!$L$298*AC34*Geometria!$L$299/100-Geometria!$L$300*AC11*Geometria!$L$301/100 -> 217.30273 | AK11: σi,4 | AL11: =IF(Geometria!$N$437<Geometria!$N$1307/100,"Reduzir","OK") -> OK | AM11: =IF(AL11="Reduzir",AN11,AP11) -> -3350.8831 | AN11: =-(AS11/(Geometria!$L$48/100^2))+(AT11/(Geometria!$L$52/100^3))-(('Cargas adicionais'!$O$246)/(Geometria!$L$52/100^3))-(('Cargas adicionais'!$R$246)/(Geometria!$L$401))-((Geometria!$L$76*'Cargas adicionais'!$U$246)/(Geometria!$L$401)) -> -3778.0143 | AO11: =((Geometria!$N$369*(Geometria!$N$897*100))/Geometria!$N$1307) -> 124.16252 | AP11: =-('Perdas por Seção'!$F$99/(Geometria!$L$48/100^2))+('Perdas por Seção'!$F$100/(Geometria!$L$52/100^3))-((Geometria!$N$673)/(Geometria!$L$52/100^3))-((Geometria!$N$684)/(Geometria!$L$401))-((Geometria!$L$77*Geometria!$N$695)/(Geometria!$L$401)) -> -3350.8831 | AS11: =Geometria!$L$298*AO34+Geometria!$L$300*AO11 -> 1158.9479 | AT11: =Geometria!$L$298*AO34*Geometria!$L$299/100-Geometria!$L$300*AO11*Geometria!$L$301/100 -> 217.30273 | AW11: σi,4 | AX11: =IF(Geometria!$N$437<Geometria!$N$1307/100,"Reduzir","OK") -> OK | AY11: =IF(AX11="Reduzir",AZ11,BB11) -> -2588.6257 | AZ11: =-(BE11/(Geometria!$L$48/100^2))+(BF11/(Geometria!$L$52/100^3))-(('Cargas adicionais'!$O$246)/(Geometria!$L$52/100^3))-(('Cargas adicionais'!$R$246)/(Geometria!$L$401))-((Geometria!$L$76*'Cargas adicionais'!$U$246)/(Geometria!$L$401)) -> -3778.0143 | BA11: =((Geometria!$N$369*(Geometria!$N$897*100))/Geometria!$N$1307) -> 124.16252 | BB11: =-('Perdas por Seção'!$F$99/(Geometria!$L$48/100^2))+('Perdas por Seção'!$F$100/(Geometria!$L$52/100^3))-((Geometria!$N$673)/(Geometria!$L$52/100^3))-((Geometria!$N$684)/(Geometria!$L$401)) -> -2588.6257 | BE11: =Geometria!$L$298*BA34+Geometria!$L$300*BA11 -> 1158.9479 | BF11: =Geometria!$L$298*BA34*Geometria!$L$299/100-Geometria!$L$300*BA11*Geometria!$L$301/100 -> 217.30273
A12: σi,5 | B12: =IF(Geometria!$O$437<Geometria!$N$1307/100,"Reduzir","OK") -> OK | C12: =IF(B12="Reduzir",D12,F12) -> 5696.8972 | D12: =-I12/(Geometria!$L$48/100^2)+J12/(Geometria!$L$52/100^3)-Geometria!$L$898/(Geometria!$L$52/100^3) -> 8479.245 | E12: =((Geometria!$L$326*(Geometria!$O$897*100))/Geometria!$N$1307) -> 195.91675 | F12: =-'Perdas por Seção'!$G$101/(Geometria!$L$48/100^2)+'Perdas por Seção'!$G$102/(Geometria!$L$52/100^3)-Geometria!$O$898/(Geometria!$L$52/100^3) -> 5696.8972 | I12: =Geometria!$L$298*E35+Geometria!$L$300*E12 -> 1833.3684 | J12: =Geometria!$L$298*E35*Geometria!$L$299/100-Geometria!$L$300*E12*Geometria!$L$301/100 -> 343.75657 | M12: σi,5 | N12: =IF(Geometria!$O$437<Geometria!$N$1307/100,"Reduzir","OK") -> OK | O12: =IF(N12="Reduzir",P12,R12) -> -6034.1361 | P12: =-(U12/(Geometria!$L$48/100^2))+(V12/(Geometria!$L$52/100^3))-(('Cargas adicionais'!$O$247)/(Geometria!$L$52/100^3))-(('Cargas adicionais'!$R$247)/(Geometria!$L$401))-((Geometria!$L$76*'Cargas adicionais'!$U$247)/(Geometria!$L$401)) -> -4299.1729 | Q12: =((Geometria!$N$369*(Geometria!$O$897*100))/Geometria!$N$1307) -> 165.55003 | R12: =-('Perdas por Seção'!$G$99/(Geometria!$L$48/100^2))+('Perdas por Seção'!$G$100/(Geometria!$L$52/100^3))-(('Cargas adicionais'!$O$247)/(Geometria!$L$52/100^3))-(('Cargas adicionais'!$R$247)/(Geometria!$L$401))-((Geometria!$L$76*'Cargas adicionais'!$U$247)/(Geometria!$L$401)) -> -6034.1361 | U12: =Geometria!$L$298*Q35+Geometria!$L$300*Q12 -> 1545.2639 | V12: =Geometria!$L$298*Q35*Geometria!$L$299/100-Geometria!$L$300*Q12*Geometria!$L$301/100 -> 289.73698 | Y12: σi,5 | Z12: =IF(Geometria!$O$437<Geometria!$N$1307/100,"Reduzir","OK") -> OK | AA12: =IF(Z12="Reduzir",AB12,AD12) -> -4599.2985 | AB12: =-(AG12/(Geometria!$L$48/100^2))+(AH12/(Geometria!$L$52/100^3))-(('Cargas adicionais'!$O$247)/(Geometria!$L$52/100^3))-(('Cargas adicionais'!$R$247)/(Geometria!$L$401))-((Geometria!$L$76*'Cargas adicionais'!$U$247)/(Geometria!$L$401)) -> -4299.1729 | AC12: =((Geometria!$N$369*(Geometria!$O$897*100))/Geometria!$N$1307) -> 165.55003 | AD12: =-('Perdas por Seção'!$G$99/(Geometria!$L$48/100^2))+('Perdas por Seção'!$G$100/(Geometria!$L$52/100^3))-(('Cargas adicionais'!$O$247)/(Geometria!$L$52/100^3))-(('Cargas adicionais'!$R$247)/(Geometria!$L$401)) -> -4599.2985 | AG12: =Geometria!$L$298*AC35+Geometria!$L$300*AC12 -> 1545.2639 | AH12: =Geometria!$L$298*AC35*Geometria!$L$299/100-Geometria!$L$300*AC12*Geometria!$L$301/100 -> 289.73698 | AK12: σi,5 | AL12: =IF(Geometria!$O$437<Geometria!$N$1307/100,"Reduzir","OK") -> OK | AM12: =IF(AL12="Reduzir",AN12,AP12) -> -5555.8569 | AN12: =-(AS12/(Geometria!$L$48/100^2))+(AT12/(Geometria!$L$52/100^3))-(('Cargas adicionais'!$O$247)/(Geometria!$L$52/100^3))-(('Cargas adicionais'!$R$247)/(Geometria!$L$401))-((Geometria!$L$76*'Cargas adicionais'!$U$247)/(Geometria!$L$401)) -> -4299.1729 | AO12: =((Geometria!$N$369*(Geometria!$O$897*100))/Geometria!$N$1307) -> 165.55003 | AP12: =-('Perdas por Seção'!$G$99/(Geometria!$L$48/100^2))+('Perdas por Seção'!$G$100/(Geometria!$L$52/100^3))-((Geometria!$O$673)/(Geometria!$L$52/100^3))-((Geometria!$O$684)/(Geometria!$L$401))-((Geometria!$L$77*Geometria!$O$695)/(Geometria!$L$401)) -> -5555.8569 | AS12: =Geometria!$L$298*AO35+Geometria!$L$300*AO12 -> 1545.2639 | AT12: =Geometria!$L$298*AO35*Geometria!$L$299/100-Geometria!$L$300*AO12*Geometria!$L$301/100 -> 289.73698 | AW12: σi,5 | AX12: =IF(Geometria!$O$437<Geometria!$N$1307/100,"Reduzir","OK") -> OK | AY12: =IF(AX12="Reduzir",AZ12,BB12) -> -4599.2985 | AZ12: =-(BE12/(Geometria!$L$48/100^2))+(BF12/(Geometria!$L$52/100^3))-(('Cargas adicionais'!$O$247)/(Geometria!$L$52/100^3))-(('Cargas adicionais'!$R$247)/(Geometria!$L$401))-((Geometria!$L$76*'Cargas adicionais'!$U$247)/(Geometria!$L$401)) -> -4299.1729 | BA12: =((Geometria!$N$369*(Geometria!$O$897*100))/Geometria!$N$1307) -> 165.55003 | BB12: =-('Perdas por Seção'!$G$99/(Geometria!$L$48/100^2))+('Perdas por Seção'!$G$100/(Geometria!$L$52/100^3))-((Geometria!$O$673)/(Geometria!$L$52/100^3))-((Geometria!$O$684)/(Geometria!$L$401)) -> -4599.2985 | BE12: =Geometria!$L$298*BA35+Geometria!$L$300*BA12 -> 1545.2639 | BF12: =Geometria!$L$298*BA35*Geometria!$L$299/100-Geometria!$L$300*BA12*Geometria!$L$301/100 -> 289.73698
A13: σi,6 | B13: =IF(Geometria!$P$437<Geometria!$N$1307/100,"Reduzir","OK") -> OK | C13: =IF(B13="Reduzir",D13,F13) -> 5451.3839 | D13: =-I13/(Geometria!$L$48/100^2)+J13/(Geometria!$L$52/100^3)-Geometria!$L$898/(Geometria!$L$52/100^3) -> 10707.297 | E13: =((Geometria!$L$326*(Geometria!$P$897*100))/Geometria!$N$1307) -> 244.89594 | F13: =-'Perdas por Seção'!$H$101/(Geometria!$L$48/100^2)+'Perdas por Seção'!$H$102/(Geometria!$L$52/100^3)-Geometria!$P$898/(Geometria!$L$52/100^3) -> 5451.3839 | I13: =Geometria!$L$298*E36+Geometria!$L$300*E13 -> 2291.7104 | J13: =Geometria!$L$298*E36*Geometria!$L$299/100-Geometria!$L$300*E13*Geometria!$L$301/100 -> 429.69571 | M13: σi,6 | N13: =IF(Geometria!$P$437<Geometria!$N$1307/100,"Reduzir","OK") -> OK | O13: =IF(N13="Reduzir",P13,R13) -> -7982.1109 | P13: =-(U13/(Geometria!$L$48/100^2))+(V13/(Geometria!$L$52/100^3))-(('Cargas adicionais'!$O$248)/(Geometria!$L$52/100^3))-(('Cargas adicionais'!$R$248)/(Geometria!$L$401))-((Geometria!$L$76*'Cargas adicionais'!$U$248)/(Geometria!$L$401)) -> -4451.2418 | Q13: =((Geometria!$N$369*(Geometria!$P$897*100))/Geometria!$N$1307) -> 206.93754 | R13: =-('Perdas por Seção'!$H$99/(Geometria!$L$48/100^2))+('Perdas por Seção'!$H$100/(Geometria!$L$52/100^3))-(('Cargas adicionais'!$O$248)/(Geometria!$L$52/100^3))-(('Cargas adicionais'!$R$248)/(Geometria!$L$401))-((Geometria!$L$76*'Cargas adicionais'!$U$248)/(Geometria!$L$401)) -> -7982.1109 | U13: =Geometria!$L$298*Q36+Geometria!$L$300*Q13 -> 1931.5799 | V13: =Geometria!$L$298*Q36*Geometria!$L$299/100-Geometria!$L$300*Q13*Geometria!$L$301/100 -> 362.17122 | Y13: σi,6 | Z13: =IF(Geometria!$P$437<Geometria!$N$1307/100,"Reduzir","OK") -> OK | AA13: =IF(Z13="Reduzir",AB13,AD13) -> -6300.6606 | AB13: =-(AG13/(Geometria!$L$48/100^2))+(AH13/(Geometria!$L$52/100^3))-(('Cargas adicionais'!$O$248)/(Geometria!$L$52/100^3))-(('Cargas adicionais'!$R$248)/(Geometria!$L$401))-((Geometria!$L$76*'Cargas adicionais'!$U$248)/(Geometria!$L$401)) -> -4451.2418 | AC13: =((Geometria!$N$369*(Geometria!$P$897*100))/Geometria!$N$1307) -> 206.93754 | AD13: =-('Perdas por Seção'!$H$99/(Geometria!$L$48/100^2))+('Perdas por Seção'!$H$100/(Geometria!$L$52/100^3))-(('Cargas adicionais'!$O$248)/(Geometria!$L$52/100^3))-(('Cargas adicionais'!$R$248)/(Geometria!$L$401)) -> -6300.6606 | AG13: =Geometria!$L$298*AC36+Geometria!$L$300*AC13 -> 1931.5799 | AH13: =Geometria!$L$298*AC36*Geometria!$L$299/100-Geometria!$L$300*AC13*Geometria!$L$301/100 -> 362.17122 | AK13: σi,6 | AL13: =IF(Geometria!$P$437<Geometria!$N$1307/100,"Reduzir","OK") -> OK | AM13: =IF(AL13="Reduzir",AN13,AP13) -> -7421.6275 | AN13: =-(AS13/(Geometria!$L$48/100^2))+(AT13/(Geometria!$L$52/100^3))-(('Cargas adicionais'!$O$248)/(Geometria!$L$52/100^3))-(('Cargas adicionais'!$R$248)/(Geometria!$L$401))-((Geometria!$L$76*'Cargas adicionais'!$U$248)/(Geometria!$L$401)) -> -4451.2418 | AO13: =((Geometria!$N$369*(Geometria!$P$897*100))/Geometria!$N$1307) -> 206.93754 | AP13: =-('Perdas por Seção'!$H$99/(Geometria!$L$48/100^2))+('Perdas por Seção'!$H$100/(Geometria!$L$52/100^3))-((Geometria!$P$673)/(Geometria!$L$52/100^3))-((Geometria!$P$684)/(Geometria!$L$401))-((Geometria!$L$77*Geometria!$P$695)/(Geometria!$L$401)) -> -7421.6275 | AS13: =Geometria!$L$298*AO36+Geometria!$L$300*AO13 -> 1931.5799 | AT13: =Geometria!$L$298*AO36*Geometria!$L$299/100-Geometria!$L$300*AO13*Geometria!$L$301/100 -> 362.17122 | AW13: σi,6 | AX13: =IF(Geometria!$P$437<Geometria!$N$1307/100,"Reduzir","OK") -> OK | AY13: =IF(AX13="Reduzir",AZ13,BB13) -> -6300.6606 | AZ13: =-(BE13/(Geometria!$L$48/100^2))+(BF13/(Geometria!$L$52/100^3))-(('Cargas adicionais'!$O$248)/(Geometria!$L$52/100^3))-(('Cargas adicionais'!$R$248)/(Geometria!$L$401))-((Geometria!$L$76*'Cargas adicionais'!$U$248)/(Geometria!$L$401)) -> -4451.2418 | BA13: =((Geometria!$N$369*(Geometria!$P$897*100))/Geometria!$N$1307) -> 206.93754 | BB13: =-('Perdas por Seção'!$H$99/(Geometria!$L$48/100^2))+('Perdas por Seção'!$H$100/(Geometria!$L$52/100^3))-((Geometria!$P$673)/(Geometria!$L$52/100^3))-((Geometria!$P$684)/(Geometria!$L$401)) -> -6300.6606 | BE13: =Geometria!$L$298*BA36+Geometria!$L$300*BA13 -> 1931.5799 | BF13: =Geometria!$L$298*BA36*Geometria!$L$299/100-Geometria!$L$300*BA13*Geometria!$L$301/100 -> 362.17122
A14: σi,7 | B14: =IF(Geometria!$Q$437<Geometria!$N$1307/100,"Reduzir","OK") -> OK | C14: =IF(B14="Reduzir",D14,F14) -> 5250.5094 | D14: =-I14/(Geometria!$L$48/100^2)+J14/(Geometria!$L$52/100^3)-Geometria!$L$898/(Geometria!$L$52/100^3) -> 12935.349 | E14: =((Geometria!$L$326*(Geometria!$Q$897*100))/Geometria!$N$1307) -> 293.87513 | F14: =-'Perdas por Seção'!$I$101/(Geometria!$L$48/100^2)+'Perdas por Seção'!$I$102/(Geometria!$L$52/100^3)-Geometria!$Q$898/(Geometria!$L$52/100^3) -> 5250.5094 | I14: =Geometria!$L$298*E37+Geometria!$L$300*E14 -> 2750.0525 | J14: =Geometria!$L$298*E37*Geometria!$L$299/100-Geometria!$L$300*E14*Geometria!$L$301/100 -> 515.63485 | M14: σi,7 | N14: =IF(Geometria!$Q$437<Geometria!$N$1307/100,"Reduzir","OK") -> OK | O14: =IF(N14="Reduzir",P14,R14) -> -9575.9245 | P14: =-(U14/(Geometria!$L$48/100^2))+(V14/(Geometria!$L$52/100^3))-(('Cargas adicionais'!$O$249)/(Geometria!$L$52/100^3))-(('Cargas adicionais'!$R$249)/(Geometria!$L$401))-((Geometria!$L$76*'Cargas adicionais'!$U$249)/(Geometria!$L$401)) -> -4234.2208 | Q14: =((Geometria!$N$369*(Geometria!$Q$897*100))/Geometria!$N$1307) -> 248.32505 | R14: =-('Perdas por Seção'!$I$99/(Geometria!$L$48/100^2))+('Perdas por Seção'!$I$100/(Geometria!$L$52/100^3))-(('Cargas adicionais'!$O$249)/(Geometria!$L$52/100^3))-(('Cargas adicionais'!$R$249)/(Geometria!$L$401))-((Geometria!$L$76*'Cargas adicionais'!$U$249)/(Geometria!$L$401)) -> -9575.9245 | U14: =Geometria!$L$298*Q37+Geometria!$L$300*Q14 -> 2317.8958 | V14: =Geometria!$L$298*Q37*Geometria!$L$299/100-Geometria!$L$300*Q14*Geometria!$L$301/100 -> 434.60547 | Y14: σi,7 | Z14: =IF(Geometria!$Q$437<Geometria!$N$1307/100,"Reduzir","OK") -> OK | AA14: =IF(Z14="Reduzir",AB14,AD14) -> -7692.7002 | AB14: =-(AG14/(Geometria!$L$48/100^2))+(AH14/(Geometria!$L$52/100^3))-(('Cargas adicionais'!$O$249)/(Geometria!$L$52/100^3))-(('Cargas adicionais'!$R$249)/(Geometria!$L$401))-((Geometria!$L$76*'Cargas adicionais'!$U$249)/(Geometria!$L$401)) -> -4234.2208 | AC14: =((Geometria!$N$369*(Geometria!$Q$897*100))/Geometria!$N$1307) -> 248.32505 | AD14: =-('Perdas por Seção'!$I$99/(Geometria!$L$48/100^2))+('Perdas por Seção'!$I$100/(Geometria!$L$52/100^3))-(('Cargas adicionais'!$O$249)/(Geometria!$L$52/100^3))-(('Cargas adicionais'!$R$249)/(Geometria!$L$401)) -> -7692.7002 | AG14: =Geometria!$L$298*AC37+Geometria!$L$300*AC14 -> 2317.8958 | AH14: =Geometria!$L$298*AC37*Geometria!$L$299/100-Geometria!$L$300*AC14*Geometria!$L$301/100 -> 434.60547 | AK14: σi,7 | AL14: =IF(Geometria!$Q$437<Geometria!$N$1307/100,"Reduzir","OK") -> OK | AM14: =IF(AL14="Reduzir",AN14,AP14) -> -8948.1831 | AN14: =-(AS14/(Geometria!$L$48/100^2))+(AT14/(Geometria!$L$52/100^3))-(('Cargas adicionais'!$O$249)/(Geometria!$L$52/100^3))-(('Cargas adicionais'!$R$249)/(Geometria!$L$401))-((Geometria!$L$76*'Cargas adicionais'!$U$249)/(Geometria!$L$401)) -> -4234.2208 | AO14: =((Geometria!$N$369*(Geometria!$Q$897*100))/Geometria!$N$1307) -> 248.32505 | AP14: =-('Perdas por Seção'!$I$99/(Geometria!$L$48/100^2))+('Perdas por Seção'!$I$100/(Geometria!$L$52/100^3))-((Geometria!$Q$673)/(Geometria!$L$52/100^3))-((Geometria!$Q$684)/(Geometria!$L$401))-((Geometria!$L$77*Geometria!$Q$695)/(Geometria!$L$401)) -> -8948.1831 | AS14: =Geometria!$L$298*AO37+Geometria!$L$300*AO14 -> 2317.8958 | AT14: =Geometria!$L$298*AO37*Geometria!$L$299/100-Geometria!$L$300*AO14*Geometria!$L$301/100 -> 434.60547 | AW14: σi,7 | AX14: =IF(Geometria!$Q$437<Geometria!$N$1307/100,"Reduzir","OK") -> OK | AY14: =IF(AX14="Reduzir",AZ14,BB14) -> -7692.7002 | AZ14: =-(BE14/(Geometria!$L$48/100^2))+(BF14/(Geometria!$L$52/100^3))-(('Cargas adicionais'!$O$249)/(Geometria!$L$52/100^3))-(('Cargas adicionais'!$R$249)/(Geometria!$L$401))-((Geometria!$L$76*'Cargas adicionais'!$U$249)/(Geometria!$L$401)) -> -4234.2208 | BA14: =((Geometria!$N$369*(Geometria!$Q$897*100))/Geometria!$N$1307) -> 248.32505 | BB14: =-('Perdas por Seção'!$I$99/(Geometria!$L$48/100^2))+('Perdas por Seção'!$I$100/(Geometria!$L$52/100^3))-((Geometria!$Q$673)/(Geometria!$L$52/100^3))-((Geometria!$Q$684)/(Geometria!$L$401)) -> -7692.7002 | BE14: =Geometria!$L$298*BA37+Geometria!$L$300*BA14 -> 2317.8958 | BF14: =Geometria!$L$298*BA37*Geometria!$L$299/100-Geometria!$L$300*BA14*Geometria!$L$301/100 -> 434.60547
